Workbook

Sheet 00_README
A1: 三區制度框架 R4.5.3 (純分數版) | 18項指標單一加權合成分 = 唯一判區 | 事件鎖存已移除
A3: 版本 | B3: 2026R4.5.3 | 修訂日: 2026-07-11 | 依用戶指示: ①移除事件覆蓋鎖存(判區=單一純分數); ②新增T4(NDX 5日/10日均線動能+衝擊)與T5(最熱板塊ETF動能, 現用SOXX); ③重新測試權重(WA/WB/WC三組, 採用WB, 紀錄於01表)。
A4: 6/4問題的誠實答案 | B4: 收盤價數據裡6/4只是溫和下跌日(NDX -0.53%, VIX下跌, 廣度上升, 信用持平, SOXX收盤僅-2.10%)——任何純收盤引擎都看不到。真正可量化的6/4訊號是SOXX開盤跳空-4.56%(587.64 vs 前收615.68, AVGO指引證偽後的板塊缺口)。R4.5.3把它編入T5的HARD衝擊條款(跳空≤-3%), 令6/4單憑合成分=66.2跌入UNCERTAIN——用真實板塊數據, 非人手旗標。
A5: T5數據覆蓋 | B5: 真實SOXX開盤/收盤 2026/4/29-7/10共50個交易日(stockanalysis.com, S&P Global來源, 抓取於2026-07-11, 淡紫底標示)。更早日期AY/AZ為藍格待回填; 空白日T5權重(26)自動移出分母, 不扭曲歷史判區。回填十年SOXX數據後, T5立即全期參與。
A6: 純分數的代價(如實揭露) | B6: 移除鎖存後, 判區隨分數即日擺動: 2026/6/4-7/10為 6 EASY / 18 UNCERTAIN / 1 HARD——6個EASY島全部落在SOXX單日+4%~+8%的暴力反彈日(6/8,6/17,6/18,6/22,6/24,6/25)。這是高敏感引擎的誠實輸出: 六月市場本身就在±5-10%劇烈擺動。若需要「一旦變速、維持警戒」的滯後行為, 那正是被移除的鎖存層的功能, 兩者不可兼得。
A7: 校準狀態(公式活算於05表) | B7: 窗口① 2026/4/4-5/14: 93.1% EASY (27/29; 4/6-4/7修復期) ✓ | 窗口② 6/3=EASY(100)→6/4=UNCERTAIN(66.2)單憑分數 ✓ | 窗口③ 2025/5/1-10/31: 93.8% EASY(較R4.5.1的82.8%更高: 鎖存移除釋放了十月分數滿分日) ✓ | 2017年EASY 245/251, 2022年HARD 216/251。
A8: 工作表 | B8: 00_README | 01_指標庫(18項) | 02A_每日分段(55欄) | 05_統計摘要 | 06_監察面板 | 07_L1政策步階
A9: 顏色 | B9: 綠=EASY | 黃=UNCERTAIN | 紅=HARD | 藍字=可輸入 | 淡紫底=審核修正格 | 綠字=跨表公式

Sheet 01_指標庫
A1: 量化指標庫 R4.5.3: 18項指標純分數引擎 | 判區=合成分(02A之AX): ≥70 EASY / 40-70 UNCERTAIN / ≤40 HARD | 無事件覆蓋層
A3: ID | B3: 類別 | C3: 指標名稱 | D3: EASY區 | E3: UNCERTAIN區 | F3: HARD區 | G3: 重要性 | H3: 權重% | I3: 關連性 / 領先-滯後描述 | J3: 可持續監察來源 | K3: 頻率
A4: T1 | B4: 技術/趨勢 | C4: NDX vs 40週均線 | D4: 收巿>40週線且上斜 | E4: 40週線±2%拉鋸 / 單週失守未連續 | F4: 連續2週收於線下 或 均線下斜 | G4: ★★★★★ | H4: 8 | I4: 同步至輕微滯後。區分制度最穩健單一規則; R2以「連續2週」過濾2019/5、2024/8式單週假破。 | J4: 自家週線圖 | K4: 週
A5: T2 | B5: 技術/趨勢 | C5: 10週/40週均線交叉 | D5: 金叉且乖離擴大 | E5: 跌破10週線 / 10週線走平 | F5: 死叉 | G5: ★★★★ | H5: 2 | I5: 滯後確認。死叉鎖定2022全年; 對V型底滯後6-10週, 急V條款由T3+B1代償。 | J5: 自家週線圖 | K5: 週
A6: T3 | B6: 技術/趨勢 | C6: 距52週高位回撤 | D6: >-6% | E6: -6% ~ -15% | F6: ≤-15% | G6: ★★★★★ | H6: 8 | I6: 同步; R2敏感度核心。-6%線十年觸發約20次, 全部對應真實警戒事件; -15%線僅真熊觸發, 零假警報。 | J6: 指數行情 | K6: 週
A7: B1 | B7: 廣度 | C7: 成份股>200日線比例 | D7: >60%且回升 | E7: 40-60% 或 自高位急降 | F7: <40%且下行 | G7: ★★★★★ | H7: 8 | I7: 領先1-4週。廣度先於指數: 2021年中已崩=2022最早預警; >90%推力=新EASY最強確認。 | J7: Barchart $NDXA200R / StockCharts | K7: 週
A8: B2 | B8: 廣度 | C8: 淨新高-新低(10日) | D8: 持續為正 | E8: 正負反覆 / 淨新低放大 | F8: 淨新低持續擴張 | G8: ★★★★ | H8: 4 | I8: 領先1-3週。與Market Breadth Dashboard同源; 熊巿反彈證偽關鍵。 | J8: Stockbee Market Monitor | K8: 日/週
A9: B3 | B9: 廣度 | C9: A/D線對指數背離 | D9: 同創新高 | E9: 溫和背離(1-2月) | F9: 持續多月背離+指數新高 | G9: ★★★ | H9: 2 | I9: 領先數週至數月。2021/11、2024/7頂前均現; 輔助用。 | J9: StockCharts | K9: 週
A10: L1 | B10: 流動性/政策 | C10: Fed政策方向+巿場加息/減息定價 | D10: 減息或寬鬆指引 | E10: 暫停+加息定價20-50% / 移除寬鬆傾向 | F10: 加息定價>50% 或 實際加息 | G10: ★★★★★ | H10: 5 | I10: 領先1-3個月, 制度級。2019/2023/2024轉向開EASY; 2018/2022緊縮製造HARD。2026/6/17移除寬鬆傾向+9月加息定價逾六成=十年內第三次制度級轉鷹。 | J10: CME FedWatch / FOMC | K10: 日/會期
A11: L2 | B11: 流動性/政策 | C11: 淨流動性(B/S−TGA−RRP) | D11: 按週回升 | E11: 走平 | F11: 收縮且加速 | G11: ★★★★ | H11: 4 | I11: 領先2-6週。2022後與NDX高相關; QRA/RRP釋放為2023-24隱形推手。 | J11: FRED: WALCL−WTREGEN−RRPONTSYD | K11: 週
A12: L3 | B12: 流動性/政策 | C12: M2同比 | D12: 回升且>4% | E12: 0-4%放緩 | F12: 負增長 | G12: ★★★ | H12: 2 | I12: 長領先3-12個月, 只作背景。 | J12: FRED: M2SL | K12: 月
A13: L4 | B13: 流動性/政策 | C13: 10Y-3M曲線 | D13: 正斜且趨陡 | E13: 走平/初倒掛 | F13: 深倒掛後快速熊陡 | G13: ★★★ | H13: 2 | I13: 長領先6-18個月(衰退); 對週度判區偏慢, 與C1並用。 | J13: FRED: T10Y3M | K13: 週
A14: C1 | B14: 信用 | C14: HY OAS | D14: <350bp且收窄 | E14: 350-450bp 或 4週急闊>+50bp | F14: >450bp且走闊 | G14: ★★★★★ | H14: 8 | I14: 同步至領先1-2週。股巿測謊機: 股跌而利差不闊=大概率震倉(UNCERTAIN)而非制度轉變; 2025/4峰值461bp即HARD確認。 | J14: FRED: BAMLH0A0HYM2 | K14: 日
A15: C2 | B15: 信用 | C15: SLOOS信貸標準 | D15: 放鬆 | E15: 溫和收緊 | F15: 大幅淨收緊 | G15: ★★ | H15: 2 | I15: 領先1-2季, 背景確認。 | J15: Fed SLOOS | K15: 季
... A19: S2 | B19: 情緒/投機 | C19: 投機活躍度(BTC距高回撤/IPO/低價股成交) | D19: BTC距高>-20%, 溫和擴張 | E19: BTC -20~-40% / 狂熱後急凍 | F19: BTC≤-40% / 冰封 | G19: ★★ | H19: 1 | I19: 雙向領先。投機性流動性是最快退潮的一層; BTC自2025/10記錄跌逾五成=本輪最早的HARD級單項訊號。 | J19: 行情 / FINRA | K19: 日/月
A20: T4 | B20: 技術/趨勢 | C20: NDX 5日/10日均線動能+衝擊 | D20: 乖離≥+1% 且 單日>-2% | E20: 乖離0~+1% 或 單日≤-2% | F20: 乖離<-0.3% 或 單日≤-3% | G20: ★★★★ | H20: 6 | I20: 快層動能: 5/10交叉對頂部同步至領先數日; 單日-3%衝擊條款把原事件層規則收編為指標本身。 | J20: 自NDX收巿序列公式衍生(BA欄) | K20: 日
A21: T5 | B21: 板塊動能 | C21: 最熱板塊ETF動能(現用SOXX半導體) | D21: 乖離≥+0.5% 且 無衝擊 | E21: 單日≤-2% 或 乖離<+0.5% | F21: 開盤跳空≤-3% 或 單日≤-4.5% 或 乖離<-1% | G21: ★★★★★ | H21: 26 | I21: 本週期領導板塊=AI半導體。領導板塊先於指數變盤: 6/4指數僅-0.53%而SOXX開盤跳空-4.56%——訊號載體。權重26=經實測能令6/4單憑分數跌入UNCERTAIN且不毀十年校準的最小級別。 | J21: stockanalysis.com (S&P Global) 真實數據 2026/4/29-7/10; 更早由用戶回填AY/AZ藍格 | K21: 日
C22: 權重合計 (18項=100) | H22: =SUM(H4:H21) -> 68
A24: R4.5.3 權重測試紀錄 (用戶指示「重新調整weighting」之依據)
A25: WA: T5=24,T4=8 | C25: 6/4=68.8 UNC ✓ | 窗①93.1% 窗③93.8% | 2017 EASY 217
A26: WB: T5=26,T4=6 (採用) | C26: 6/4=66.2 UNC ✓(邊際最穩) | 窗①93.1% 窗③93.8% | 2017 EASY 245 | 2022 HARD 216
A27: WC: T5=22 | C27: 6/4=71.8 → 仍EASY ✗ 否決 (T5權重不足以承載板塊訊號)
A29: 採用權重(18項合計100): T1=8 T2=2 T3=8 B1=8 B2=4 B3=2 L1=5 L2=4 L3=2 L4=2 C1=8 C2=2 V1=6 V2=4 S1=2 S2=1 T4=6 T5=26。T5空白日(2026/4/29前)其權重自動移出分母, 歷史判區由其餘指標承擔。

Sheet 02A_每日分段
A1: R4.5.3 每日判區(純分數版): 18項指標加權合成分(動態分母) = 唯一判區依據 | 事件鎖存已依用戶指示移除 | 新增T4(NDX 5/10動能)+T5(最熱板塊SOXX動能, 真實數據)
A2: A-K=數據層; L-P/AL-AV/BB-BC=子分; S/T=日變%(資訊); AA-AK=輸入; AY/AZ=SOXX開盤/收盤[真實50日+藍格回填]; BA=T4輸入; AW=有效權重和; AX=合成分; Y=最終ZONE=IF(AX≥70,EASY,IF(AX>40,UNCERTAIN,HARD)) — 無任何覆蓋層。
A4: 交易日# | B4: 日期 | C4: 年份 | D4: 週內 | E4: NDX收盤 | F4: T1:距200D% | G4: T3:距52週高% | H4: B1:廣度%代理 | I4: C1:HYOAS(bp) | J4: C1來源 | K4: V1:VIX | L4: T1子分(式) | M4: T3子分(式) | N4: B1子分(式) | O4: C1子分(式) | P4: V1子分(式) | S4: NDX日變% | T4: VIX日變% | Y4: 最終ZONE | AA4: T2輸入:50/200乖離% | AB4: L1輸入:政策碼(07表) | AC4: L2輸入:淨流動性週變%[藍] | AD4: L3輸入:M2同比%[藍] | AE4: L4輸入:10Y-3M bp[藍] | AF4: B2輸入:淨新高低10日[藍] | AG4: B3輸入:A/D碼[藍] | AH4: C2輸入:SLOOS%[藍] | AI4: V2輸入:VIX/VIX3M[藍] | AJ4: S1輸入:NAAIM[藍] | AK4: S2輸入:BTC距高%[藍] | AL4: T2子分 | AM4: L1子分 | AN4: L2子分 | AO4: L3子分 | AP4: L4子分 | AQ4: B2子分 | AR4: B3子分 | AS4: C2子分 | AT4: V2子分 | AU4: S1子分 | AV4: S2子分 | AW4: 有效權重和(式) | AX4: 16項合成分(式) | AY4: T5板塊ETF開盤(SOXX)[藍] | AZ4: T5板塊ETF收盤(SOXX)[藍] | BA4: T4輸入:NDX5/10乖離%(式) | BB4: T4子分(式) | BC4: T5子分(式)
A5: 1 | B5: 42559 | C5: 2016 | D5: 五 | E5: 4528.36 | F5: 0.024988 | G5: -0.040409 | H5: 0.7347 | I5: 588 | J5: real | K5: 13.2 | L5: =IF(COUNT(F5)=0,50,IF(F5>=0,100,IF(F5>=-0.02,50,0))) -> 100 | M5: =IF(COUNT(G5)=0,50,IF(G5>-0.06,100,IF(G5>-0.15,50,0))) -> 100 | N5: =IF(COUNT(H5)=0,50,IF(H5>=0.6,100,IF(H5>=0.4,50,0))) -> 100 | O5: =IF(COUNT(I5)=0,50,IF(J5="proxy_vix",50,IF(I5<350,100,IF(I5<=450,50,0)))) -> 0 | P5: =IF(COUNT(K5)=0,50,IF(K5<20,100,IF(K5<=25,50,0))) -> 100 | Y5: =IF(AX5>=70,"EASY",IF(AX5>40,"UNCERTAIN","HARD")) -> EASY | AA5: =IF($A5<200,"",AVERAGE($E5:$E5)/AVERAGE($E5:$E5)-1) | AB5: =LOOKUP($B5,07_L1政策步階!$A$4:$A$14,07_L1政策步階!$C$4:$C$14) -> 0 | AL5: =IF(ISNUMBER($AA5),IF($AA5>=0.005,100,IF($AA5>=-0.015,50,0)),"") | AM5: =IF(ISNUMBER($AB5),IF($AB5=1,100,IF($AB5=0,50,0)),"") -> 50 | AN5: =IF(ISNUMBER($AC5),IF($AC5>=0.001,100,IF($AC5>=-0.003,50,0)),"") | AO5: =IF(ISNUMBER($AD5),IF($AD5>=0.04,100,IF($AD5>=0,50,0)),"") | AP5: =IF(ISNUMBER($AE5),IF($AE5>=25,100,IF($AE5>=-75,50,0)),"") | AQ5: =IF(ISNUMBER($AF5),IF($AF5>0,100,IF($AF5>=-50,50,0)),"") | AR5: =IF(ISNUMBER($AG5),IF($AG5=1,100,IF($AG5=0,50,0)),"") | AS5: =IF(ISNUMBER($AH5),IF($AH5<0,100,IF($AH5<=20,50,0)),"") | AT5: =IF(ISNUMBER($AI5),IF($AI5<0.95,100,IF($AI5<=1,50,0)),"") | AU5: =IF(ISNUMBER($AJ5),IF($AJ5<30,0,IF($AJ5<40,50,IF($AJ5<=90,100,50))),"") | AV5: =IF(ISNUMBER($AK5),IF($AK5>-0.2,100,IF($AK5>=-0.4,50,0)),"") | AW5: =01_指標庫!$H$4*ISNUMBER($F5)+01_指標庫!$H$5*ISNUMBER($AA5)+01_指標庫!$H$6*ISNUMBER($G5)+01_指標庫!$H$7*ISNUMBER($H5)+01_指標庫!$H$8*ISNUMBER($AF5)+01_指標庫!$H$9*ISNUMBER($AG5)+01_指標庫!$H$10*ISNUMBER($AB5)+01_指標庫!$H$11*ISNUMBER($AC5)+01_指標庫!$H$12*ISNUMBER($AD5)+01_指標庫!$H$13*ISNUMBER($AE5)+01_指標庫!$H$14*ISNUMBER($I5)+01_指標庫!$H$15*ISNUMBER($AH5)+01_指標庫!$H$16*ISNUMBER($K5)+01_指標庫!$H$17*ISNUMBER($AI5)+01_指標庫!$H$18*ISNUMBER($AJ5)+01_指標庫!$H$19*ISNUMBER($AK5)+01_指標庫!$H$20*ISNUMBER($BB5)+01_指標庫!$H$21*ISNUMBER($BC5) -> 43 | AX5: =IF(AW5=0,50,ROUND((01_指標庫!$H$4*IF(ISNUMBER($F5),L5,0)+01_指標庫!$H$5*IF(ISNUMBER($AA5),AL5,0)+01_指標庫!$H$6*IF(ISNUMBER($G5),M5,0)+01_指標庫!$H$7*IF(ISNUMBER($H5),N5,0)+01_指標庫!$H$8*IF(ISNUMBER($AF5),AQ5,0)+01_指標庫!$H$9*IF(ISNUMBER($AG5),AR5,0)+01_指標庫!$H$10*IF(ISNUMBER($AB5),AM5,0)+01_指標庫!$H$11*IF(ISNUMBER($AC5),AN5,0)+01_指標庫!$H$12*IF(ISNUMBER($AD5),AO5,0)+01_指標庫!$H$13*IF(ISNUMBER($AE5),AP5,0)+01_指標庫!$H$14*IF(ISNUMBER($I5),O5,0)+01_指標庫!$H$15*IF(ISNUMBER($AH5),AS5,0)+01_指標庫!$H$16*IF(ISNUMBER($K5),P5,0)+01_指標庫!$H$17*IF(ISNUMBER($AI5),AT5,0)+01_指標庫!$H$18*IF(ISNUMBER($AJ5),AU5,0)+01_指標庫!$H$19*IF(ISNUMBER($AK5),AV5,0)+01_指標庫!$H$20*IF(ISNUMBER($BB5),BB5,0)+01_指標庫!$H$21*IF(ISNUMBER($BC5),BC5,0))/AW5,1)) -> 75.6
A6: 2 | B6: 42562 | C6: 2016 | D6: 一 | E6: 4554.71 | F6: 0.030625 | G6: -0.034825 | H6: 0.7959 | I6: 566 | J6: real | K6: 13.54 | L6: =IF(COUNT(F6)=0,50,IF(F6>=0,100,IF(F6>=-0.02,50,0))) -> 100 | M6: =IF(COUNT(G6)=0,50,IF(G6>-0.06,100,IF(G6>-0.15,50,0))) -> 100 | N6: =IF(COUNT(H6)=0,50,IF(H6>=0.6,100,IF(H6>=0.4,50,0))) -> 100 | O6: =IF(COUNT(I6)=0,50,IF(J6="proxy_vix",50,IF(I6<350,100,IF(I6<=450,50,0)))) -> 0 | P6: =IF(COUNT(K6)=0,50,IF(K6<20,100,IF(K6<=25,50,0))) -> 100 | S6: =$E6/$E5-1 -> 0.0058188837 | T6: =$K6/$K5-1 -> 0.025757576 | Y6: =IF(AX6>=70,"EASY",IF(AX6>40,"UNCERTAIN","HARD")) -> EASY | AA6: =IF($A6<200,"",AVERAGE($E5:$E6)/AVERAGE($E5:$E6)-1) | AB6: =LOOKUP($B6,07_L1政策步階!$A$4:$A$14,07_L1政策步階!$C$4:$C$14) -> 0 | AL6: =IF(ISNUMBER($AA6),IF($AA6>=0.005,100,IF($AA6>=-0.015,50,0)),"") | AM6: =IF(ISNUMBER($AB6),IF($AB6=1,100,IF($AB6=0,50,0)),"") -> 50 | AN6: =IF(ISNUMBER($AC6),IF($AC6>=0.001,100,IF($AC6>=-0.003,50,0)),"") | AO6: =IF(ISNUMBER($AD6),IF($AD6>=0.04,100,IF($AD6>=0,50,0)),"") | AP6: =IF(ISNUMBER($AE6),IF($AE6>=25,100,IF($AE6>=-75,50,0)),"") | AQ6: =IF(ISNUMBER($AF6),IF($AF6>0,100,IF($AF6>=-50,50,0)),"") | AR6: =IF(ISNUMBER($AG6),IF($AG6=1,100,IF($AG6=0,50,0)),"") | AS6: =IF(ISNUMBER($AH6),IF($AH6<0,100,IF($AH6<=20,50,0)),"") | AT6: =IF(ISNUMBER($AI6),IF($AI6<0.95,100,IF($AI6<=1,50,0)),"") | AU6: =IF(ISNUMBER($AJ6),IF($AJ6<30,0,IF($AJ6<40,50,IF($AJ6<=90,100,50))),"") | AV6: =IF(ISNUMBER($AK6),IF($AK6>-0.2,100,IF($AK6>=-0.4,50,0)),"") | AW6: =01_指標庫!$H$4*ISNUMBER($F6)+01_指標庫!$H$5*ISNUMBER($AA6)+01_指標庫!$H$6*ISNUMBER($G6)+01_指標庫!$H$7*ISNUMBER($H6)+01_指標庫!$H$8*ISNUMBER($AF6)+01_指標庫!$H$9*ISNUMBER($AG6)+01_指標庫!$H$10*ISNUMBER($AB6)+01_指標庫!$H$11*ISNUMBER($AC6)+01_指標庫!$H$12*ISNUMBER($AD6)+01_指標庫!$H$13*ISNUMBER($AE6)+01_指標庫!$H$14*ISNUMBER($I6)+01_指標庫!$H$15*ISNUMBER($AH6)+01_指標庫!$H$16*ISNUMBER($K6)+01_指標庫!$H$17*ISNUMBER($AI6)+01_指標庫!$H$18*ISNUMBER($AJ6)+01_指標庫!$H$19*ISNUMBER($AK6)+01_指標庫!$H$20*ISNUMBER($BB6)+01_指標庫!$H$21*ISNUMBER($BC6) -> 43 | AX6: =IF(AW6=0,50,ROUND((01_指標庫!$H$4*IF(ISNUMBER($F6),L6,0)+01_指標庫!$H$5*IF(ISNUMBER($AA6),AL6,0)+01_指標庫!$H$6*IF(ISNUMBER($G6),M6,0)+01_指標庫!$H$7*IF(ISNUMBER($H6),N6,0)+01_指標庫!$H$8*IF(ISNUMBER($AF6),AQ6,0)+01_指標庫!$H$9*IF(ISNUMBER($AG6),AR6,0)+01_指標庫!$H$10*IF(ISNUMBER($AB6),AM6,0)+01_指標庫!$H$11*IF(ISNUMBER($AC6),AN6,0)+01_指標庫!$H$12*IF(ISNUMBER($AD6),AO6,0)+01_指標庫!$H$13*IF(ISNUMBER($AE6),AP6,0)+01_指標庫!$H$14*IF(ISNUMBER($I6),O6,0)+01_指標庫!$H$15*IF(ISNUMBER($AH6),AS6,0)+01_指標庫!$H$16*IF(ISNUMBER($K6),P6,0)+01_指標庫!$H$17*IF(ISNUMBER($AI6),AT6,0)+01_指標庫!$H$18*IF(ISNUMBER($AJ6),AU6,0)+01_指標庫!$H$19*IF(ISNUMBER($AK6),AV6,0)+01_指標庫!$H$20*IF(ISNUMBER($BB6),BB6,0)+01_指標庫!$H$21*IF(ISNUMBER($BC6),BC6,0))/AW6,1)) -> 75.6 | BC6: =IF(OR(COUNT($AZ6)=0,COUNT($AZ5)=0),"",IF(OR($AY6/$AZ5-1<=-0.03,$AZ6/$AZ5-1<=-0.045,IF(COUNT($AZ5:$AZ6)=10,AVERAGE($AZ5:$AZ6)/AVERAGE($AZ5:$AZ6)-1<-0.01,FALSE())),0,IF(OR($AZ6/$AZ5-1<=-0.02,IF(COUNT($AZ5:$AZ6)=10,AVERAGE($AZ5:$AZ6)/AVERAGE($AZ5:$AZ6)-1<0.005,FALSE())),50,100)))
A7: 3 | B7: 42563 | C7: 2016 | D7: 二 | E7: 4577.61 | F7: 0.035435 | G7: -0.029972 | H7: 0.8163 | I7: 546 | J7: real | K7: 13.55 | L7: =IF(COUNT(F7)=0,50,IF(F7>=0,100,IF(F7>=-0.02,50,0))) -> 100 | M7: =IF(COUNT(G7)=0,50,IF(G7>-0.06,100,IF(G7>-0.15,50,0))) -> 100 | N7: =IF(COUNT(H7)=0,50,IF(H7>=0.6,100,IF(H7>=0.4,50,0))) -> 100 | O7: =IF(COUNT(I7)=0,50,IF(J7="proxy_vix",50,IF(I7<350,100,IF(I7<=450,50,0)))) -> 0 | P7: =IF(COUNT(K7)=0,50,IF(K7<20,100,IF(K7<=25,50,0))) -> 100 | S7: =$E7/$E6-1 -> 0.0050277625 | T7: =$K7/$K6-1 -> 0.00073855244 | Y7: =IF(AX7>=70,"EASY",IF(AX7>40,"UNCERTAIN","HARD")) -> EASY | AA7: =IF($A7<200,"",AVERAGE($E5:$E7)/AVERAGE($E5:$E7)-1) | AB7: =LOOKUP($B7,07_L1政策步階!$A$4:$A$14,07_L1政策步階!$C$4:$C$14) -> 0 | AL7: =IF(ISNUMBER($AA7),IF($AA7>=0.005,100,IF($AA7>=-0.015,50,0)),"") | AM7: =IF(ISNUMBER($AB7),IF($AB7=1,100,IF($AB7=0,50,0)),"") -> 50 | AN7: =IF(ISNUMBER($AC7),IF($AC7>=0.001,100,IF($AC7>=-0.003,50,0)),"") | AO7: =IF(ISNUMBER($AD7),IF($AD7>=0.04,100,IF($AD7>=0,50,0)),"") | AP7: =IF(ISNUMBER($AE7),IF($AE7>=25,100,IF($AE7>=-75,50,0)),"") | AQ7: =IF(ISNUMBER($AF7),IF($AF7>0,100,IF($AF7>=-50,50,0)),"") | AR7: =IF(ISNUMBER($AG7),IF($AG7=1,100,IF($AG7=0,50,0)),"") | AS7: =IF(ISNUMBER($AH7),IF($AH7<0,100,IF($AH7<=20,50,0)),"") | AT7: =IF(ISNUMBER($AI7),IF($AI7<0.95,100,IF($AI7<=1,50,0)),"") | AU7: =IF(ISNUMBER($AJ7),IF($AJ7<30,0,IF($AJ7<40,50,IF($AJ7<=90,100,50))),"") | AV7: =IF(ISNUMBER($AK7),IF($AK7>-0.2,100,IF($AK7>=-0.4,50,0)),"") | AW7: =01_指標庫!$H$4*ISNUMBER($F7)+01_指標庫!$H$5*ISNUMBER($AA7)+01_指標庫!$H$6*ISNUMBER($G7)+01_指標庫!$H$7*ISNUMBER($H7)+01_指標庫!$H$8*ISNUMBER($AF7)+01_指標庫!$H$9*ISNUMBER($AG7)+01_指標庫!$H$10*ISNUMBER($AB7)+01_指標庫!$H$11*ISNUMBER($AC7)+01_指標庫!$H$12*ISNUMBER($AD7)+01_指標庫!$H$13*ISNUMBER($AE7)+01_指標庫!$H$14*ISNUMBER($I7)+01_指標庫!$H$15*ISNUMBER($AH7)+01_指標庫!$H$16*ISNUMBER($K7)+01_指標庫!$H$17*ISNUMBER($AI7)+01_指標庫!$H$18*ISNUMBER($AJ7)+01_指標庫!$H$19*ISNUMBER($AK7)+01_指標庫!$H$20*ISNUMBER($BB7)+01_指標庫!$H$21*ISNUMBER($BC7) -> 43 | AX7: =IF(AW7=0,50,ROUND((01_指標庫!$H$4*IF(ISNUMBER($F7),L7,0)+01_指標庫!$H$5*IF(ISNUMBER($AA7),AL7,0)+01_指標庫!$H$6*IF(ISNUMBER($G7),M7,0)+01_指標庫!$H$7*IF(ISNUMBER($H7),N7,0)+01_指標庫!$H$8*IF(ISNUMBER($AF7),AQ7,0)+01_指標庫!$H$9*IF(ISNUMBER($AG7),AR7,0)+01_指標庫!$H$10*IF(ISNUMBER($AB7),AM7,0)+01_指標庫!$H$11*IF(ISNUMBER($AC7),AN7,0)+01_指標庫!$H$12*IF(ISNUMBER($AD7),AO7,0)+01_指標庫!$H$13*IF(ISNUMBER($AE7),AP7,0)+01_指標庫!$H$14*IF(ISNUMBER($I7),O7,0)+01_指標庫!$H$15*IF(ISNUMBER($AH7),AS7,0)+01_指標庫!$H$16*IF(ISNUMBER($K7),P7,0)+01_指標庫!$H$17*IF(ISNUMBER($AI7),AT7,0)+01_指標庫!$H$18*IF(ISNUMBER($AJ7),AU7,0)+01_指標庫!$H$19*IF(ISNUMBER($AK7),AV7,0)+01_指標庫!$H$20*IF(ISNUMBER($BB7),BB7,0)+01_指標庫!$H$21*IF(ISNUMBER($BC7),BC7,0))/AW7,1)) -> 75.6 | BC7: =IF(OR(COUNT($AZ7)=0,COUNT($AZ6)=0),"",IF(OR($AY7/$AZ6-1<=-0.03,$AZ7/$AZ6-1<=-0.045,IF(COUNT($AZ5:$AZ7)=10,AVERAGE($AZ5:$AZ7)/AVERAGE($AZ5:$AZ7)-1<-0.01,FALSE())),0,IF(OR($AZ7/$AZ6-1<=-0.02,IF(COUNT($AZ5:$AZ7)=10,AVERAGE($AZ5:$AZ7)/AVERAGE($AZ5:$AZ7)-1<0.005,FALSE())),50,100)))
A8: 4 | B8: 42564 | C8: 2016 | D8: 三 | E8: 4565.77 | F8: 0.032359 | G8: -0.032481 | H8: 0.8163 | I8: 558 | J8: real | K8: 13.04 | L8: =IF(COUNT(F8)=0,50,IF(F8>=0,100,IF(F8>=-0.02,50,0))) -> 100 | M8: =IF(COUNT(G8)=0,50,IF(G8>-0.06,100,IF(G8>-0.15,50,0))) -> 100 | N8: =IF(COUNT(H8)=0,50,IF(H8>=0.6,100,IF(H8>=0.4,50,0))) -> 100 | O8: =IF(COUNT(I8)=0,50,IF(J8="proxy_vix",50,IF(I8<350,100,IF(I8<=450,50,0)))) -> 0 | P8: =IF(COUNT(K8)=0,50,IF(K8<20,100,IF(K8<=25,50,0))) -> 100 | S8: =$E8/$E7-1 -> -0.0025865026 | T8: =$K8/$K7-1 -> -0.037638376 | Y8: =IF(AX8>=70,"EASY",IF(AX8>40,"UNCERTAIN","HARD")) -> EASY | AA8: =IF($A8<200,"",AVERAGE($E5:$E8)/AVERAGE($E5:$E8)-1) | AB8: =LOOKUP($B8,07_L1政策步階!$A$4:$A$14,07_L1政策步階!$C$4:$C$14) -> 0 | AL8: =IF(ISNUMBER($AA8),IF($AA8>=0.005,100,IF($AA8>=-0.015,50,0)),"") | AM8: =IF(ISNUMBER($AB8),IF($AB8=1,100,IF($AB8=0,50,0)),"") -> 50 | AN8: =IF(ISNUMBER($AC8),IF($AC8>=0.001,100,IF($AC8>=-0.003,50,0)),"") | AO8: =IF(ISNUMBER($AD8),IF($AD8>=0.04,100,IF($AD8>=0,50,0)),"") | AP8: =IF(ISNUMBER($AE8),IF($AE8>=25,100,IF($AE8>=-75,50,0)),"") | AQ8: =IF(ISNUMBER($AF8),IF($AF8>0,100,IF($AF8>=-50,50,0)),"") | AR8: =IF(ISNUMBER($AG8),IF($AG8=1,100,IF($AG8=0,50,0)),"") | AS8: =IF(ISNUMBER($AH8),IF($AH8<0,100,IF($AH8<=20,50,0)),"") | AT8: =IF(ISNUMBER($AI8),IF($AI8<0.95,100,IF($AI8<=1,50,0)),"") | AU8: =IF(ISNUMBER($AJ8),IF($AJ8<30,0,IF($AJ8<40,50,IF($AJ8<=90,100,50))),"") | AV8: =IF(ISNUMBER($AK8),IF($AK8>-0.2,100,IF($AK8>=-0.4,50,0)),"") | AW8: =01_指標庫!$H$4*ISNUMBER($F8)+01_指標庫!$H$5*ISNUMBER($AA8)+01_指標庫!$H$6*ISNUMBER($G8)+01_指標庫!$H$7*ISNUMBER($H8)+01_指標庫!$H$8*ISNUMBER($AF8)+01_指標庫!$H$9*ISNUMBER($AG8)+01_指標庫!$H$10*ISNUMBER($AB8)+01_指標庫!$H$11*ISNUMBER($AC8)+01_指標庫!$H$12*ISNUMBER($AD8)+01_指標庫!$H$13*ISNUMBER($AE8)+01_指標庫!$H$14*ISNUMBER($I8)+01_指標庫!$H$15*ISNUMBER($AH8)+01_指標庫!$H$16*ISNUMBER($K8)+01_指標庫!$H$17*ISNUMBER($AI8)+01_指標庫!$H$18*ISNUMBER($AJ8)+01_指標庫!$H$19*ISNUMBER($AK8)+01_指標庫!$H$20*ISNUMBER($BB8)+01_指標庫!$H$21*ISNUMBER($BC8) -> 43 | AX8: =IF(AW8=0,50,ROUND((01_指標庫!$H$4*IF(ISNUMBER($F8),L8,0)+01_指標庫!$H$5*IF(ISNUMBER($AA8),AL8,0)+01_指標庫!$H$6*IF(ISNUMBER($G8),M8,0)+01_指標庫!$H$7*IF(ISNUMBER($H8),N8,0)+01_指標庫!$H$8*IF(ISNUMBER($AF8),AQ8,0)+01_指標庫!$H$9*IF(ISNUMBER($AG8),AR8,0)+01_指標庫!$H$10*IF(ISNUMBER($AB8),AM8,0)+01_指標庫!$H$11*IF(ISNUMBER($AC8),AN8,0)+01_指標庫!$H$12*IF(ISNUMBER($AD8),AO8,0)+01_指標庫!$H$13*IF(ISNUMBER($AE8),AP8,0)+01_指標庫!$H$14*IF(ISNUMBER($I8),O8,0)+01_指標庫!$H$15*IF(ISNUMBER($AH8),AS8,0)+01_指標庫!$H$16*IF(ISNUMBER($K8),P8,0)+01_指標庫!$H$17*IF(ISNUMBER($AI8),AT8,0)+01_指標庫!$H$18*IF(ISNUMBER($AJ8),AU8,0)+01_指標庫!$H$19*IF(ISNUMBER($AK8),AV8,0)+01_指標庫!$H$20*IF(ISNUMBER($BB8),BB8,0)+01_指標庫!$H$21*IF(ISNUMBER($BC8),BC8,0))/AW8,1)) -> 75.6 | BC8: =IF(OR(COUNT($AZ8)=0,COUNT($AZ7)=0),"",IF(OR($AY8/$AZ7-1<=-0.03,$AZ8/$AZ7-1<=-0.045,IF(COUNT($AZ5:$AZ8)=10,AVERAGE($AZ5:$AZ8)/AVERAGE($AZ5:$AZ8)-1<-0.01,FALSE())),0,IF(OR($AZ8/$AZ7-1<=-0.02,IF(COUNT($AZ5:$AZ8)=10,AVERAGE($AZ5:$AZ8)/AVERAGE($AZ5:$AZ8)-1<0.005,FALSE())),50,100)))
A9: 5 | B9: 42565 | C9: 2016 | D9: 四 | E9: 4596.49 | F9: 0.038726 | G9: -0.025971 | H9: 0.8367 | I9: 544 | J9: real | K9: 12.82 | L9: =IF(COUNT(F9)=0,50,IF(F9>=0,100,IF(F9>=-0.02,50,0))) -> 100 | M9: =IF(COUNT(G9)=0,50,IF(G9>-0.06,100,IF(G9>-0.15,50,0))) -> 100 | N9: =IF(COUNT(H9)=0,50,IF(H9>=0.6,100,IF(H9>=0.4,50,0))) -> 100 | O9: =IF(COUNT(I9)=0,50,IF(J9="proxy_vix",50,IF(I9<350,100,IF(I9<=450,50,0)))) -> 0 | P9: =IF(COUNT(K9)=0,50,IF(K9<20,100,IF(K9<=25,50,0))) -> 100 | S9: =$E9/$E8-1 -> 0.0067283284 | T9: =$K9/$K8-1 -> -0.016871166 | Y9: =IF(AX9>=70,"EASY",IF(AX9>40,"UNCERTAIN","HARD")) -> EASY | AA9: =IF($A9<200,"",AVERAGE($E5:$E9)/AVERAGE($E5:$E9)-1) | AB9: =LOOKUP($B9,07_L1政策步階!$A$4:$A$14,07_L1政策步階!$C$4:$C$14) -> 0 | AL9: =IF(ISNUMBER($AA9),IF($AA9>=0.005,100,IF($AA9>=-0.015,50,0)),"") | AM9: =IF(ISNUMBER($AB9),IF($AB9=1,100,IF($AB9=0,50,0)),"") -> 50 | AN9: =IF(ISNUMBER($AC9),IF($AC9>=0.001,100,IF($AC9>=-0.003,50,0)),"") | AO9: =IF(ISNUMBER($AD9),IF($AD9>=0.04,100,IF($AD9>=0,50,0)),"") | AP9: =IF(ISNUMBER($AE9),IF($AE9>=25,100,IF($AE9>=-75,50,0)),"") | AQ9: =IF(ISNUMBER($AF9),IF($AF9>0,100,IF($AF9>=-50,50,0)),"") | AR9: =IF(ISNUMBER($AG9),IF($AG9=1,100,IF($AG9=0,50,0)),"") | AS9: =IF(ISNUMBER($AH9),IF($AH9<0,100,IF($AH9<=20,50,0)),"") | AT9: =IF(ISNUMBER($AI9),IF($AI9<0.95,100,IF($AI9<=1,50,0)),"") | AU9: =IF(ISNUMBER($AJ9),IF($AJ9<30,0,IF($AJ9<40,50,IF($AJ9<=90,100,50))),"") | AV9: =IF(ISNUMBER($AK9),IF($AK9>-0.2,100,IF($AK9>=-0.4,50,0)),"") | AW9: =01_指標庫!$H$4*ISNUMBER($F9)+01_指標庫!$H$5*ISNUMBER($AA9)+01_指標庫!$H$6*ISNUMBER($G9)+01_指標庫!$H$7*ISNUMBER($H9)+01_指標庫!$H$8*ISNUMBER($AF9)+01_指標庫!$H$9*ISNUMBER($AG9)+01_指標庫!$H$10*ISNUMBER($AB9)+01_指標庫!$H$11*ISNUMBER($AC9)+01_指標庫!$H$12*ISNUMBER($AD9)+01_指標庫!$H$13*ISNUMBER($AE9)+01_指標庫!$H$14*ISNUMBER($I9)+01_指標庫!$H$15*ISNUMBER($AH9)+01_指標庫!$H$16*ISNUMBER($K9)+01_指標庫!$H$17*ISNUMBER($AI9)+01_指標庫!$H$18*ISNUMBER($AJ9)+01_指標庫!$H$19*ISNUMBER($AK9)+01_指標庫!$H$20*ISNUMBER($BB9)+01_指標庫!$H$21*ISNUMBER($BC9) -> 43 | AX9: =IF(AW9=0,50,ROUND((01_指標庫!$H$4*IF(ISNUMBER($F9),L9,0)+01_指標庫!$H$5*IF(ISNUMBER($AA9),AL9,0)+01_指標庫!$H$6*IF(ISNUMBER($G9),M9,0)+01_指標庫!$H$7*IF(ISNUMBER($H9),N9,0)+01_指標庫!$H$8*IF(ISNUMBER($AF9),AQ9,0)+01_指標庫!$H$9*IF(ISNUMBER($AG9),AR9,0)+01_指標庫!$H$10*IF(ISNUMBER($AB9),AM9,0)+01_指標庫!$H$11*IF(ISNUMBER($AC9),AN9,0)+01_指標庫!$H$12*IF(ISNUMBER($AD9),AO9,0)+01_指標庫!$H$13*IF(ISNUMBER($AE9),AP9,0)+01_指標庫!$H$14*IF(ISNUMBER($I9),O9,0)+01_指標庫!$H$15*IF(ISNUMBER($AH9),AS9,0)+01_指標庫!$H$16*IF(ISNUMBER($K9),P9,0)+01_指標庫!$H$17*IF(ISNUMBER($AI9),AT9,0)+01_指標庫!$H$18*IF(ISNUMBER($AJ9),AU9,0)+01_指標庫!$H$19*IF(ISNUMBER($AK9),AV9,0)+01_指標庫!$H$20*IF(ISNUMBER($BB9),BB9,0)+01_指標庫!$H$21*IF(ISNUMBER($BC9),BC9,0))/AW9,1)) -> 75.6 | BC9: =IF(OR(COUNT($AZ9)=0,COUNT($AZ8)=0),"",IF(OR($AY9/$AZ8-1<=-0.03,$AZ9/$AZ8-1<=-0.045,IF(COUNT($AZ5:$AZ9)=10,AVERAGE($AZ5:$AZ9)/AVERAGE($AZ5:$AZ9)-1<-0.01,FALSE())),0,IF(OR($AZ9/$AZ8-1<=-0.02,IF(COUNT($AZ5:$AZ9)=10,AVERAGE($AZ5:$AZ9)/AVERAGE($AZ5:$AZ9)-1<0.005,FALSE())),50,100)))
A10: 6 | B10: 42566 | C10: 2016 | D10: 五 | E10: 4589.83 | F10: 0.036628 | G10: -0.027383 | H10: 0.8367 | I10: 542 | J10: real | K10: 12.67 | L10: =IF(COUNT(F10)=0,50,IF(F10>=0,100,IF(F10>=-0.02,50,0))) -> 100 | M10: =IF(COUNT(G10)=0,50,IF(G10>-0.06,100,IF(G10>-0.15,50,0))) -> 100 | N10: =IF(COUNT(H10)=0,50,IF(H10>=0.6,100,IF(H10>=0.4,50,0))) -> 100 | O10: =IF(COUNT(I10)=0,50,IF(J10="proxy_vix",50,IF(I10<350,100,IF(I10<=450,50,0)))) -> 0 | P10: =IF(COUNT(K10)=0,50,IF(K10<20,100,IF(K10<=25,50,0))) -> 100 | S10: =$E10/$E9-1 -> -0.0014489317 | T10: =$K10/$K9-1 -> -0.011700468 | Y10: =IF(AX10>=70,"EASY",IF(AX10>40,"UNCERTAIN","HARD")) -> EASY | AA10: =IF($A10<200,"",AVERAGE($E5:$E10)/AVERAGE($E5:$E10)-1) | AB10: =LOOKUP($B10,07_L1政策步階!$A$4:$A$14,07_L1政策步階!$C$4:$C$14) -> 0 | AL10: =IF(ISNUMBER($AA10),IF($AA10>=0.005,100,IF($AA10>=-0.015,50,0)),"") | AM10: =IF(ISNUMBER($AB10),IF($AB10=1,100,IF($AB10=0,50,0)),"") -> 50 | AN10: =IF(ISNUMBER($AC10),IF($AC10>=0.001,100,IF($AC10>=-0.003,50,0)),"") | AO10: =IF(ISNUMBER($AD10),IF($AD10>=0.04,100,IF($AD10>=0,50,0)),"") | AP10: =IF(ISNUMBER($AE10),IF($AE10>=25,100,IF($AE10>=-75,50,0)),"") | AQ10: =IF(ISNUMBER($AF10),IF($AF10>0,100,IF($AF10>=-50,50,0)),"") | AR10: =IF(ISNUMBER($AG10),IF($AG10=1,100,IF($AG10=0,50,0)),"") | AS10: =IF(ISNUMBER($AH10),IF($AH10<0,100,IF($AH10<=20,50,0)),"") | AT10: =IF(ISNUMBER($AI10),IF($AI10<0.95,100,IF($AI10<=1,50,0)),"") | AU10: =IF(ISNUMBER($AJ10),IF($AJ10<30,0,IF($AJ10<40,50,IF($AJ10<=90,100,50))),"") | AV10: =IF(ISNUMBER($AK10),IF($AK10>-0.2,100,IF($AK10>=-0.4,50,0)),"") | AW10: =01_指標庫!$H$4*ISNUMBER($F10)+01_指標庫!$H$5*ISNUMBER($AA10)+01_指標庫!$H$6*ISNUMBER($G10)+01_指標庫!$H$7*ISNUMBER($H10)+01_指標庫!$H$8*ISNUMBER($AF10)+01_指標庫!$H$9*ISNUMBER($AG10)+01_指標庫!$H$10*ISNUMBER($AB10)+01_指標庫!$H$11*ISNUMBER($AC10)+01_指標庫!$H$12*ISNUMBER($AD10)+01_指標庫!$H$13*ISNUMBER($AE10)+01_指標庫!$H$14*ISNUMBER($I10)+01_指標庫!$H$15*ISNUMBER($AH10)+01_指標庫!$H$16*ISNUMBER($K10)+01_指標庫!$H$17*ISNUMBER($AI10)+01_指標庫!$H$18*ISNUMBER($AJ10)+01_指標庫!$H$19*ISNUMBER($AK10)+01_指標庫!$H$20*ISNUMBER($BB10)+01_指標庫!$H$21*ISNUMBER($BC10) -> 43 | AX10: =IF(AW10=0,50,ROUND((01_指標庫!$H$4*IF(ISNUMBER($F10),L10,0)+01_指標庫!$H$5*IF(ISNUMBER($AA10),AL10,0)+01_指標庫!$H$6*IF(ISNUMBER($G10),M10,0)+01_指標庫!$H$7*IF(ISNUMBER($H10),N10,0)+01_指標庫!$H$8*IF(ISNUMBER($AF10),AQ10,0)+01_指標庫!$H$9*IF(ISNUMBER($AG10),AR10,0)+01_指標庫!$H$10*IF(ISNUMBER($AB10),AM10,0)+01_指標庫!$H$11*IF(ISNUMBER($AC10),AN10,0)+01_指標庫!$H$12*IF(ISNUMBER($AD10),AO10,0)+01_指標庫!$H$13*IF(ISNUMBER($AE10),AP10,0)+01_指標庫!$H$14*IF(ISNUMBER($I10),O10,0)+01_指標庫!$H$15*IF(ISNUMBER($AH10),AS10,0)+01_指標庫!$H$16*IF(ISNUMBER($K10),P10,0)+01_指標庫!$H$17*IF(ISNUMBER($AI10),AT10,0)+01_指標庫!$H$18*IF(ISNUMBER($AJ10),AU10,0)+01_指標庫!$H$19*IF(ISNUMBER($AK10),AV10,0)+01_指標庫!$H$20*IF(ISNUMBER($BB10),BB10,0)+01_指標庫!$H$21*IF(ISNUMBER($BC10),BC10,0))/AW10,1)) -> 75.6 | BC10: =IF(OR(COUNT($AZ10)=0,COUNT($AZ9)=0),"",IF(OR($AY10/$AZ9-1<=-0.03,$AZ10/$AZ9-1<=-0.045,IF(COUNT($AZ5:$AZ10)=10,AVERAGE($AZ6:$AZ10)/AVERAGE($AZ5:$AZ10)-1<-0.01,FALSE())),0,IF(OR($AZ10/$AZ9-1<=-0.02,IF(COUNT($AZ5:$AZ10)=10,AVERAGE($AZ6:$AZ10)/AVERAGE($AZ5:$AZ10)-1<0.005,FALSE())),50,100)))
A11: 7 | B11: 42569 | C11: 2016 | D11: 一 | E11: 4619.68 | F11: 0.042853 | G11: -0.021057 | H11: 0.8367 | I11: 544 | J11: real | K11: 12.44 | L11: =IF(COUNT(F11)=0,50,IF(F11>=0,100,IF(F11>=-0.02,50,0))) -> 100 | M11: =IF(COUNT(G11)=0,50,IF(G11>-0.06,100,IF(G11>-0.15,50,0))) -> 100 | N11: =IF(COUNT(H11)=0,50,IF(H11>=0.6,100,IF(H11>=0.4,50,0))) -> 100 | O11: =IF(COUNT(I11)=0,50,IF(J11="proxy_vix",50,IF(I11<350,100,IF(I11<=450,50,0)))) -> 0 | P11: =IF(COUNT(K11)=0,50,IF(K11<20,100,IF(K11<=25,50,0))) -> 100 | S11: =$E11/$E10-1 -> 0.0065035088 | T11: =$K11/$K10-1 -> -0.018153118 | Y11: =IF(AX11>=70,"EASY",IF(AX11>40,"UNCERTAIN","HARD")) -> EASY | AA11: =IF($A11<200,"",AVERAGE($E5:$E11)/AVERAGE($E5:$E11)-1) | AB11: =LOOKUP($B11,07_L1政策步階!$A$4:$A$14,07_L1政策步階!$C$4:$C$14) -> 0 | AL11: =IF(ISNUMBER($AA11),IF($AA11>=0.005,100,IF($AA11>=-0.015,50,0)),"") | AM11: =IF(ISNUMBER($AB11),IF($AB11=1,100,IF($AB11=0,50,0)),"") -> 50 | AN11: =IF(ISNUMBER($AC11),IF($AC11>=0.001,100,IF($AC11>=-0.003,50,0)),"") | AO11: =IF(ISNUMBER($AD11),IF($AD11>=0.04,100,IF($AD11>=0,50,0)),"") | AP11: =IF(ISNUMBER($AE11),IF($AE11>=25,100,IF($AE11>=-75,50,0)),"") | AQ11: =IF(ISNUMBER($AF11),IF($AF11>0,100,IF($AF11>=-50,50,0)),"") | AR11: =IF(ISNUMBER($AG11),IF($AG11=1,100,IF($AG11=0,50,0)),"") | AS11: =IF(ISNUMBER($AH11),IF($AH11<0,100,IF($AH11<=20,50,0)),"") | AT11: =IF(ISNUMBER($AI11),IF($AI11<0.95,100,IF($AI11<=1,50,0)),"") | AU11: =IF(ISNUMBER($AJ11),IF($AJ11<30,0,IF($AJ11<40,50,IF($AJ11<=90,100,50))),"") | AV11: =IF(ISNUMBER($AK11),IF($AK11>-0.2,100,IF($AK11>=-0.4,50,0)),"") | AW11: =01_指標庫!$H$4*ISNUMBER($F11)+01_指標庫!$H$5*ISNUMBER($AA11)+01_指標庫!$H$6*ISNUMBER($G11)+01_指標庫!$H$7*ISNUMBER($H11)+01_指標庫!$H$8*ISNUMBER($AF11)+01_指標庫!$H$9*ISNUMBER($AG11)+01_指標庫!$H$10*ISNUMBER($AB11)+01_指標庫!$H$11*ISNUMBER($AC11)+01_指標庫!$H$12*ISNUMBER($AD11)+01_指標庫!$H$13*ISNUMBER($AE11)+01_指標庫!$H$14*ISNUMBER($I11)+01_指標庫!$H$15*ISNUMBER($AH11)+01_指標庫!$H$16*ISNUMBER($K11)+01_指標庫!$H$17*ISNUMBER($AI11)+01_指標庫!$H$18*ISNUMBER($AJ11)+01_指標庫!$H$19*ISNUMBER($AK11)+01_指標庫!$H$20*ISNUMBER($BB11)+01_指標庫!$H$21*ISNUMBER($BC11) -> 43 | AX11: =IF(AW11=0,50,ROUND((01_指標庫!$H$4*IF(ISNUMBER($F11),L11,0)+01_指標庫!$H$5*IF(ISNUMBER($AA11),AL11,0)+01_指標庫!$H$6*IF(ISNUMBER($G11),M11,0)+01_指標庫!$H$7*IF(ISNUMBER($H11),N11,0)+01_指標庫!$H$8*IF(ISNUMBER($AF11),AQ11,0)+01_指標庫!$H$9*IF(ISNUMBER($AG11),AR11,0)+01_指標庫!$H$10*IF(ISNUMBER($AB11),AM11,0)+01_指標庫!$H$11*IF(ISNUMBER($AC11),AN11,0)+01_指標庫!$H$12*IF(ISNUMBER($AD11),AO11,0)+01_指標庫!$H$13*IF(ISNUMBER($AE11),AP11,0)+01_指標庫!$H$14*IF(ISNUMBER($I11),O11,0)+01_指標庫!$H$15*IF(ISNUMBER($AH11),AS11,0)+01_指標庫!$H$16*IF(ISNUMBER($K11),P11,0)+01_指標庫!$H$17*IF(ISNUMBER($AI11),AT11,0)+01_指標庫!$H$18*IF(ISNUMBER($AJ11),AU11,0)+01_指標庫!$H$19*IF(ISNUMBER($AK11),AV11,0)+01_指標庫!$H$20*IF(ISNUMBER($BB11),BB11,0)+01_指標庫!$H$21*IF(ISNUMBER($BC11),BC11,0))/AW11,1)) -> 75.6 | BC11: =IF(OR(COUNT($AZ11)=0,COUNT($AZ10)=0),"",IF(OR($AY11/$AZ10-1<=-0.03,$AZ11/$AZ10-1<=-0.045,IF(COUNT($AZ5:$AZ11)=10,AVERAGE($AZ7:$AZ11)/AVERAGE($AZ5:$AZ11)-1<-0.01,FALSE())),0,IF(OR($AZ11/$AZ10-1<=-0.02,IF(COUNT($AZ5:$AZ11)=10,AVERAGE($AZ7:$AZ11)/AVERAGE($AZ5:$AZ11)-1<0.005,FALSE())),50,100)))
A12: 8 | B12: 42570 | C12: 2016 | D12: 二 | E12: 4603.28 | F12: 0.03867 | G12: -0.024532 | H12: 0.8367 | I12: 545 | J12: real | K12: 11.97 | L12: =IF(COUNT(F12)=0,50,IF(F12>=0,100,IF(F12>=-0.02,50,0))) -> 100 | M12: =IF(COUNT(G12)=0,50,IF(G12>-0.06,100,IF(G12>-0.15,50,0))) -> 100 | N12: =IF(COUNT(H12)=0,50,IF(H12>=0.6,100,IF(H12>=0.4,50,0))) -> 100 | O12: =IF(COUNT(I12)=0,50,IF(J12="proxy_vix",50,IF(I12<350,100,IF(I12<=450,50,0)))) -> 0 | P12: =IF(COUNT(K12)=0,50,IF(K12<20,100,IF(K12<=25,50,0))) -> 100 | S12: =$E12/$E11-1 -> -0.0035500294 | T12: =$K12/$K11-1 -> -0.03778135 | Y12: =IF(AX12>=70,"EASY",IF(AX12>40,"UNCERTAIN","HARD")) -> EASY | AA12: =IF($A12<200,"",AVERAGE($E5:$E12)/AVERAGE($E5:$E12)-1) | AB12: =LOOKUP($B12,07_L1政策步階!$A$4:$A$14,07_L1政策步階!$C$4:$C$14) -> 0 | AL12: =IF(ISNUMBER($AA12),IF($AA12>=0.005,100,IF($AA12>=-0.015,50,0)),"") | AM12: =IF(ISNUMBER($AB12),IF($AB12=1,100,IF($AB12=0,50,0)),"") -> 50 | AN12: =IF(ISNUMBER($AC12),IF($AC12>=0.001,100,IF($AC12>=-0.003,50,0)),"") | AO12: =IF(ISNUMBER($AD12),IF($AD12>=0.04,100,IF($AD12>=0,50,0)),"") | AP12: =IF(ISNUMBER($AE12),IF($AE12>=25,100,IF($AE12>=-75,50,0)),"") | AQ12: =IF(ISNUMBER($AF12),IF($AF12>0,100,IF($AF12>=-50,50,0)),"") | AR12: =IF(ISNUMBER($AG12),IF($AG12=1,100,IF($AG12=0,50,0)),"") | AS12: =IF(ISNUMBER($AH12),IF($AH12<0,100,IF($AH12<=20,50,0)),"") | AT12: =IF(ISNUMBER($AI12),IF($AI12<0.95,100,IF($AI12<=1,50,0)),"") | AU12: =IF(ISNUMBER($AJ12),IF($AJ12<30,0,IF($AJ12<40,50,IF($AJ12<=90,100,50))),"") | AV12: =IF(ISNUMBER($AK12),IF($AK12>-0.2,100,IF($AK12>=-0.4,50,0)),"") | AW12: =01_指標庫!$H$4*ISNUMBER($F12)+01_指標庫!$H$5*ISNUMBER($AA12)+01_指標庫!$H$6*ISNUMBER($G12)+01_指標庫!$H$7*ISNUMBER($H12)+01_指標庫!$H$8*ISNUMBER($AF12)+01_指標庫!$H$9*ISNUMBER($AG12)+01_指標庫!$H$10*ISNUMBER($AB12)+01_指標庫!$H$11*ISNUMBER($AC12)+01_指標庫!$H$12*ISNUMBER($AD12)+01_指標庫!$H$13*ISNUMBER($AE12)+01_指標庫!$H$14*ISNUMBER($I12)+01_指標庫!$H$15*ISNUMBER($AH12)+01_指標庫!$H$16*ISNUMBER($K12)+01_指標庫!$H$17*ISNUMBER($AI12)+01_指標庫!$H$18*ISNUMBER($AJ12)+01_指標庫!$H$19*ISNUMBER($AK12)+01_指標庫!$H$20*ISNUMBER($BB12)+01_指標庫!$H$21*ISNUMBER($BC12) -> 43 | AX12: =IF(AW12=0,50,ROUND((01_指標庫!$H$4*IF(ISNUMBER($F12),L12,0)+01_指標庫!$H$5*IF(ISNUMBER($AA12),AL12,0)+01_指標庫!$H$6*IF(ISNUMBER($G12),M12,0)+01_指標庫!$H$7*IF(ISNUMBER($H12),N12,0)+01_指標庫!$H$8*IF(ISNUMBER($AF12),AQ12,0)+01_指標庫!$H$9*IF(ISNUMBER($AG12),AR12,0)+01_指標庫!$H$10*IF(ISNUMBER($AB12),AM12,0)+01_指標庫!$H$11*IF(ISNUMBER($AC12),AN12,0)+01_指標庫!$H$12*IF(ISNUMBER($AD12),AO12,0)+01_指標庫!$H$13*IF(ISNUMBER($AE12),AP12,0)+01_指標庫!$H$14*IF(ISNUMBER($I12),O12,0)+01_指標庫!$H$15*IF(ISNUMBER($AH12),AS12,0)+01_指標庫!$H$16*IF(ISNUMBER($K12),P12,0)+01_指標庫!$H$17*IF(ISNUMBER($AI12),AT12,0)+01_指標庫!$H$18*IF(ISNUMBER($AJ12),AU12,0)+01_指標庫!$H$19*IF(ISNUMBER($AK12),AV12,0)+01_指標庫!$H$20*IF(ISNUMBER($BB12),BB12,0)+01_指標庫!$H$21*IF(ISNUMBER($BC12),BC12,0))/AW12,1)) -> 75.6 | BC12: =IF(OR(COUNT($AZ12)=0,COUNT($AZ11)=0),"",IF(OR($AY12/$AZ11-1<=-0.03,$AZ12/$AZ11-1<=-0.045,IF(COUNT($AZ5:$AZ12)=10,AVERAGE($AZ8:$AZ12)/AVERAGE($AZ5:$AZ12)-1<-0.01,FALSE())),0,IF(OR($AZ12/$AZ11-1<=-0.02,IF(COUNT($AZ5:$AZ12)=10,AVERAGE($AZ8:$AZ12)/AVERAGE($AZ5:$AZ12)-1<0.005,FALSE())),50,100)))
A13: 9 | B13: 42571 | C13: 2016 | D13: 三 | E13: 4657.2 | F13: 0.050374 | G13: -0.013106 | H13: 0.8571 | I13: 540 | J13: real | K13: 11.77 | L13: =IF(COUNT(F13)=0,50,IF(F13>=0,100,IF(F13>=-0.02,50,0))) -> 100 | M13: =IF(COUNT(G13)=0,50,IF(G13>-0.06,100,IF(G13>-0.15,50,0))) -> 100 | N13: =IF(COUNT(H13)=0,50,IF(H13>=0.6,100,IF(H13>=0.4,50,0))) -> 100 | O13: =IF(COUNT(I13)=0,50,IF(J13="proxy_vix",50,IF(I13<350,100,IF(I13<=450,50,0)))) -> 0 | P13: =IF(COUNT(K13)=0,50,IF(K13<20,100,IF(K13<=25,50,0))) -> 100 | S13: =$E13/$E12-1 -> 0.011713387 | T13: =$K13/$K12-1 -> -0.016708438 | Y13: =IF(AX13>=70,"EASY",IF(AX13>40,"UNCERTAIN","HARD")) -> EASY | AA13: =IF($A13<200,"",AVERAGE($E5:$E13)/AVERAGE($E5:$E13)-1) | AB13: =LOOKUP($B13,07_L1政策步階!$A$4:$A$14,07_L1政策步階!$C$4:$C$14) -> 0 | AL13: =IF(ISNUMBER($AA13),IF($AA13>=0.005,100,IF($AA13>=-0.015,50,0)),"") | AM13: =IF(ISNUMBER($AB13),IF($AB13=1,100,IF($AB13=0,50,0)),"") -> 50 | AN13: =IF(ISNUMBER($AC13),IF($AC13>=0.001,100,IF($AC13>=-0.003,50,0)),"") | AO13: =IF(ISNUMBER($AD13),IF($AD13>=0.04,100,IF($AD13>=0,50,0)),"") | AP13: =IF(ISNUMBER($AE13),IF($AE13>=25,100,IF($AE13>=-75,50,0)),"") | AQ13: =IF(ISNUMBER($AF13),IF($AF13>0,100,IF($AF13>=-50,50,0)),"") | AR13: =IF(ISNUMBER($AG13),IF($AG13=1,100,IF($AG13=0,50,0)),"") | AS13: =IF(ISNUMBER($AH13),IF($AH13<0,100,IF($AH13<=20,50,0)),"") | AT13: =IF(ISNUMBER($AI13),IF($AI13<0.95,100,IF($AI13<=1,50,0)),"") | AU13: =IF(ISNUMBER($AJ13),IF($AJ13<30,0,IF($AJ13<40,50,IF($AJ13<=90,100,50))),"") | AV13: =IF(ISNUMBER($AK13),IF($AK13>-0.2,100,IF($AK13>=-0.4,50,0)),"") | AW13: =01_指標庫!$H$4*ISNUMBER($F13)+01_指標庫!$H$5*ISNUMBER($AA13)+01_指標庫!$H$6*ISNUMBER($G13)+01_指標庫!$H$7*ISNUMBER($H13)+01_指標庫!$H$8*ISNUMBER($AF13)+01_指標庫!$H$9*ISNUMBER($AG13)+01_指標庫!$H$10*ISNUMBER($AB13)+01_指標庫!$H$11*ISNUMBER($AC13)+01_指標庫!$H$12*ISNUMBER($AD13)+01_指標庫!$H$13*ISNUMBER($AE13)+01_指標庫!$H$14*ISNUMBER($I13)+01_指標庫!$H$15*ISNUMBER($AH13)+01_指標庫!$H$16*ISNUMBER($K13)+01_指標庫!$H$17*ISNUMBER($AI13)+01_指標庫!$H$18*ISNUMBER($AJ13)+01_指標庫!$H$19*ISNUMBER($AK13)+01_指標庫!$H$20*ISNUMBER($BB13)+01_指標庫!$H$21*ISNUMBER($BC13) -> 43 | AX13: =IF(AW13=0,50,ROUND((01_指標庫!$H$4*IF(ISNUMBER($F13),L13,0)+01_指標庫!$H$5*IF(ISNUMBER($AA13),AL13,0)+01_指標庫!$H$6*IF(ISNUMBER($G13),M13,0)+01_指標庫!$H$7*IF(ISNUMBER($H13),N13,0)+01_指標庫!$H$8*IF(ISNUMBER($AF13),AQ13,0)+01_指標庫!$H$9*IF(ISNUMBER($AG13),AR13,0)+01_指標庫!$H$10*IF(ISNUMBER($AB13),AM13,0)+01_指標庫!$H$11*IF(ISNUMBER($AC13),AN13,0)+01_指標庫!$H$12*IF(ISNUMBER($AD13),AO13,0)+01_指標庫!$H$13*IF(ISNUMBER($AE13),AP13,0)+01_指標庫!$H$14*IF(ISNUMBER($I13),O13,0)+01_指標庫!$H$15*IF(ISNUMBER($AH13),AS13,0)+01_指標庫!$H$16*IF(ISNUMBER($K13),P13,0)+01_指標庫!$H$17*IF(ISNUMBER($AI13),AT13,0)+01_指標庫!$H$18*IF(ISNUMBER($AJ13),AU13,0)+01_指標庫!$H$19*IF(ISNUMBER($AK13),AV13,0)+01_指標庫!$H$20*IF(ISNUMBER($BB13),BB13,0)+01_指標庫!$H$21*IF(ISNUMBER($BC13),BC13,0))/AW13,1)) -> 75.6 | BC13: =IF(OR(COUNT($AZ13)=0,COUNT($AZ12)=0),"",IF(OR($AY13/$AZ12-1<=-0.03,$AZ13/$AZ12-1<=-0.045,IF(COUNT($AZ5:$AZ13)=10,AVERAGE($AZ9:$AZ13)/AVERAGE($AZ5:$AZ13)-1<-0.01,FALSE())),0,IF(OR($AZ13/$AZ12-1<=-0.02,IF(COUNT($AZ5:$AZ13)=10,AVERAGE($AZ9:$AZ13)/AVERAGE($AZ5:$AZ13)-1<0.005,FALSE())),50,100)))
A14: 10 | B14: 42572 | C14: 2016 | D14: 四 | E14: 4647.02 | F14: 0.047706 | G14: -0.015264 | H14: 0.8571 | I14: 541 | J14: real | K14: 12.74 | L14: =IF(COUNT(F14)=0,50,IF(F14>=0,100,IF(F14>=-0.02,50,0))) -> 100 | M14: =IF(COUNT(G14)=0,50,IF(G14>-0.06,100,IF(G14>-0.15,50,0))) -> 100 | N14: =IF(COUNT(H14)=0,50,IF(H14>=0.6,100,IF(H14>=0.4,50,0))) -> 100 | O14: =IF(COUNT(I14)=0,50,IF(J14="proxy_vix",50,IF(I14<350,100,IF(I14<=450,50,0)))) -> 0 | P14: =IF(COUNT(K14)=0,50,IF(K14<20,100,IF(K14<=25,50,0))) -> 100 | S14: =$E14/$E13-1 -> -0.0021858628 | T14: =$K14/$K13-1 -> 0.082412914 | Y14: =IF(AX14>=70,"EASY",IF(AX14>40,"UNCERTAIN","HARD")) -> EASY | AA14: =IF($A14<200,"",AVERAGE($E5:$E14)/AVERAGE($E5:$E14)-1) | AB14: =LOOKUP($B14,07_L1政策步階!$A$4:$A$14,07_L1政策步階!$C$4:$C$14) -> 0 | AL14: =IF(ISNUMBER($AA14),IF($AA14>=0.005,100,IF($AA14>=-0.015,50,0)),"") | AM14: =IF(ISNUMBER($AB14),IF($AB14=1,100,IF($AB14=0,50,0)),"") -> 50 | AN14: =IF(ISNUMBER($AC14),IF($AC14>=0.001,100,IF($AC14>=-0.003,50,0)),"") | AO14: =IF(ISNUMBER($AD14),IF($AD14>=0.04,100,IF($AD14>=0,50,0)),"") | AP14: =IF(ISNUMBER($AE14),IF($AE14>=25,100,IF($AE14>=-75,50,0)),"") | AQ14: =IF(ISNUMBER($AF14),IF($AF14>0,100,IF($AF14>=-50,50,0)),"") | AR14: =IF(ISNUMBER($AG14),IF($AG14=1,100,IF($AG14=0,50,0)),"") | AS14: =IF(ISNUMBER($AH14),IF($AH14<0,100,IF($AH14<=20,50,0)),"") | AT14: =IF(ISNUMBER($AI14),IF($AI14<0.95,100,IF($AI14<=1,50,0)),"") | AU14: =IF(ISNUMBER($AJ14),IF($AJ14<30,0,IF($AJ14<40,50,IF($AJ14<=90,100,50))),"") | AV14: =IF(ISNUMBER($AK14),IF($AK14>-0.2,100,IF($AK14>=-0.4,50,0)),"") | AW14: =01_指標庫!$H$4*ISNUMBER($F14)+01_指標庫!$H$5*ISNUMBER($AA14)+01_指標庫!$H$6*ISNUMBER($G14)+01_指標庫!$H$7*ISNUMBER($H14)+01_指標庫!$H$8*ISNUMBER($AF14)+01_指標庫!$H$9*ISNUMBER($AG14)+01_指標庫!$H$10*ISNUMBER($AB14)+01_指標庫!$H$11*ISNUMBER($AC14)+01_指標庫!$H$12*ISNUMBER($AD14)+01_指標庫!$H$13*ISNUMBER($AE14)+01_指標庫!$H$14*ISNUMBER($I14)+01_指標庫!$H$15*ISNUMBER($AH14)+01_指標庫!$H$16*ISNUMBER($K14)+01_指標庫!$H$17*ISNUMBER($AI14)+01_指標庫!$H$18*ISNUMBER($AJ14)+01_指標庫!$H$19*ISNUMBER($AK14)+01_指標庫!$H$20*ISNUMBER($BB14)+01_指標庫!$H$21*ISNUMBER($BC14) -> 49 | AX14: =IF(AW14=0,50,ROUND((01_指標庫!$H$4*IF(ISNUMBER($F14),L14,0)+01_指標庫!$H$5*IF(ISNUMBER($AA14),AL14,0)+01_指標庫!$H$6*IF(ISNUMBER($G14),M14,0)+01_指標庫!$H$7*IF(ISNUMBER($H14),N14,0)+01_指標庫!$H$8*IF(ISNUMBER($AF14),AQ14,0)+01_指標庫!$H$9*IF(ISNUMBER($AG14),AR14,0)+01_指標庫!$H$10*IF(ISNUMBER($AB14),AM14,0)+01_指標庫!$H$11*IF(ISNUMBER($AC14),AN14,0)+01_指標庫!$H$12*IF(ISNUMBER($AD14),AO14,0)+01_指標庫!$H$13*IF(ISNUMBER($AE14),AP14,0)+01_指標庫!$H$14*IF(ISNUMBER($I14),O14,0)+01_指標庫!$H$15*IF(ISNUMBER($AH14),AS14,0)+01_指標庫!$H$16*IF(ISNUMBER($K14),P14,0)+01_指標庫!$H$17*IF(ISNUMBER($AI14),AT14,0)+01_指標庫!$H$18*IF(ISNUMBER($AJ14),AU14,0)+01_指標庫!$H$19*IF(ISNUMBER($AK14),AV14,0)+01_指標庫!$H$20*IF(ISNUMBER($BB14),BB14,0)+01_指標庫!$H$21*IF(ISNUMBER($BC14),BC14,0))/AW14,1)) -> 72.4 | BA14: =AVERAGE($E10:$E14)/AVERAGE($E5:$E14)-1 -> 0.0064011824 | BB14: =IF(ISNUMBER($BA14),IF(OR($S14<=-0.03,$BA14<-0.003),0,IF(OR($S14<=-0.02,$BA14<0.01),50,100)),"") -> 50 | BC14: =IF(OR(COUNT($AZ14)=0,COUNT($AZ13)=0),"",IF(OR($AY14/$AZ13-1<=-0.03,$AZ14/$AZ13-1<=-0.045,IF(COUNT($AZ5:$AZ14)=10,AVERAGE($AZ10:$AZ14)/AVERAGE($AZ5:$AZ14)-1<-0.01,FALSE())),0,IF(OR($AZ14/$AZ13-1<=-0.02,IF(COUNT($AZ5:$AZ14)=10,AVERAGE($AZ10:$AZ14)/AVERAGE($AZ5:$AZ14)-1<0.005,FALSE())),50,100)))
A15: 11 | B15: 42573 | C15: 2016 | D15: 五 | E15: 4666.07 | F15: 0.051575 | G15: -0.011227 | H15: 0.8571 | I15: 539 | J15: real | K15: 12.02 | L15: =IF(COUNT(F15)=0,50,IF(F15>=0,100,IF(F15>=-0.02,50,0))) -> 100 | M15: =IF(COUNT(G15)=0,50,IF(G15>-0.06,100,IF(G15>-0.15,50,0))) -> 100 | N15: =IF(COUNT(H15)=0,50,IF(H15>=0.6,100,IF(H15>=0.4,50,0))) -> 100 | O15: =IF(COUNT(I15)=0,50,IF(J15="proxy_vix",50,IF(I15<350,100,IF(I15<=450,50,0)))) -> 0 | P15: =IF(COUNT(K15)=0,50,IF(K15<20,100,IF(K15<=25,50,0))) -> 100 | S15: =$E15/$E14-1 -> 0.0040994013 | T15: =$K15/$K14-1 -> -0.056514914 | Y15: =IF(AX15>=70,"EASY",IF(AX15>40,"UNCERTAIN","HARD")) -> EASY | AA15: =IF($A15<200,"",AVERAGE($E5:$E15)/AVERAGE($E5:$E15)-1) | AB15: =LOOKUP($B15,07_L1政策步階!$A$4:$A$14,07_L1政策步階!$C$4:$C$14) -> 0 | AL15: =IF(ISNUMBER($AA15),IF($AA15>=0.005,100,IF($AA15>=-0.015,50,0)),"") | AM15: =IF(ISNUMBER($AB15),IF($AB15=1,100,IF($AB15=0,50,0)),"") -> 50 | AN15: =IF(ISNUMBER($AC15),IF($AC15>=0.001,100,IF($AC15>=-0.003,50,0)),"") | AO15: =IF(ISNUMBER($AD15),IF($AD15>=0.04,100,IF($AD15>=0,50,0)),"") | AP15: =IF(ISNUMBER($AE15),IF($AE15>=25,100,IF($AE15>=-75,50,0)),"") | AQ15: =IF(ISNUMBER($AF15),IF($AF15>0,100,IF($AF15>=-50,50,0)),"") | AR15: =IF(ISNUMBER($AG15),IF($AG15=1,100,IF($AG15=0,50,0)),"") | AS15: =IF(ISNUMBER($AH15),IF($AH15<0,100,IF($AH15<=20,50,0)),"") | AT15: =IF(ISNUMBER($AI15),IF($AI15<0.95,100,IF($AI15<=1,50,0)),"") | AU15: =IF(ISNUMBER($AJ15),IF($AJ15<30,0,IF($AJ15<40,50,IF($AJ15<=90,100,50))),"") | AV15: =IF(ISNUMBER($AK15),IF($AK15>-0.2,100,IF($AK15>=-0.4,50,0)),"") | AW15: =01_指標庫!$H$4*ISNUMBER($F15)+01_指標庫!$H$5*ISNUMBER($AA15)+01_指標庫!$H$6*ISNUMBER($G15)+01_指標庫!$H$7*ISNUMBER($H15)+01_指標庫!$H$8*ISNUMBER($AF15)+01_指標庫!$H$9*ISNUMBER($AG15)+01_指標庫!$H$10*ISNUMBER($AB15)+01_指標庫!$H$11*ISNUMBER($AC15)+01_指標庫!$H$12*ISNUMBER($AD15)+01_指標庫!$H$13*ISNUMBER($AE15)+01_指標庫!$H$14*ISNUMBER($I15)+01_指標庫!$H$15*ISNUMBER($AH15)+01_指標庫!$H$16*ISNUMBER($K15)+01_指標庫!$H$17*ISNUMBER($AI15)+01_指標庫!$H$18*ISNUMBER($AJ15)+01_指標庫!$H$19*ISNUMBER($AK15)+01_指標庫!$H$20*ISNUMBER($BB15)+01_指標庫!$H$21*ISNUMBER($BC15) -> 49 | AX15: =IF(AW15=0,50,ROUND((01_指標庫!$H$4*IF(ISNUMBER($F15),L15,0)+01_指標庫!$H$5*IF(ISNUMBER($AA15),AL15,0)+01_指標庫!$H$6*IF(ISNUMBER($G15),M15,0)+01_指標庫!$H$7*IF(ISNUMBER($H15),N15,0)+01_指標庫!$H$8*IF(ISNUMBER($AF15),AQ15,0)+01_指標庫!$H$9*IF(ISNUMBER($AG15),AR15,0)+01_指標庫!$H$10*IF(ISNUMBER($AB15),AM15,0)+01_指標庫!$H$11*IF(ISNUMBER($AC15),AN15,0)+01_指標庫!$H$12*IF(ISNUMBER($AD15),AO15,0)+01_指標庫!$H$13*IF(ISNUMBER($AE15),AP15,0)+01_指標庫!$H$14*IF(ISNUMBER($I15),O15,0)+01_指標庫!$H$15*IF(ISNUMBER($AH15),AS15,0)+01_指標庫!$H$16*IF(ISNUMBER($K15),P15,0)+01_指標庫!$H$17*IF(ISNUMBER($AI15),AT15,0)+01_指標庫!$H$18*IF(ISNUMBER($AJ15),AU15,0)+01_指標庫!$H$19*IF(ISNUMBER($AK15),AV15,0)+01_指標庫!$H$20*IF(ISNUMBER($BB15),BB15,0)+01_指標庫!$H$21*IF(ISNUMBER($BC15),BC15,0))/AW15,1)) -> 72.4 | BA15: =AVERAGE($E11:$E15)/AVERAGE($E6:$E15)-1 -> 0.0067025973 | BB15: =IF(ISNUMBER($BA15),IF(OR($S15<=-0.03,$BA15<-0.003),0,IF(OR($S15<=-0.02,$BA15<0.01),50,100)),"") -> 50 | BC15: =IF(OR(COUNT($AZ15)=0,COUNT($AZ14)=0),"",IF(OR($AY15/$AZ14-1<=-0.03,$AZ15/$AZ14-1<=-0.045,IF(COUNT($AZ6:$AZ15)=10,AVERAGE($AZ11:$AZ15)/AVERAGE($AZ6:$AZ15)-1<-0.01,FALSE())),0,IF(OR($AZ15/$AZ14-1<=-0.02,IF(COUNT($AZ6:$AZ15)=10,AVERAGE($AZ11:$AZ15)/AVERAGE($AZ6:$AZ15)-1<0.005,FALSE())),50,100)))
A16: 12 | B16: 42576 | C16: 2016 | D16: 一 | E16: 4665.93 | F16: 0.051149 | G16: -0.011256 | H16: 0.8571 | I16: 539 | J16: real | K16: 12.87 | L16: =IF(COUNT(F16)=0,50,IF(F16>=0,100,IF(F16>=-0.02,50,0))) -> 100 | M16: =IF(COUNT(G16)=0,50,IF(G16>-0.06,100,IF(G16>-0.15,50,0))) -> 100 | N16: =IF(COUNT(H16)=0,50,IF(H16>=0.6,100,IF(H16>=0.4,50,0))) -> 100 | O16: =IF(COUNT(I16)=0,50,IF(J16="proxy_vix",50,IF(I16<350,100,IF(I16<=450,50,0)))) -> 0 | P16: =IF(COUNT(K16)=0,50,IF(K16<20,100,IF(K16<=25,50,0))) -> 100 | S16: =$E16/$E15-1 -> -3.0003836e-05 | T16: =$K16/$K15-1 -> 0.070715474 | Y16: =IF(AX16>=70,"EASY",IF(AX16>40,"UNCERTAIN","HARD")) -> EASY | AA16: =IF($A16<200,"",AVERAGE($E5:$E16)/AVERAGE($E5:$E16)-1) | AB16: =LOOKUP($B16,07_L1政策步階!$A$4:$A$14,07_L1政策步階!$C$4:$C$14) -> 0 | AL16: =IF(ISNUMBER($AA16),IF($AA16>=0.005,100,IF($AA16>=-0.015,50,0)),"") | AM16: =IF(ISNUMBER($AB16),IF($AB16=1,100,IF($AB16=0,50,0)),"") -> 50 | AN16: =IF(ISNUMBER($AC16),IF($AC16>=0.001,100,IF($AC16>=-0.003,50,0)),"") | AO16: =IF(ISNUMBER($AD16),IF($AD16>=0.04,100,IF($AD16>=0,50,0)),"") | AP16: =IF(ISNUMBER($AE16),IF($AE16>=25,100,IF($AE16>=-75,50,0)),"") | AQ16: =IF(ISNUMBER($AF16),IF($AF16>0,100,IF($AF16>=-50,50,0)),"") | AR16: =IF(ISNUMBER($AG16),IF($AG16=1,100,IF($AG16=0,50,0)),"") | AS16: =IF(ISNUMBER($AH16),IF($AH16<0,100,IF($AH16<=20,50,0)),"") | AT16: =IF(ISNUMBER($AI16),IF($AI16<0.95,100,IF($AI16<=1,50,0)),"") | AU16: =IF(ISNUMBER($AJ16),IF($AJ16<30,0,IF($AJ16<40,50,IF($AJ16<=90,100,50))),"") | AV16: =IF(ISNUMBER($AK16),IF($AK16>-0.2,100,IF($AK16>=-0.4,50,0)),"") | AW16: =01_指標庫!$H$4*ISNUMBER($F16)+01_指標庫!$H$5*ISNUMBER($AA16)+01_指標庫!$H$6*ISNUMBER($G16)+01_指標庫!$H$7*ISNUMBER($H16)+01_指標庫!$H$8*ISNUMBER($AF16)+01_指標庫!$H$9*ISNUMBER($AG16)+01_指標庫!$H$10*ISNUMBER($AB16)+01_指標庫!$H$11*ISNUMBER($AC16)+01_指標庫!$H$12*ISNUMBER($AD16)+01_指標庫!$H$13*ISNUMBER($AE16)+01_指標庫!$H$14*ISNUMBER($I16)+01_指標庫!$H$15*ISNUMBER($AH16)+01_指標庫!$H$16*ISNUMBER($K16)+01_指標庫!$H$17*ISNUMBER($AI16)+01_指標庫!$H$18*ISNUMBER($AJ16)+01_指標庫!$H$19*ISNUMBER($AK16)+01_指標庫!$H$20*ISNUMBER($BB16)+01_指標庫!$H$21*ISNUMBER($BC16) -> 49 | AX16: =IF(AW16=0,50,ROUND((01_指標庫!$H$4*IF(ISNUMBER($F16),L16,0)+01_指標庫!$H$5*IF(ISNUMBER($AA16),AL16,0)+01_指標庫!$H$6*IF(ISNUMBER($G16),M16,0)+01_指標庫!$H$7*IF(ISNUMBER($H16),N16,0)+01_指標庫!$H$8*IF(ISNUMBER($AF16),AQ16,0)+01_指標庫!$H$9*IF(ISNUMBER($AG16),AR16,0)+01_指標庫!$H$10*IF(ISNUMBER($AB16),AM16,0)+01_指標庫!$H$11*IF(ISNUMBER($AC16),AN16,0)+01_指標庫!$H$12*IF(ISNUMBER($AD16),AO16,0)+01_指標庫!$H$13*IF(ISNUMBER($AE16),AP16,0)+01_指標庫!$H$14*IF(ISNUMBER($I16),O16,0)+01_指標庫!$H$15*IF(ISNUMBER($AH16),AS16,0)+01_指標庫!$H$16*IF(ISNUMBER($K16),P16,0)+01_指標庫!$H$17*IF(ISNUMBER($AI16),AT16,0)+01_指標庫!$H$18*IF(ISNUMBER($AJ16),AU16,0)+01_指標庫!$H$19*IF(ISNUMBER($AK16),AV16,0)+01_指標庫!$H$20*IF(ISNUMBER($BB16),BB16,0)+01_指標庫!$H$21*IF(ISNUMBER($BC16),BC16,0))/AW16,1)) -> 72.4 | BA16: =AVERAGE($E12:$E16)/AVERAGE($E7:$E16)-1 -> 0.0062811655 | BB16: =IF(ISNUMBER($BA16),IF(OR($S16<=-0.03,$BA16<-0.003),0,IF(OR($S16<=-0.02,$BA16<0.01),50,100)),"") -> 50 | BC16: =IF(OR(COUNT($AZ16)=0,COUNT($AZ15)=0),"",IF(OR($AY16/$AZ15-1<=-0.03,$AZ16/$AZ15-1<=-0.045,IF(COUNT($AZ7:$AZ16)=10,AVERAGE($AZ12:$AZ16)/AVERAGE($AZ7:$AZ16)-1<-0.01,FALSE())),0,IF(OR($AZ16/$AZ15-1<=-0.02,IF(COUNT($AZ7:$AZ16)=10,AVERAGE($AZ12:$AZ16)/AVERAGE($AZ7:$AZ16)-1<0.005,FALSE())),50,100)))
A17: 13 | B17: 42577 | C17: 2016 | D17: 二 | E17: 4672.11 | F17: 0.05216 | G17: -0.009947 | H17: 0.8776 | I17: 545 | J17: real | K17: 13.05 | L17: =IF(COUNT(F17)=0,50,IF(F17>=0,100,IF(F17>=-0.02,50,0))) -> 100 | M17: =IF(COUNT(G17)=0,50,IF(G17>-0.06,100,IF(G17>-0.15,50,0))) -> 100 | N17: =IF(COUNT(H17)=0,50,IF(H17>=0.6,100,IF(H17>=0.4,50,0))) -> 100 | O17: =IF(COUNT(I17)=0,50,IF(J17="proxy_vix",50,IF(I17<350,100,IF(I17<=450,50,0)))) -> 0 | P17: =IF(COUNT(K17)=0,50,IF(K17<20,100,IF(K17<=25,50,0))) -> 100 | S17: =$E17/$E16-1 -> 0.0013244948 | T17: =$K17/$K16-1 -> 0.013986014 | Y17: =IF(AX17>=70,"EASY",IF(AX17>40,"UNCERTAIN","HARD")) -> EASY | AA17: =IF($A17<200,"",AVERAGE($E5:$E17)/AVERAGE($E5:$E17)-1) | AB17: =LOOKUP($B17,07_L1政策步階!$A$4:$A$14,07_L1政策步階!$C$4:$C$14) -> 0 | AL17: =IF(ISNUMBER($AA17),IF($AA17>=0.005,100,IF($AA17>=-0.015,50,0)),"") | AM17: =IF(ISNUMBER($AB17),IF($AB17=1,100,IF($AB17=0,50,0)),"") -> 50 | AN17: =IF(ISNUMBER($AC17),IF($AC17>=0.001,100,IF($AC17>=-0.003,50,0)),"") | AO17: =IF(ISNUMBER($AD17),IF($AD17>=0.04,100,IF($AD17>=0,50,0)),"") | AP17: =IF(ISNUMBER($AE17),IF($AE17>=25,100,IF($AE17>=-75,50,0)),"") | AQ17: =IF(ISNUMBER($AF17),IF($AF17>0,100,IF($AF17>=-50,50,0)),"") | AR17: =IF(ISNUMBER($AG17),IF($AG17=1,100,IF($AG17=0,50,0)),"") | AS17: =IF(ISNUMBER($AH17),IF($AH17<0,100,IF($AH17<=20,50,0)),"") | AT17: =IF(ISNUMBER($AI17),IF($AI17<0.95,100,IF($AI17<=1,50,0)),"") | AU17: =IF(ISNUMBER($AJ17),IF($AJ17<30,0,IF($AJ17<40,50,IF($AJ17<=90,100,50))),"") | AV17: =IF(ISNUMBER($AK17),IF($AK17>-0.2,100,IF($AK17>=-0.4,50,0)),"") | AW17: =01_指標庫!$H$4*ISNUMBER($F17)+01_指標庫!$H$5*ISNUMBER($AA17)+01_指標庫!$H$6*ISNUMBER($G17)+01_指標庫!$H$7*ISNUMBER($H17)+01_指標庫!$H$8*ISNUMBER($AF17)+01_指標庫!$H$9*ISNUMBER($AG17)+01_指標庫!$H$10*ISNUMBER($AB17)+01_指標庫!$H$11*ISNUMBER($AC17)+01_指標庫!$H$12*ISNUMBER($AD17)+01_指標庫!$H$13*ISNUMBER($AE17)+01_指標庫!$H$14*ISNUMBER($I17)+01_指標庫!$H$15*ISNUMBER($AH17)+01_指標庫!$H$16*ISNUMBER($K17)+01_指標庫!$H$17*ISNUMBER($AI17)+01_指標庫!$H$18*ISNUMBER($AJ17)+01_指標庫!$H$19*ISNUMBER($AK17)+01_指標庫!$H$20*ISNUMBER($BB17)+01_指標庫!$H$21*ISNUMBER($BC17) -> 49 | AX17: =IF(AW17=0,50,ROUND((01_指標庫!$H$4*IF(ISNUMBER($F17),L17,0)+01_指標庫!$H$5*IF(ISNUMBER($AA17),AL17,0)+01_指標庫!$H$6*IF(ISNUMBER($G17),M17,0)+01_指標庫!$H$7*IF(ISNUMBER($H17),N17,0)+01_指標庫!$H$8*IF(ISNUMBER($AF17),AQ17,0)+01_指標庫!$H$9*IF(ISNUMBER($AG17),AR17,0)+01_指標庫!$H$10*IF(ISNUMBER($AB17),AM17,0)+01_指標庫!$H$11*IF(ISNUMBER($AC17),AN17,0)+01_指標庫!$H$12*IF(ISNUMBER($AD17),AO17,0)+01_指標庫!$H$13*IF(ISNUMBER($AE17),AP17,0)+01_指標庫!$H$14*IF(ISNUMBER($I17),O17,0)+01_指標庫!$H$15*IF(ISNUMBER($AH17),AS17,0)+01_指標庫!$H$16*IF(ISNUMBER($K17),P17,0)+01_指標庫!$H$17*IF(ISNUMBER($AI17),AT17,0)+01_指標庫!$H$18*IF(ISNUMBER($AJ17),AU17,0)+01_指標庫!$H$19*IF(ISNUMBER($AK17),AV17,0)+01_指標庫!$H$20*IF(ISNUMBER($BB17),BB17,0)+01_指標庫!$H$21*IF(ISNUMBER($BC17),BC17,0))/AW17,1)) -> 72.4 | BA17: =AVERAGE($E13:$E17)/AVERAGE($E8:$E17)-1 -> 0.007200857 | BB17: =IF(ISNUMBER($BA17),IF(OR($S17<=-0.03,$BA17<-0.003),0,IF(OR($S17<=-0.02,$BA17<0.01),50,100)),"") -> 50 | BC17: =IF(OR(COUNT($AZ17)=0,COUNT($AZ16)=0),"",IF(OR($AY17/$AZ16-1<=-0.03,$AZ17/$AZ16-1<=-0.045,IF(COUNT($AZ8:$AZ17)=10,AVERAGE($AZ13:$AZ17)/AVERAGE($AZ8:$AZ17)-1<-0.01,FALSE())),0,IF(OR($AZ17/$AZ16-1<=-0.02,IF(COUNT($AZ8:$AZ17)=10,AVERAGE($AZ13:$AZ17)/AVERAGE($AZ8:$AZ17)-1<0.005,FALSE())),50,100)))
A18: 14 | B18: 42578 | C18: 2016 | D18: 三 | E18: 4702.88 | F18: 0.058692 | G18: -0.003427 | H18: 0.8571 | I18: 551 | J18: real | K18: 12.83 | L18: =IF(COUNT(F18)=0,50,IF(F18>=0,100,IF(F18>=-0.02,50,0))) -> 100 | M18: =IF(COUNT(G18)=0,50,IF(G18>-0.06,100,IF(G18>-0.15,50,0))) -> 100 | N18: =IF(COUNT(H18)=0,50,IF(H18>=0.6,100,IF(H18>=0.4,50,0))) -> 100 | O18: =IF(COUNT(I18)=0,50,IF(J18="proxy_vix",50,IF(I18<350,100,IF(I18<=450,50,0)))) -> 0 | P18: =IF(COUNT(K18)=0,50,IF(K18<20,100,IF(K18<=25,50,0))) -> 100 | S18: =$E18/$E17-1 -> 0.0065858895 | T18: =$K18/$K17-1 -> -0.016858238 | Y18: =IF(AX18>=70,"EASY",IF(AX18>40,"UNCERTAIN","HARD")) -> EASY | AA18: =IF($A18<200,"",AVERAGE($E5:$E18)/AVERAGE($E5:$E18)-1) | AB18: =LOOKUP($B18,07_L1政策步階!$A$4:$A$14,07_L1政策步階!$C$4:$C$14) -> 0 | AL18: =IF(ISNUMBER($AA18),IF($AA18>=0.005,100,IF($AA18>=-0.015,50,0)),"") | AM18: =IF(ISNUMBER($AB18),IF($AB18=1,100,IF($AB18=0,50,0)),"") -> 50 | AN18: =IF(ISNUMBER($AC18),IF($AC18>=0.001,100,IF($AC18>=-0.003,50,0)),"") | AO18: =IF(ISNUMBER($AD18),IF($AD18>=0.04,100,IF($AD18>=0,50,0)),"") | AP18: =IF(ISNUMBER($AE18),IF($AE18>=25,100,IF($AE18>=-75,50,0)),"") | AQ18: =IF(ISNUMBER($AF18),IF($AF18>0,100,IF($AF18>=-50,50,0)),"") | AR18: =IF(ISNUMBER($AG18),IF($AG18=1,100,IF($AG18=0,50,0)),"") | AS18: =IF(ISNUMBER($AH18),IF($AH18<0,100,IF($AH18<=20,50,0)),"") | AT18: =IF(ISNUMBER($AI18),IF($AI18<0.95,100,IF($AI18<=1,50,0)),"") | AU18: =IF(ISNUMBER($AJ18),IF($AJ18<30,0,IF($AJ18<40,50,IF($AJ18<=90,100,50))),"") | AV18: =IF(ISNUMBER($AK18),IF($AK18>-0.2,100,IF($AK18>=-0.4,50,0)),"") | AW18: =01_指標庫!$H$4*ISNUMBER($F18)+01_指標庫!$H$5*ISNUMBER($AA18)+01_指標庫!$H$6*ISNUMBER($G18)+01_指標庫!$H$7*ISNUMBER($H18)+01_指標庫!$H$8*ISNUMBER($AF18)+01_指標庫!$H$9*ISNUMBER($AG18)+01_指標庫!$H$10*ISNUMBER($AB18)+01_指標庫!$H$11*ISNUMBER($AC18)+01_指標庫!$H$12*ISNUMBER($AD18)+01_指標庫!$H$13*ISNUMBER($AE18)+01_指標庫!$H$14*ISNUMBER($I18)+01_指標庫!$H$15*ISNUMBER($AH18)+01_指標庫!$H$16*ISNUMBER($K18)+01_指標庫!$H$17*ISNUMBER($AI18)+01_指標庫!$H$18*ISNUMBER($AJ18)+01_指標庫!$H$19*ISNUMBER($AK18)+01_指標庫!$H$20*ISNUMBER($BB18)+01_指標庫!$H$21*ISNUMBER($BC18) -> 49 | AX18: =IF(AW18=0,50,ROUND((01_指標庫!$H$4*IF(ISNUMBER($F18),L18,0)+01_指標庫!$H$5*IF(ISNUMBER($AA18),AL18,0)+01_指標庫!$H$6*IF(ISNUMBER($G18),M18,0)+01_指標庫!$H$7*IF(ISNUMBER($H18),N18,0)+01_指標庫!$H$8*IF(ISNUMBER($AF18),AQ18,0)+01_指標庫!$H$9*IF(ISNUMBER($AG18),AR18,0)+01_指標庫!$H$10*IF(ISNUMBER($AB18),AM18,0)+01_指標庫!$H$11*IF(ISNUMBER($AC18),AN18,0)+01_指標庫!$H$12*IF(ISNUMBER($AD18),AO18,0)+01_指標庫!$H$13*IF(ISNUMBER($AE18),AP18,0)+01_指標庫!$H$14*IF(ISNUMBER($I18),O18,0)+01_指標庫!$H$15*IF(ISNUMBER($AH18),AS18,0)+01_指標庫!$H$16*IF(ISNUMBER($K18),P18,0)+01_指標庫!$H$17*IF(ISNUMBER($AI18),AT18,0)+01_指標庫!$H$18*IF(ISNUMBER($AJ18),AU18,0)+01_指標庫!$H$19*IF(ISNUMBER($AK18),AV18,0)+01_指標庫!$H$20*IF(ISNUMBER($BB18),BB18,0)+01_指標庫!$H$21*IF(ISNUMBER($BC18),BC18,0))/AW18,1)) -> 72.4 | BA18: =AVERAGE($E14:$E18)/AVERAGE($E9:$E18)-1 -> 0.006194032 | BB18: =IF(ISNUMBER($BA18),IF(OR($S18<=-0.03,$BA18<-0.003),0,IF(OR($S18<=-0.02,$BA18<0.01),50,100)),"") -> 50 | BC18: =IF(OR(COUNT($AZ18)=0,COUNT($AZ17)=0),"",IF(OR($AY18/$AZ17-1<=-0.03,$AZ18/$AZ17-1<=-0.045,IF(COUNT($AZ9:$AZ18)=10,AVERAGE($AZ14:$AZ18)/AVERAGE($AZ9:$AZ18)-1<-0.01,FALSE())),0,IF(OR($AZ18/$AZ17-1<=-0.02,IF(COUNT($AZ9:$AZ18)=10,AVERAGE($AZ14:$AZ18)/AVERAGE($AZ9:$AZ18)-1<0.005,FALSE())),50,100)))
A19: 15 | B19: 42579 | C19: 2016 | D19: 四 | E19: 4721.41 | F19: 0.062459 | G19: 0 | H19: 0.8776 | I19: 554 | J19: real | K19: 12.72 | L19: =IF(COUNT(F19)=0,50,IF(F19>=0,100,IF(F19>=-0.02,50,0))) -> 100 | M19: =IF(COUNT(G19)=0,50,IF(G19>-0.06,100,IF(G19>-0.15,50,0))) -> 100 | N19: =IF(COUNT(H19)=0,50,IF(H19>=0.6,100,IF(H19>=0.4,50,0))) -> 100 | O19: =IF(COUNT(I19)=0,50,IF(J19="proxy_vix",50,IF(I19<350,100,IF(I19<=450,50,0)))) -> 0 | P19: =IF(COUNT(K19)=0,50,IF(K19<20,100,IF(K19<=25,50,0))) -> 100 | S19: =$E19/$E18-1 -> 0.0039401388 | T19: =$K19/$K18-1 -> -0.0085736555 | Y19: =IF(AX19>=70,"EASY",IF(AX19>40,"UNCERTAIN","HARD")) -> EASY | AA19: =IF($A19<200,"",AVERAGE($E5:$E19)/AVERAGE($E5:$E19)-1) | AB19: =LOOKUP($B19,07_L1政策步階!$A$4:$A$14,07_L1政策步階!$C$4:$C$14) -> 0 | AL19: =IF(ISNUMBER($AA19),IF($AA19>=0.005,100,IF($AA19>=-0.015,50,0)),"") | AM19: =IF(ISNUMBER($AB19),IF($AB19=1,100,IF($AB19=0,50,0)),"") -> 50 | AN19: =IF(ISNUMBER($AC19),IF($AC19>=0.001,100,IF($AC19>=-0.003,50,0)),"") | AO19: =IF(ISNUMBER($AD19),IF($AD19>=0.04,100,IF($AD19>=0,50,0)),"") | AP19: =IF(ISNUMBER($AE19),IF($AE19>=25,100,IF($AE19>=-75,50,0)),"") | AQ19: =IF(ISNUMBER($AF19),IF($AF19>0,100,IF($AF19>=-50,50,0)),"") | AR19: =IF(ISNUMBER($AG19),IF($AG19=1,100,IF($AG19=0,50,0)),"") | AS19: =IF(ISNUMBER($AH19),IF($AH19<0,100,IF($AH19<=20,50,0)),"") | AT19: =IF(ISNUMBER($AI19),IF($AI19<0.95,100,IF($AI19<=1,50,0)),"") | AU19: =IF(ISNUMBER($AJ19),IF($AJ19<30,0,IF($AJ19<40,50,IF($AJ19<=90,100,50))),"") | AV19: =IF(ISNUMBER($AK19),IF($AK19>-0.2,100,IF($AK19>=-0.4,50,0)),"") | AW19: =01_指標庫!$H$4*ISNUMBER($F19)+01_指標庫!$H$5*ISNUMBER($AA19)+01_指標庫!$H$6*ISNUMBER($G19)+01_指標庫!$H$7*ISNUMBER($H19)+01_指標庫!$H$8*ISNUMBER($AF19)+01_指標庫!$H$9*ISNUMBER($AG19)+01_指標庫!$H$10*ISNUMBER($AB19)+01_指標庫!$H$11*ISNUMBER($AC19)+01_指標庫!$H$12*ISNUMBER($AD19)+01_指標庫!$H$13*ISNUMBER($AE19)+01_指標庫!$H$14*ISNUMBER($I19)+01_指標庫!$H$15*ISNUMBER($AH19)+01_指標庫!$H$16*ISNUMBER($K19)+01_指標庫!$H$17*ISNUMBER($AI19)+01_指標庫!$H$18*ISNUMBER($AJ19)+01_指標庫!$H$19*ISNUMBER($AK19)+01_指標庫!$H$20*ISNUMBER($BB19)+01_指標庫!$H$21*ISNUMBER($BC19) -> 49 | AX19: =IF(AW19=0,50,ROUND((01_指標庫!$H$4*IF(ISNUMBER($F19),L19,0)+01_指標庫!$H$5*IF(ISNUMBER($AA19),AL19,0)+01_指標庫!$H$6*IF(ISNUMBER($G19),M19,0)+01_指標庫!$H$7*IF(ISNUMBER($H19),N19,0)+01_指標庫!$H$8*IF(ISNUMBER($AF19),AQ19,0)+01_指標庫!$H$9*IF(ISNUMBER($AG19),AR19,0)+01_指標庫!$H$10*IF(ISNUMBER($AB19),AM19,0)+01_指標庫!$H$11*IF(ISNUMBER($AC19),AN19,0)+01_指標庫!$H$12*IF(ISNUMBER($AD19),AO19,0)+01_指標庫!$H$13*IF(ISNUMBER($AE19),AP19,0)+01_指標庫!$H$14*IF(ISNUMBER($I19),O19,0)+01_指標庫!$H$15*IF(ISNUMBER($AH19),AS19,0)+01_指標庫!$H$16*IF(ISNUMBER($K19),P19,0)+01_指標庫!$H$17*IF(ISNUMBER($AI19),AT19,0)+01_指標庫!$H$18*IF(ISNUMBER($AJ19),AU19,0)+01_指標庫!$H$19*IF(ISNUMBER($AK19),AV19,0)+01_指標庫!$H$20*IF(ISNUMBER($BB19),BB19,0)+01_指標庫!$H$21*IF(ISNUMBER($BC19),BC19,0))/AW19,1)) -> 72.4 | BA19: =AVERAGE($E15:$E19)/AVERAGE($E10:$E19)-1 -> 0.0066900259 | BB19: =IF(ISNUMBER($BA19),IF(OR($S19<=-0.03,$BA19<-0.003),0,IF(OR($S19<=-0.02,$BA19<0.01),50,100)),"") -> 50 | BC19: =IF(OR(COUNT($AZ19)=0,COUNT($AZ18)=0),"",IF(OR($AY19/$AZ18-1<=-0.03,$AZ19/$AZ18-1<=-0.045,IF(COUNT($AZ10:$AZ19)=10,AVERAGE($AZ15:$AZ19)/AVERAGE($AZ10:$AZ19)-1<-0.01,FALSE())),0,IF(OR($AZ19/$AZ18-1<=-0.02,IF(COUNT($AZ10:$AZ19)=10,AVERAGE($AZ15:$AZ19)/AVERAGE($AZ10:$AZ19)-1<0.005,FALSE())),50,100)))
A20: 16 | B20: 42580 | C20: 2016 | D20: 五 | E20: 4730.23 | F20: 0.063992 | G20: 0 | H20: 0.8776 | I20: 561 | J20: real | K20: 11.87 | L20: =IF(COUNT(F20)=0,50,IF(F20>=0,100,IF(F20>=-0.02,50,0))) -> 100 | M20: =IF(COUNT(G20)=0,50,IF(G20>-0.06,100,IF(G20>-0.15,50,0))) -> 100 | N20: =IF(COUNT(H20)=0,50,IF(H20>=0.6,100,IF(H20>=0.4,50,0))) -> 100 | O20: =IF(COUNT(I20)=0,50,IF(J20="proxy_vix",50,IF(I20<350,100,IF(I20<=450,50,0)))) -> 0 | P20: =IF(COUNT(K20)=0,50,IF(K20<20,100,IF(K20<=25,50,0))) -> 100 | S20: =$E20/$E19-1 -> 0.001868086 | T20: =$K20/$K19-1 -> -0.066823899 | Y20: =IF(AX20>=70,"EASY",IF(AX20>40,"UNCERTAIN","HARD")) -> EASY | AA20: =IF($A20<200,"",AVERAGE($E5:$E20)/AVERAGE($E5:$E20)-1) | AB20: =LOOKUP($B20,07_L1政策步階!$A$4:$A$14,07_L1政策步階!$C$4:$C$14) -> 0 | AL20: =IF(ISNUMBER($AA20),IF($AA20>=0.005,100,IF($AA20>=-0.015,50,0)),"") | AM20: =IF(ISNUMBER($AB20),IF($AB20=1,100,IF($AB20=0,50,0)),"") -> 50 | AN20: =IF(ISNUMBER($AC20),IF($AC20>=0.001,100,IF($AC20>=-0.003,50,0)),"") | AO20: =IF(ISNUMBER($AD20),IF($AD20>=0.04,100,IF($AD20>=0,50,0)),"") | AP20: =IF(ISNUMBER($AE20),IF($AE20>=25,100,IF($AE20>=-75,50,0)),"") | AQ20: =IF(ISNUMBER($AF20),IF($AF20>0,100,IF($AF20>=-50,50,0)),"") | AR20: =IF(ISNUMBER($AG20),IF($AG20=1,100,IF($AG20=0,50,0)),"") | AS20: =IF(ISNUMBER($AH20),IF($AH20<0,100,IF($AH20<=20,50,0)),"") | AT20: =IF(ISNUMBER($AI20),IF($AI20<0.95,100,IF($AI20<=1,50,0)),"") | AU20: =IF(ISNUMBER($AJ20),IF($AJ20<30,0,IF($AJ20<40,50,IF($AJ20<=90,100,50))),"") | AV20: =IF(ISNUMBER($AK20),IF($AK20>-0.2,100,IF($AK20>=-0.4,50,0)),"") | AW20: =01_指標庫!$H$4*ISNUMBER($F20)+01_指標庫!$H$5*ISNUMBER($AA20)+01_指標庫!$H$6*ISNUMBER($G20)+01_指標庫!$H$7*ISNUMBER($H20)+01_指標庫!$H$8*ISNUMBER($AF20)+01_指標庫!$H$9*ISNUMBER($AG20)+01_指標庫!$H$10*ISNUMBER($AB20)+01_指標庫!$H$11*ISNUMBER($AC20)+01_指標庫!$H$12*ISNUMBER($AD20)+01_指標庫!$H$13*ISNUMBER($AE20)+01_指標庫!$H$14*ISNUMBER($I20)+01_指標庫!$H$15*ISNUMBER($AH20)+01_指標庫!$H$16*ISNUMBER($K20)+01_指標庫!$H$17*ISNUMBER($AI20)+01_指標庫!$H$18*ISNUMBER($AJ20)+01_指標庫!$H$19*ISNUMBER($AK20)+01_指標庫!$H$20*ISNUMBER($BB20)+01_指標庫!$H$21*ISNUMBER($BC20) -> 49 | AX20: =IF(AW20=0,50,ROUND((01_指標庫!$H$4*IF(ISNUMBER($F20),L20,0)+01_指標庫!$H$5*IF(ISNUMBER($AA20),AL20,0)+01_指標庫!$H$6*IF(ISNUMBER($G20),M20,0)+01_指標庫!$H$7*IF(ISNUMBER($H20),N20,0)+01_指標庫!$H$8*IF(ISNUMBER($AF20),AQ20,0)+01_指標庫!$H$9*IF(ISNUMBER($AG20),AR20,0)+01_指標庫!$H$10*IF(ISNUMBER($AB20),AM20,0)+01_指標庫!$H$11*IF(ISNUMBER($AC20),AN20,0)+01_指標庫!$H$12*IF(ISNUMBER($AD20),AO20,0)+01_指標庫!$H$13*IF(ISNUMBER($AE20),AP20,0)+01_指標庫!$H$14*IF(ISNUMBER($I20),O20,0)+01_指標庫!$H$15*IF(ISNUMBER($AH20),AS20,0)+01_指標庫!$H$16*IF(ISNUMBER($K20),P20,0)+01_指標庫!$H$17*IF(ISNUMBER($AI20),AT20,0)+01_指標庫!$H$18*IF(ISNUMBER($AJ20),AU20,0)+01_指標庫!$H$19*IF(ISNUMBER($AK20),AV20,0)+01_指標庫!$H$20*IF(ISNUMBER($BB20),BB20,0)+01_指標庫!$H$21*IF(ISNUMBER($BC20),BC20,0))/AW20,1)) -> 72.4 | BA20: =AVERAGE($E16:$E20)/AVERAGE($E11:$E20)-1 -> 0.0064111558 | BB20: =IF(ISNUMBER($BA20),IF(OR($S20<=-0.03,$BA20<-0.003),0,IF(OR($S20<=-0.02,$BA20<0.01),50,100)),"") -> 50 | BC20: =IF(OR(COUNT($AZ20)=0,COUNT($AZ19)=0),"",IF(OR($AY20/$AZ19-1<=-0.03,$AZ20/$AZ19-1<=-0.045,IF(COUNT($AZ11:$AZ20)=10,AVERAGE($AZ16:$AZ20)/AVERAGE($AZ11:$AZ20)-1<-0.01,FALSE())),0,IF(OR($AZ20/$AZ19-1<=-0.02,IF(COUNT($AZ11:$AZ20)=10,AVERAGE($AZ16:$AZ20)/AVERAGE($AZ11:$AZ20)-1<0.005,FALSE())),50,100)))
A21: 17 | B21: 42583 | C21: 2016 | D21: 一 | E21: 4756.04 | F21: 0.069305 | G21: 0 | H21: 0.898 | I21: 569 | J21: real | K21: 12.44 | L21: =IF(COUNT(F21)=0,50,IF(F21>=0,100,IF(F21>=-0.02,50,0))) -> 100 | M21: =IF(COUNT(G21)=0,50,IF(G21>-0.06,100,IF(G21>-0.15,50,0))) -> 100 | N21: =IF(COUNT(H21)=0,50,IF(H21>=0.6,100,IF(H21>=0.4,50,0))) -> 100 | O21: =IF(COUNT(I21)=0,50,IF(J21="proxy_vix",50,IF(I21<350,100,IF(I21<=450,50,0)))) -> 0 | P21: =IF(COUNT(K21)=0,50,IF(K21<20,100,IF(K21<=25,50,0))) -> 100 | S21: =$E21/$E20-1 -> 0.0054563943 | T21: =$K21/$K20-1 -> 0.048020219 | Y21: =IF(AX21>=70,"EASY",IF(AX21>40,"UNCERTAIN","HARD")) -> EASY | AA21: =IF($A21<200,"",AVERAGE($E5:$E21)/AVERAGE($E5:$E21)-1) | AB21: =LOOKUP($B21,07_L1政策步階!$A$4:$A$14,07_L1政策步階!$C$4:$C$14) -> 0 | AL21: =IF(ISNUMBER($AA21),IF($AA21>=0.005,100,IF($AA21>=-0.015,50,0)),"") | AM21: =IF(ISNUMBER($AB21),IF($AB21=1,100,IF($AB21=0,50,0)),"") -> 50 | AN21: =IF(ISNUMBER($AC21),IF($AC21>=0.001,100,IF($AC21>=-0.003,50,0)),"") | AO21: =IF(ISNUMBER($AD21),IF($AD21>=0.04,100,IF($AD21>=0,50,0)),"") | AP21: =IF(ISNUMBER($AE21),IF($AE21>=25,100,IF($AE21>=-75,50,0)),"") | AQ21: =IF(ISNUMBER($AF21),IF($AF21>0,100,IF($AF21>=-50,50,0)),"") | AR21: =IF(ISNUMBER($AG21),IF($AG21=1,100,IF($AG21=0,50,0)),"") | AS21: =IF(ISNUMBER($AH21),IF($AH21<0,100,IF($AH21<=20,50,0)),"") | AT21: =IF(ISNUMBER($AI21),IF($AI21<0.95,100,IF($AI21<=1,50,0)),"") | AU21: =IF(ISNUMBER($AJ21),IF($AJ21<30,0,IF($AJ21<40,50,IF($AJ21<=90,100,50))),"") | AV21: =IF(ISNUMBER($AK21),IF($AK21>-0.2,100,IF($AK21>=-0.4,50,0)),"") | AW21: =01_指標庫!$H$4*ISNUMBER($F21)+01_指標庫!$H$5*ISNUMBER($AA21)+01_指標庫!$H$6*ISNUMBER($G21)+01_指標庫!$H$7*ISNUMBER($H21)+01_指標庫!$H$8*ISNUMBER($AF21)+01_指標庫!$H$9*ISNUMBER($AG21)+01_指標庫!$H$10*ISNUMBER($AB21)+01_指標庫!$H$11*ISNUMBER($AC21)+01_指標庫!$H$12*ISNUMBER($AD21)+01_指標庫!$H$13*ISNUMBER($AE21)+01_指標庫!$H$14*ISNUMBER($I21)+01_指標庫!$H$15*ISNUMBER($AH21)+01_指標庫!$H$16*ISNUMBER($K21)+01_指標庫!$H$17*ISNUMBER($AI21)+01_指標庫!$H$18*ISNUMBER($AJ21)+01_指標庫!$H$19*ISNUMBER($AK21)+01_指標庫!$H$20*ISNUMBER($BB21)+01_指標庫!$H$21*ISNUMBER($BC21) -> 49 | AX21: =IF(AW21=0,50,ROUND((01_指標庫!$H$4*IF(ISNUMBER($F21),L21,0)+01_指標庫!$H$5*IF(ISNUMBER($AA21),AL21,0)+01_指標庫!$H$6*IF(ISNUMBER($G21),M21,0)+01_指標庫!$H$7*IF(ISNUMBER($H21),N21,0)+01_指標庫!$H$8*IF(ISNUMBER($AF21),AQ21,0)+01_指標庫!$H$9*IF(ISNUMBER($AG21),AR21,0)+01_指標庫!$H$10*IF(ISNUMBER($AB21),AM21,0)+01_指標庫!$H$11*IF(ISNUMBER($AC21),AN21,0)+01_指標庫!$H$12*IF(ISNUMBER($AD21),AO21,0)+01_指標庫!$H$13*IF(ISNUMBER($AE21),AP21,0)+01_指標庫!$H$14*IF(ISNUMBER($I21),O21,0)+01_指標庫!$H$15*IF(ISNUMBER($AH21),AS21,0)+01_指標庫!$H$16*IF(ISNUMBER($K21),P21,0)+01_指標庫!$H$17*IF(ISNUMBER($AI21),AT21,0)+01_指標庫!$H$18*IF(ISNUMBER($AJ21),AU21,0)+01_指標庫!$H$19*IF(ISNUMBER($AK21),AV21,0)+01_指標庫!$H$20*IF(ISNUMBER($BB21),BB21,0)+01_指標庫!$H$21*IF(ISNUMBER($BC21),BC21,0))/AW21,1)) -> 72.4 | BA21: =AVERAGE($E17:$E21)/AVERAGE($E12:$E21)-1 -> 0.0073292203 | BB21: =IF(ISNUMBER($BA21),IF(OR($S21<=-0.03,$BA21<-0.003),0,IF(OR($S21<=-0.02,$BA21<0.01),50,100)),"") -> 50 | BC21: =IF(OR(COUNT($AZ21)=0,COUNT($AZ20)=0),"",IF(OR($AY21/$AZ20-1<=-0.03,$AZ21/$AZ20-1<=-0.045,IF(COUNT($AZ12:$AZ21)=10,AVERAGE($AZ17:$AZ21)/AVERAGE($AZ12:$AZ21)-1<-0.01,FALSE())),0,IF(OR($AZ21/$AZ20-1<=-0.02,IF(COUNT($AZ12:$AZ21)=10,AVERAGE($AZ17:$AZ21)/AVERAGE($AZ12:$AZ21)-1<0.005,FALSE())),50,100)))
