Workbook

Sheet 00_方法論
A1: NASDAQ 100 趨勢轉折 × 領先指標 分析 (2026-07-26)
A2: 目標 | B2: 找出NDX趨勢轉折(見頂/見底)的領先指標: 客觀偵測45個主要轉折(1999-2026), 對五大指標族的量化規則逐一量測領先/滯後天數, 經對抗性驗證。
A3: 轉折定義 | B3: ZigZag演算法(無前視): 收盤自峰回落≥15%確認一個TOP, 自谷回升≥15%確認一個BOTTOM → 45個主要轉折(02表)。±8%版=163個中級轉折(輔助統計與假訊號判定)。
A4: 數據 | B4: ①NDX真實日線2016-07-08..2026-07-10(原工作簿02A); ②1999-01..2016-07用Nasdaq Composite日報酬鏈接(arch套件學術數據, 重疊期625日報酬相關0.989); ③VIX 2014起; ④HY OAS/廣度/合成分 2016-07起(原工作簿); ⑤成交量1999-2016(Composite); ⑥月度七支柱1976-2026(前次50年引擎)。
A5: 評估協定 | B5: lead=訊號日−轉折日(交易日, 負=領先)。配對窗[轉折-90交易日, 轉折+5交易日], 取窗內最早訊號。假訊號=訊號後90交易日內無同向主要/中級轉折。判定: LEADING(中位lead<-5) / COINCIDENT(-5..+5) / CONFIRMING(>+5)。
A6: 執行方式 | B6: 五個獨立分析agent(趨勢動能/波動率/信用廣度/量價/月度支柱)按同一協定計算 → 五個對抗性驗證agent獨立重算抽查(規則重現/lead重算/前視偏誤專查) → 通過後彙總。驗證結果見03表『驗證』欄。
A7: 工作表 | B7: 01_指標排行(統計=活公式) | 02_轉折點45個 | 03_指標明細(全部規則+驗證) | 04_逐轉折lead明細 | 05_訊號明細(全部訊號日) | 06_日線與趨勢線(活公式SMA)
A8: 核心結論 | B8: 頂部最強領先: 廣度頂背離(2016後6/6命中, 中位-69交易日, FP12%)、廣度先崩(-82d)、RSI14頂背離(14/22, -73d)、HV20低位翻升(13/22, -80d)、VIX與價同升背離(6/7, -44d)。底部最強領先: RSI14底背離(18/22, FP=0, -32d)、OBV底背離(12/16, FP=0, -34d)、HY OAS峰值回落(5/6, -43d)、廣度washout回升(4/6, -44d); VIX尖峰翻落(-2d)為同步精確擇時器。月度制度層: 合成分跌穿70領先月度頂中位8個月(8/9)。對照: 均線/交叉/回撤類全部是滯後確認器(真實滯後: 5/10日叉+5d, -6%回撤線+9d, 週MACD+26d, 200日線穿越+31d, 10/40週叉+65d, 200日線斜率+83d)。
A9: 限制(誠實揭露) | B9: ①主要轉折僅45個, 統計置信度有限; ②信用/廣度族只覆蓋2016後(12個主要轉折), 量價族只覆蓋1999-2016; ③規則參數為合理預設而非優化, 但仍屬in-sample檢視; ④「領先」為統計中位數, 個別轉折可能失效; ⑤2016年前價格為Composite代理。

Sheet 01_指標排行
A1: 領先指標排行榜 — 按中位lead排序(越負越領先) | 完整規則見03表 | ⭐=HTML raster入選
A2: 排名 | B2: 指標 | C2: 族 | D2: 警訊 | E2: 判定 | F2: 中位lead | G2: 命中率摘要 | H2: 假訊號率 | I2: 入選
A3: 1 | B3: newhigh_low_volume | C3: 量價 | D3: TOP | E3: WEAK | F3: -83 | G3: T7/16 B0/0 | H3: 0.5
A4: 2 | B4: breadth_break_first | C4: 信用廣度 | D4: TOP | E4: LEADING | F4: -82 | G4: T4/6 B0/0 | H4: 0.24 | I4: ⭐
A5: 3 | B5: HV20_rise_from_low_near_high | C5: 波動率 | D5: TOP | E5: LEADING | F5: -80 | G5: T13/22 B0/0 | H5: 0.431 | I5: ⭐
A6: 4 | B6: vix_hyoas_double | C6: 信用廣度 | D6: TOP | E6: WEAK | F6: -80 | G6: T4/6 B0/0 | H6: 0.377
A7: 5 | B7: distribution_cluster | C7: 量價 | D7: TOP | E7: WEAK | F7: -80 | G7: T5/16 B0/0 | H7: 0.383
A8: 6 | B8: HV20_regime_cross25 | C8: 波動率 | D8: TOP | E8: WEAK | F8: -74.5 | G8: T4/22 B0/0 | H8: 0.467
A9: 7 | B9: sma200_slope_neg | C9: 趨勢動能 | D9: TOP | E9: WEAK | F9: -74 | G9: T4/22 B0/0 | H9: 0.571
A10: 8 | B10: rsi14_top_div | C10: 趨勢動能 | D10: TOP | E10: LEADING | F10: -73 | G10: T14/22 B0/0 | H10: 0.34 | I10: ⭐
A11: 9 | B11: breadth_top_divergence | C11: 信用廣度 | D11: TOP | E11: LEADING | F11: -69 | G11: T6/6 B0/0 | H11: 0.125 | I11: ⭐
A12: 10 | B12: hyoas_widen50 | C12: 信用廣度 | D12: TOP | E12: WEAK | F12: -64 | G12: T2/6 B0/0 | H12: 0.6087
A13: 11 | B13: obv_top_divergence | C13: 量價 | D13: TOP | E13: WEAK | F13: -63.5 | G13: T6/16 B0/0 | H13: 0.341
A14: 12 | B14: sma5_10_cross | C14: 趨勢動能 | D14: BOTH | E14: LEADING | F14: -60 | G14: T10/22 B16/22 | H14: 0.432
A15: 13 | B15: close_x_sma200 | C15: 趨勢動能 | D15: BOTH | E15: LEADING | F15: -56.5 | G15: T9/22 B15/22 | H15: 0.425
A16: 14 | B16: macd_wk_hist | C16: 趨勢動能 | D16: BOTH | E16: WEAK | F16: -55 | G16: T8/22 B5/22 | H16: 0.49
A17: 15 | B17: dd52w_cross_6 | C17: 趨勢動能 | D17: TOP | E17: LEADING | F17: -51 | G17: T11/22 B0/0 | H17: 0.525
A18: 16 | B18: VIX_price_rise_divergence | C18: 波動率 | D18: TOP | E18: LEADING | F18: -44 | G18: T6/7 B0/0 | H18: 0.4 | I18: ⭐
A19: 17 | B19: breadth_washout_recovery | C19: 信用廣度 | D19: BOTTOM | E19: LEADING | F19: -44 | G19: T0/0 B4/6 | H19: 0.3333 | I19: ⭐
A20: 18 | B20: score_break70 | C20: 信用廣度 | D20: TOP | E20: WEAK | F20: -44 | G20: T5/6 B0/0 | H20: 0.4355
A21: 19 | B21: hyoas_peak_falloff | C21: 信用廣度 | D21: BOTTOM | E21: LEADING | F21: -43 | G21: T0/0 B5/6 | H21: 0.4769 | I21: ⭐
A22: 20 | B22: volume_climax_reversal_1p5x | C22: 量價 | D22: BOTTOM | E22: WEAK | F22: -35.5 | G22: T0/0 B2/16 | H22: 0.5
A23: 21 | B23: obv_bottom_divergence | C23: 量價 | D23: BOTTOM | E23: LEADING | F23: -34 | G23: T0/0 B12/16 | H23: 0 | I23: ⭐
A24: 22 | B24: rsi14_bot_div | C24: 趨勢動能 | D24: BOTTOM | E24: LEADING | F24: -32 | G24: T0/0 B18/22 | H24: 0 | I24: ⭐
A25: 23 | B25: score_recover45 | C25: 信用廣度 | D25: BOTTOM | E25: LEADING | F25: -29 | G25: T0/0 B5/6 | H25: 0.4667 | I25: ⭐
A26: 24 | B26: HV20_peak_rolloff | C26: 波動率 | D26: BOTTOM | E26: WEAK | F26: -27.5 | G26: T0/0 B4/22 | H26: 0.125
A27: 25 | B27: wk10_40_cross | C27: 趨勢動能 | D27: BOTH | E27: WEAK | F27: -25 | G27: T2/22 B1/22 | H27: 0.529
A28: 26 | B28: VIX_squeeze_break | C28: 波動率 | D28: TOP | E28: WEAK | F28: -16 | G28: T1/7 B0/0 | H28: 0.429
A29: 27 | B29: s_CREDIT | C29: 月度支柱 | D29: BOTH | E29: WEAK | F29: -12.5 | G29: T3/9 B5/9 | H29: 0.262
A30: 28 | B30: score | C30: 月度支柱 | D30: BOTH | E30: LEADING | F30: -8 | G30: T8/9 B5/9 | H30: 0.232 | I30: ⭐
A31: 29 | B31: s_POLICY | C31: 月度支柱 | D31: BOTH | E31: LEADING | F31: -7 | G31: T3/9 B6/9 | H31: 0.333
A32: 30 | B32: s_CURVE | C32: 月度支柱 | D32: TOP | E32: LEADING | F32: -7 | G32: T5/9 B0/0 | H32: 0
A33: 31 | B33: s_INFL | C33: 月度支柱 | D33: TOP | E33: WEAK | F33: -7 | G33: T3/9 B0/0 | H33: 0.111
A34: 32 | B34: s_VOL | C34: 月度支柱 | D34: TOP | E34: CONFIRMING | F34: -6.5 | G34: T4/9 B0/0 | H34: 0.083
A35: 33 | B35: VIX_spike_reversal | C35: 波動率 | D35: BOTTOM | E35: COINCIDENT | F35: -2 | G35: T0/0 B5/7 | H35: 0.167 | I35: ⭐
A36: 34 | B36: volume_climax_reversal_spec | C36: 量價 | D36: BOTTOM | E36: WEAK | F36: 0 | G36: T0/0 B0/16 | H36: 0
B38: LEADING指標數 | F38: =COUNTIF(E3:E36,"LEADING") -> 16
B39: CONFIRMING指標數 | F39: =COUNTIF(E3:E36,"CONFIRMING") -> 1
B40: LEADING之中位lead平均 | F40: =AVERAGEIF(E3:E36,"LEADING",F3:F36) -> -44.96875

Sheet 02_轉折點45個
A1: 主要轉折點 (ZigZag ±15%, 1999-2026) | 統計=活公式
A2: 日期 | B2: 類型 | C2: 價位 | D2: 其後走勢% | E2: 走勢迄
A3: 2000-03-10 | B3: TOP | C3: 4612.28 | D3: -0.3421 | E3: 2000-04-14
A4: 2000-04-14 | B4: BOTTOM | C4: 3034.24 | D4: 0.1917 | E4: 2000-05-01
A5: 2000-05-01 | B5: TOP | C5: 3615.99 | D5: -0.2005 | E5: 2000-05-23
A6: 2000-05-23 | B6: BOTTOM | C6: 2891.05 | D6: 0.3508 | E6: 2000-07-17
A7: 2000-07-17 | B7: TOP | C7: 3905.22 | D7: -0.3923 | E7: 2000-11-30
A8: 2000-11-30 | B8: BOTTOM | C8: 2373.4 | D8: 0.1606 | E8: 2000-12-11
A9: 2000-12-11 | B9: TOP | C9: 2754.51 | D9: -0.2399 | E9: 2001-01-02
A10: 2001-01-02 | B10: BOTTOM | C10: 2093.78 | D10: 0.2475 | E10: 2001-01-24
A11: 2001-01-24 | B11: TOP | C11: 2612.04 | D11: -0.4268 | E11: 2001-04-04
A12: 2001-04-04 | B12: BOTTOM | C12: 1497.16 | D12: 0.4119 | E12: 2001-05-22
A13: 2001-05-22 | B13: TOP | C13: 2113.87 | D13: -0.3849 | E13: 2001-09-21
A14: 2001-09-21 | B14: BOTTOM | C14: 1300.19 | D14: 0.447 | E14: 2002-01-04
... A46: 2025-04-08 | B46: BOTTOM | C46: 17090.4 | D46: 0.7451 | E46: 2026-07-10
A48: TOP數 | C48: =COUNTIF(B3:B46,"TOP") -> 22
A49: BOTTOM數 | C49: =COUNTIF(B3:B46,"BOTTOM") -> 22
A50: TOP後平均跌幅 | C50: =AVERAGEIF(B3:B46,"TOP",D3:D46) -> -0.26960455
A51: BOTTOM後平均升幅 | C51: =AVERAGEIF(B3:B46,"BOTTOM",D3:D46) -> 0.54406818

Sheet 03_指標明細
A1: 全部指標: 客觀規則 + 領先性量測 + 對抗性驗證結果 | lead單位: 交易日(月度支柱族=月), 負=領先
A2: 族 | B2: 指標 | C2: 警訊 | D2: 量化規則 | E2: 覆蓋 | F2: 訊號數 | G2: TOP命中 | H2: BOT命中 | I2: 中位lead | J2: 平均lead | K2: 假訊號率 | L2: 判定 | M2: 族驗證 | N2: 備註
A3: 趨勢動能 | B3: rsi14_top_div | C3: TOP | D3: price makes 63d new high (close>max of prior 63 closes, excl today) AND RSI14[t] <= RSI14[anchor]-2, anchor=most recent confirmed 63d-high day >=10 trading days earlier with lower price; Wilder RSI (ewm alpha=1/14) | E3: 1999-04-27..2026-07-10 | F3: 325 | G3: T14/22 | H3: B0/0 | I3: -73 | J3: -61.1 | K3: 0.34 | L3: LEADING | M3: CONFIRMED | N3: 高密度指標(~12訊號/年, 常連日成串; 配對窗內中位2個訊號), 故『窗內最早』常貼近-90窗緣, median lead -73 部分是窗緣效應, 非精確擇時. FP率0.34(嚴格: 同型MAJOR∪INTER轉折需落在[s,s+90]). 漏掉8/22頂(多為熊市反彈頂如2000-07,2000-12,2001,2008-11,2009-01 — 未創63日新高故規則不適用). 錨點=至少10交易日前已確認之63日高, 無前視. [hit=0.636, FP=109/321可評估訊號(尾端4筆未滿90td不計), 密度12.0/年]
A4: 趨勢動能 | B4: rsi14_bot_div | C4: BOTTOM | D4: price makes 63d new low (close<min of prior 63 closes, excl today) AND RSI14[t] >= RSI14[anchor]+2, anchor=most recent confirmed 63d-low day >=10 trading days earlier with higher price | E4: 1999-04-27..2026-07-10 | F4: 73 | G4: T0/0 | H4: B18/22 | I4: -32 | J4: -40.1 | K4: 0 | L4: LEADING | M4: CONFIRMED | N4: 全家族最佳: 18/22底命中, FP=0/73(每個訊號其後90td內必有MAJOR/INTER底). 2020-03 COVID未命中 — 跌速太快, 價與RSI同創新低無背離(誠實漏訊); 2025-04-08底於2025-04-03提前3td發出; 2022-10-10領先2022-12-28底55td. 密度僅2.7訊號/年, 訊號質量高; median lead -32為真領先而非窗緣效應. [hit=0.818, FP=0/73, 密度2.7/年]
A5: 趨勢動能 | B5: macd_wk_hist | C5: BOTH | D5: W-FRI weekly close MACD(12,26,9) histogram: flip from >=0 to <0 AND daily close>0.92*rolling252max => TOP; flip from <=0 to >0 AND close<1.15*rolling252min => BOTTOM; signal date=last trading day of that week; 40-week EMA warmup | E5: 2000-01-03..2026-07-10 | F5: 49 | G5: T8/22 | H5: B5/22 | I5: -55 | J5: -51.7 | K5: 0.49 | L5: WEAK | M5: CONFIRMED | N5: 命中率僅29.5%(13/44), FP率0.49 → 依協定判WEAK. 主因: 柱狀圖翻負多發生在頂後數週, 超出turn+5窗; 補充診斷: 轉折後首個同型訊號中位滯後+26td(n=13). 實質上是遲到的確認器而非領先指標. 2020兩個轉折皆漏(週線太慢跟不上V型). [hit=0.295, FP=24/49, 密度1.9/年]
A6: 趨勢動能 | B6: sma5_10_cross | C6: BOTH | D6: SMA5 crosses below SMA10 (prev day >=) AND close>=0.95*rolling252max => TOP; SMA5 crosses above SMA10 AND close<=1.12*rolling252min => BOTTOM | E6: 2000-01-03..2026-07-10 | F6: 248 | G6: T10/22 | H6: B16/22 | I6: -60 | J6: -47 | K6: 0.432 | L6: LEADING | M6: CONFIRMED | N6: 命中26/44(底部16/22較佳), 但FP率0.432且~9.4訊號/年(高頻鞭打). 名義LEADING但窗內負lead多來自築頂/築底過程的反覆交叉, 非精確預警. 作確認器反而快: 轉折後首個同型訊號中位滯後僅+5td(n=29) — 2020-03-27(底後5td), 2022-03-17, 2025-04-15皆及時確認. [hit=0.591, FP=105/243可評估(尾端5筆不計), 密度9.4/年]
A7: 趨勢動能 | B7: close_x_sma200 | C7: BOTH | D7: close crosses below SMA200 (prev day close>=SMA200) => TOP-confirm; close crosses above SMA200 (prev day <=) => BOTTOM-confirm | E7: 1999-10-20..2026-07-10 | F7: 176 | G7: T9/22 | H7: B15/22 | I7: -56.5 | J7: -50.3 | K7: 0.425 | L7: LEADING | M7: CONFIRMED | N7: 命中24/44, FP率0.425. median lead -56.5幾乎全來自頂/底過程中的鞭打式穿越(先穿越→收回→再穿越), 非真預警; 作確認器量測: 轉折後首次同向穿越中位滯後+31td(n=40/44). 名義上LEADING(依協定median lead), 實務應視為帶雜訊的確認器. 2020-02-19頂與2025-02-19頂皆漏(頂前價一直在200SMA上). [hit=0.545, FP=74/174可評估(尾端2筆不計), 密度6.6/年]
A8: 趨勢動能 | B8: sma200_slope_neg | C8: TOP | D8: slope=SMA200[t]-SMA200[t-20]; signal when slope flips from >=0 to <0 => TOP | E8: 1999-11-17..2026-07-10 | F8: 14 | G8: T4/22 | H8: B0/0 | I8: -74 | J8: -69.8 | K8: 0.571 | L8: WEAK | M8: CONFIRMED | N8: 僅14訊號/27年, 命中4/22頂(且4個hit全是熊市中段的次級頂, 非週期起始頂), FP率0.571 → WEAK. 診斷: 頂後首訊號中位滯後+83td(n=13) — 極度滯後, 斜率翻負時跌勢多已過半. 作頂部預警無效, 僅適合長週期regime過濾. [hit=0.182, FP=8/14, 密度0.5/年]
A9: 趨勢動能 | B9: wk10_40_cross | C9: BOTH | D9: weekly(W-FRI last close) SMA10 crosses below SMA40 => TOP; crosses above => BOTTOM; signal date=last trading day of that week | E9: 1999-10-22..2026-07-10 | F9: 36 | G9: T2/22 | H9: B1/22 | I9: -25 | J9: -31 | K9: 0.529 | L9: WEAK | M9: CONFIRMED | N9: 如預期為深度確認器: 協定窗[turn-90,turn+5]內幾乎不發訊(3/44命中→依協定WEAK), 因死叉/金叉中位滯後轉折+65td(n=29, 200td內有訊號的轉折). 36訊號FP率0.529, 2011/2015-16多次鞭打. 對照結論: 它確認趨勢已變, 但平均要等約3個月(13週), 對抓轉折無用 — 這就是題目要的滯後量測. [hit=0.068, FP=18/34可評估(尾端2筆不計), 密度1.4/年]
A10: 趨勢動能 | B10: dd52w_cross_6 | C10: TOP | D10: dd=close/rolling252max-1 (max incl today); signal when dd crosses from >=-6% to <-6% => TOP | E10: 2000-01-04..2026-07-10 | F10: 123 | G10: T11/22 | H10: B0/0 | I10: -51 | J10: -50.5 | K10: 0.525 | L10: LEADING | M10: CONFIRMED | N10: 定義上必然在頂後才觸發(需先跌6%): 頂後首訊號中位滯後僅+9td(n=11), 是全家族最快的頂部確認器(2020-02-24即頂後3td). 協定窗內11/22命中且lead為負者多為更早一波回撤的殘留訊號(如2021-09-30訊號配2021-11-19頂). FP率0.525偏高 — 6%回撤常只是牛市中繼. 依協定median lead判LEADING, 實務定位=快速TOP確認器/風控觸發線. [hit=0.5, FP=63/120可評估(尾端3筆不計), 密度4.6/年]
A11: 波動率 | B11: HV20_rise_from_low_near_high | C11: TOP | D11: HV20(t)=std(近20日log報酬,ddof=1)*sqrt(252)*100; 條件C(t): HV20(t)/min(HV20[t-59..t])-1>0.25 且 (max(close[t-251..t])-close(t))/max(close[t-251..t])<0.05; C由False轉True當日發訊 | E11: 1999-12-31..2026-07-10 (需252日滾動高+60日HV最低暖機) | F11: 202 | G11: T13/22 | H11: B0/0 | I11: -80 | J11: -72.8 | K11: 0.431 | L11: LEADING | M11: MINOR_ISSUES | N11: 抓到所有著名大頂(2000/2007/2015/2018/2020/2021/2025), 漏掉的全是熊市中的反彈頂(價不在252日高附近, 規則設計上本就不觸發)。但警告: 訊號極密(202筆,約7.6筆/年), 中位lead=-80貼近90日窗邊界, 命中很大程度靠訊號頻率; FP率43%; 另有6筆訊號因資料尾端90日窗未滿列為不確定、未計入FP。實務上屬『環境警戒』而非精準擇時。
A12: 波動率 | B12: HV20_peak_rolloff | C12: BOTTOM | D12: 狀態機: HV20>60%進入武裝並追蹤episode峰值; HV20(t)<=0.8*峰值當日發訊並解除; 需HV20重新上穿60%才再武裝 | E12: 1999-02-02..2026-07-10 | F12: 8 | G12: T0/0 | H12: B4/22 | I12: -27.5 | J12: -34.8 | K12: 0.125 | L12: WEAK | M12: MINOR_ISSUES | N12: 誠實結論: 不好用。HV20>60%門檻只在2000-01/2008/2020等極端崩盤出現, 27年僅8筆訊號, 命中率18%(4/22)。FP率低(12.5%)但因HV20是落後統計量, 2020-03-20 COVID底的訊號遲至2020-04-14(轉折後+17交易日, 窗外)才出現。多數大底(2016/2018/2022/2025)HV20根本未達60%。
A13: 波動率 | B13: VIX_price_rise_divergence | C13: TOP | D13: 條件C(t): 過去20日內(t-19..t)曾有收盤=252日滾動最高 且 SMA10(VIX)(t)/SMA10(VIX)(t-20)-1>0.10; C由False轉True當日發訊 | E13: 2014-02-14..2026-07-10 (VIX自2014-01-03起, +SMA10與20日變化暖機); tops_evaluated只計此後7個MAJOR TOP | F13: 35 | G13: T6/7 | H13: B0/0 | I13: -44 | J13: -50.2 | K13: 0.4 | L13: LEADING | M13: MINOR_ISSUES | N13: 本家族最佳TOP領先指標: VIX期7個大頂命中6個(86%), 中位領先-44交易日(約2個月)。唯一漏掉2022-08-15(熊市反彈頂, 價未創252日新高)。代價是FP率40%(35筆中14筆後續90日無任何MAJOR/INTER頂)。樣本僅7個頂, 統計效力有限。2025-02-19頂的配對訊號為2024-12-23(lead -37)。
A14: 波動率 | B14: VIX_spike_reversal | C14: BOTTOM | D14: 條件C(t): max(VIX[t-3..t-1])>35 且 VIX(t)<=0.85*該max; C由False轉True當日發訊 | E14: 2014-01-08..2026-07-10 (VIX期); bottoms_evaluated只計此後7個MAJOR BOTTOM | F14: 18 | G14: T0/0 | H14: B5/7 | I14: -2 | J14: -16.4 | K14: 0.167 | L14: COINCIDENT | M14: MINOR_ISSUES | N14: 最可靠的BOTTOM同步確認器: 命中5/7(71%), 中位lead=-2(基本上就在底部當週), FP率僅16.7%。2018-12-24與2025-04-08均在底部後1日確認。漏掉2016-02與2022-12是因VIX兩次都未超過35——門檻本身限制了覆蓋。COVID期間重複發訊(2020-03-02起6筆), 首筆領先真底14日。屬同步/確認型而非領先型。
... A36: 月度支柱 | B36: score | C36: BOTH | D36: TOP: score[t]<70 且 score[t-1]>=70 (合成分跌穿70); BOTTOM: score[t]>40 且 score[t-1]<=40 (升穿40)。 | E36: 1976-01..2026-07 (score自1927-08有效) | F36: 57 | G36: T8/9 | H36: B5/9 | I36: -8 | J36: -6.6 | K36: 0.232 | L36: LEADING | M36: MINOR_ISSUES | N36: lead單位=月。全家族最佳: 頂部8/9(僅漏1980-11), 頂部lead中位約-10.5月; 底部5/9, 底部lead中位-6月(漏1990/1998/2011/2022的急跌底 — score回升太慢, 升穿40常在V形底之後)。整體13/18=72%命中, 中位-8月。FP 13/56=23.2%, 集中於1983-84、1994(四次)、2005、2015-16等mid-cycle降溫; 1筆2025+訊號不可判定。注意跌穿70訊號多(39次), 領先性好但需容忍約1/4假警報。

Sheet 04_逐轉折lead明細
A1: 每個主要轉折 × 每個指標的 lead(交易日/月度族=月) | 空=該轉折無訊號或不在覆蓋期 | 負=領先
A2: 轉折日期 | B2: 類型 | C2: rsi14_top_div | D2: rsi14_bot_div | E2: macd_wk_hist | F2: sma5_10_cross | G2: close_x_sma200 | H2: sma200_slope_neg | I2: wk10_40_cross | J2: dd52w_cross_6 | K2: HV20_rise_from_low_near_high | L2: HV20_peak_rolloff | M2: VIX_price_rise_divergence | N2: VIX_spike_reversal | O2: VIX_squeeze_break | P2: HV20_regime_cross25 | Q2: hyoas_widen50 | R2: hyoas_peak_falloff | S2: breadth_top_divergence | T2: breadth_washout_recovery | U2: breadth_break_first | V2: score_break70 | W2: score_recover45 | X2: vix_hyoas_double | Y2: obv_top_divergence | Z2: obv_bottom_divergence | AA2: distribution_cluster | AB2: volume_climax_reversal_spec | AC2: volume_climax_reversal_1p5x | AD2: newhigh_low_volume | AE2: s_CREDIT | AF2: s_POLICY | AG2: s_CURVE | AH2: s_INFL | AI2: s_VOL | AJ2: score
A3: 2000-03-10 | B3: TOP | C3: -68 | J3: -45 | K3: -42 | P3: -55 | AD3: -72
A4: 2000-04-14 | B4: BOTTOM | G4: 1
A5: 2000-05-01 | B5: TOP | C5: -71 | G5: -10 | J5: -80 | K5: -77 | P5: -90 | AD5: -85
A6: 2000-05-23 | B6: BOTTOM | D6: 0 | G6: -25 | L6: -6
A7: 2000-07-17 | B7: TOP | G7: -63 | I7: -25 | J7: -86 | K7: -83
A8: 2000-11-30 | B8: BOTTOM | D8: -13 | G8: -69
A9: 2000-12-11 | B9: TOP | G9: -65 | H9: -42
A10: 2001-01-02 | B10: BOTTOM | D10: -34 | F10: -1 | G10: -90
A11: 2001-01-24 | B11: TOP | H11: -71
A12: 2001-04-04 | B12: BOTTOM | D12: -90 | F12: -65 | L12: -49 | Z12: -30
A13: 2001-05-22 | B13: TOP
A14: 2001-09-21 | B14: BOTTOM | Z14: -25
A15: 2002-01-04 | B15: TOP | C15: -21 | G15: -9 | Y15: -21
A16: 2002-08-05 | B16: BOTTOM | D16: -71 | F16: -3 | Z16: -44
A17: 2002-08-22 | B17: TOP
A18: 2002-10-09 | B18: BOTTOM | D18: -90 | E18: -18 | F18: -49 | Z18: -90
A19: 2004-01-26 | B19: TOP | C19: -88 | E19: -42 | F19: -83 | J19: -82 | K19: -81 | P19: -79 | Y19: -88 | AA19: -45 | AD19: -18
A20: 2004-08-12 | B20: BOTTOM | F20: 5 | G20: -70 | Z20: -16
A21: 2007-10-31 | B21: TOP | C21: -2 | E21: -67 | F21: -89 | G21: -54 | J21: -65 | K21: -59 | Y21: -85 | AA21: -80 | AD21: -84 | AE21: -7 | AG21: -15 | AJ21: -15
A22: 2008-03-10 | B22: BOTTOM | D22: -22 | F22: -27 | G22: -72 | Z22: -42
A23: 2008-06-05 | B23: TOP | C23: 0 | G23: -12 | H23: -89 | Y23: -17 | AD23: -17
A24: 2008-10-27 | B24: BOTTOM | D24: -17 | E24: -55 | F24: -70 | G24: -54 | Z24: -20
A25: 2008-11-04 | B25: TOP | G25: -59
A26: 2008-11-20 | B26: BOTTOM | D26: -35 | E26: -73 | F26: -88 | G26: -72 | L26: -6 | Z26: -38
A27: 2009-01-06 | B27: TOP
A28: 2009-03-09 | B28: BOTTOM | D28: -90 | L28: -78 | Z28: -78
A29: 2010-04-23 | B29: TOP | C29: -89 | E29: -63 | F29: -67 | J29: -59 | K29: -67 | Y29: -66 | AA29: -88 | AD29: -83
A30: 2010-07-02 | B30: BOTTOM | D30: -19 | G30: -29 | Z30: -3 | AC30: -37
A31: 2011-04-29 | B31: TOP | C31: -58 | E31: -34 | F31: -67 | J31: -31 | K31: -81 | AA31: -47 | AD31: -88 | AI31: -6 | AJ31: -10
A32: 2011-10-03 | B32: BOTTOM | D32: -30 | F32: 5 | G32: -72 | Z32: -74 | AC32: -34
A33: 2015-07-20 | B33: TOP | C33: -83 | E33: -74 | F33: -78 | K33: -85 | M33: -11 | Y33: -61 | AA33: -80
A34: 2016-02-11 | B34: BOTTOM | D34: -18 | E34: -70 | F34: -34 | G34: -75 | I34: -46 | Z34: -4
A35: 2018-08-29 | B35: TOP | C35: -49 | F35: -70 | K35: -80 | M35: -41 | S35: -61 | U35: -80 | V35: -89
A36: 2018-12-24 | B36: BOTTOM | D36: -41 | F36: -33 | G36: -49 | N36: 1 | W36: -35
A37: 2020-02-19 | B37: TOP | C37: -78 | F37: -50 | J37: 3 | K37: -90 | M37: -47 | O37: -16 | S37: -78 | U37: -90 | V37: 3 | X37: -16
A38: 2020-03-20 | B38: BOTTOM | F38: 5 | G38: -8 | N38: -14 | R38: 4 | W38: -8 | AE38: -9 | AF38: -7 | AJ38: 2
A39: 2021-11-19 | B39: TOP | C39: -85 | E39: -40 | F39: -88 | J39: -36 | K39: -44 | M39: -80 | Q39: -44 | S39: -63 | U39: -44 | V39: -44 | X39: -82
A40: 2022-03-14 | B40: BOTTOM | D40: -14 | F40: 3 | G40: -27 | N40: -2 | R40: -88 | T40: -12 | W40: -29
...

Sheet 05_訊號明細
A1: 全部訊號日 (2037筆) | 統計=活公式
A2: 日期 | B2: 指標 | C2: 警訊 | D2: 族
A3: 1976-05-31 | B3: s_CREDIT | C3: BOTTOM | D3: 月度支柱
A4: 1976-10-31 | B4: score | C4: TOP | D4: 月度支柱
A5: 1977-01-31 | B5: s_POLICY | C5: TOP | D5: 月度支柱
A6: 1977-02-28 | B6: score | C6: TOP | D6: 月度支柱
A7: 1977-11-30 | B7: s_INFL | C7: TOP | D7: 月度支柱
A8: 1978-03-31 | B8: score | C8: BOTTOM | D8: 月度支柱
A9: 1978-06-30 | B9: score | C9: TOP | D9: 月度支柱
A10: 1978-10-31 | B10: score | C10: TOP | D10: 月度支柱
A11: 1978-11-30 | B11: s_CURVE | C11: TOP | D11: 月度支柱
A12: 1979-04-30 | B12: s_CREDIT | C12: TOP | D12: 月度支柱
A13: 1979-11-30 | B13: score | C13: BOTTOM | D13: 月度支柱
... A2039: 2026-07-08 | B2039: sma5_10_cross | C2039: TOP | D2039: 趨勢動能
A2041: TOP警訊數 | C2041: =COUNTIF(C3:C2039,"TOP") -> 1599
A2042: BOTTOM警訊數 | C2042: =COUNTIF(C3:C2039,"BOTTOM") -> 438

Sheet 06_日線與趨勢線
A1: 日線 + 趨勢線(活公式) | B=收盤(2016-07前=Composite鏈接) | C-F=活公式: SMA50/SMA200/距252日高/ZigZag轉折標記(查表) | 修改B欄即全表重算
A2: 日期 | B2: 收盤 | C2: SMA50(式) | D2: SMA200(式) | E2: 距252日高(式) | F2: 主要轉折(式) | G2: 來源
A3: 1999-01-04 | B3: 2017.21 | F3: =IFERROR(INDEX(02_轉折點45個!B:B,MATCH(A3,02_轉折點45個!A:A,0)),"") | G3: IXIC_chained
A4: 1999-01-05 | B4: 2056.7 | F4: =IFERROR(INDEX(02_轉折點45個!B:B,MATCH(A4,02_轉折點45個!A:A,0)),"") | G4: IXIC_chained
A5: 1999-01-06 | B5: 2120.27 | F5: =IFERROR(INDEX(02_轉折點45個!B:B,MATCH(A5,02_轉折點45個!A:A,0)),"") | G5: IXIC_chained
A6: 1999-01-07 | B6: 2125.05 | F6: =IFERROR(INDEX(02_轉折點45個!B:B,MATCH(A6,02_轉折點45個!A:A,0)),"") | G6: IXIC_chained
A7: 1999-01-08 | B7: 2141.79 | F7: =IFERROR(INDEX(02_轉折點45個!B:B,MATCH(A7,02_轉折點45個!A:A,0)),"") | G7: IXIC_chained
A8: 1999-01-11 | B8: 2178.5 | F8: =IFERROR(INDEX(02_轉折點45個!B:B,MATCH(A8,02_轉折點45個!A:A,0)),"") | G8: IXIC_chained
A9: 1999-01-12 | B9: 2120.17 | F9: =IFERROR(INDEX(02_轉折點45個!B:B,MATCH(A9,02_轉折點45個!A:A,0)),"") | G9: IXIC_chained
A10: 1999-01-13 | B10: 2116.57 | F10: =IFERROR(INDEX(02_轉折點45個!B:B,MATCH(A10,02_轉折點45個!A:A,0)),"") | G10: IXIC_chained
A11: 1999-01-14 | B11: 2080.04 | F11: =IFERROR(INDEX(02_轉折點45個!B:B,MATCH(A11,02_轉折點45個!A:A,0)),"") | G11: IXIC_chained
A12: 1999-01-15 | B12: 2145.25 | F12: =IFERROR(INDEX(02_轉折點45個!B:B,MATCH(A12,02_轉折點45個!A:A,0)),"") | G12: IXIC_chained
A13: 1999-01-19 | B13: 2200.04 | F13: =IFERROR(INDEX(02_轉折點45個!B:B,MATCH(A13,02_轉折點45個!A:A,0)),"") | G13: IXIC_chained
A14: 1999-01-20 | B14: 2206.73 | F14: =IFERROR(INDEX(02_轉折點45個!B:B,MATCH(A14,02_轉折點45個!A:A,0)),"") | G14: IXIC_chained
... A51: 1999-03-15 | B51: 2221.3 | F51: =IFERROR(INDEX(02_轉折點45個!B:B,MATCH(A51,02_轉折點45個!A:A,0)),"") | G51: IXIC_chained
A52: 1999-03-16 | B52: 2228.45 | C52: =AVERAGE(B3:B52) -> 2154.0476 | F52: =IFERROR(INDEX(02_轉折點45個!B:B,MATCH(A52,02_轉折點45個!A:A,0)),"") | G52: IXIC_chained
A53: 1999-03-17 | B53: 2219.04 | C53: =AVERAGE(B4:B53) -> 2158.0842 | F53: =IFERROR(INDEX(02_轉折點45個!B:B,MATCH(A53,02_轉折點45個!A:A,0)),"") | G53: IXIC_chained
A54: 1999-03-18 | B54: 2250.09 | C54: =AVERAGE(B5:B54) -> 2161.952 | F54: =IFERROR(INDEX(02_轉折點45個!B:B,MATCH(A54,02_轉折點45個!A:A,0)),"") | G54: IXIC_chained
A55: 1999-03-19 | B55: 2212.01 | C55: =AVERAGE(B6:B55) -> 2163.7868 | F55: =IFERROR(INDEX(02_轉折點45個!B:B,MATCH(A55,02_轉折點45個!A:A,0)),"") | G55: IXIC_chained
A56: 1999-03-22 | B56: 2188.87 | C56: =AVERAGE(B7:B56) -> 2165.0632 | F56: =IFERROR(INDEX(02_轉折點45個!B:B,MATCH(A56,02_轉折點45個!A:A,0)),"") | G56: IXIC_chained
A57: 1999-03-23 | B57: 2122.08 | C57: =AVERAGE(B8:B57) -> 2164.669 | F57: =IFERROR(INDEX(02_轉折點45個!B:B,MATCH(A57,02_轉折點45個!A:A,0)),"") | G57: IXIC_chained
A58: 1999-03-24 | B58: 2160.86 | C58: =AVERAGE(B9:B58) -> 2164.3162 | F58: =IFERROR(INDEX(02_轉折點45個!B:B,MATCH(A58,02_轉折點45個!A:A,0)),"") | G58: IXIC_chained
A59: 1999-03-25 | B59: 2224.37 | C59: =AVERAGE(B10:B59) -> 2166.4002 | F59: =IFERROR(INDEX(02_轉折點45個!B:B,MATCH(A59,02_轉折點45個!A:A,0)),"") | G59: IXIC_chained
A60: 1999-03-26 | B60: 2210.09 | C60: =AVERAGE(B11:B60) -> 2168.2706 | F60: =IFERROR(INDEX(02_轉折點45個!B:B,MATCH(A60,02_轉折點45個!A:A,0)),"") | G60: IXIC_chained
A61: 1999-03-29 | B61: 2277.39 | C61: =AVERAGE(B12:B61) -> 2172.2176 | F61: =IFERROR(INDEX(02_轉折點45個!B:B,MATCH(A61,02_轉折點45個!A:A,0)),"") | G61: IXIC_chained
A62: 1999-03-30 | B62: 2265.93 | C62: =AVERAGE(B13:B62) -> 2174.6312 | F62: =IFERROR(INDEX(02_轉折點45個!B:B,MATCH(A62,02_轉折點45個!A:A,0)),"") | G62: IXIC_chained
A63: 1999-03-31 | B63: 2248.67 | C63: =AVERAGE(B14:B63) -> 2175.6038 | F63: =IFERROR(INDEX(02_轉折點45個!B:B,MATCH(A63,02_轉折點45個!A:A,0)),"") | G63: IXIC_chained
... A201: 1999-10-15 | B201: 2495.73 | C201: =AVERAGE(B152:B201) -> 2518.6948 | F201: =IFERROR(INDEX(02_轉折點45個!B:B,MATCH(A201,02_轉折點45個!A:A,0)),"") | G201: IXIC_chained
A202: 1999-10-18 | B202: 2456.73 | C202: =AVERAGE(B153:B202) -> 2521.2742 | D202: =AVERAGE(B3:B202) -> 2338.7806 | F202: =IFERROR(INDEX(02_轉折點45個!B:B,MATCH(A202,02_轉折點45個!A:A,0)),"") | G202: IXIC_chained
A203: 1999-10-19 | B203: 2455.85 | C203: =AVERAGE(B154:B203) -> 2524.3658 | D203: =AVERAGE(B4:B203) -> 2340.9738 | F203: =IFERROR(INDEX(02_轉折點45個!B:B,MATCH(A203,02_轉折點45個!A:A,0)),"") | G203: IXIC_chained
A204: 1999-10-20 | B204: 2547.16 | C204: =AVERAGE(B155:B204) -> 2529.811 | D204: =AVERAGE(B5:B204) -> 2343.4261 | F204: =IFERROR(INDEX(02_轉折點45個!B:B,MATCH(A204,02_轉折點45個!A:A,0)),"") | G204: IXIC_chained
A205: 1999-10-21 | B205: 2559.78 | C205: =AVERAGE(B156:B205) -> 2534.1406 | D205: =AVERAGE(B6:B205) -> 2345.6236 | F205: =IFERROR(INDEX(02_轉折點45個!B:B,MATCH(A205,02_轉折點45個!A:A,0)),"") | G205: IXIC_chained
A206: 1999-10-22 | B206: 2573.1 | C206: =AVERAGE(B157:B206) -> 2539.0198 | D206: =AVERAGE(B7:B206) -> 2347.8639 | F206: =IFERROR(INDEX(02_轉折點45個!B:B,MATCH(A206,02_轉折點45個!A:A,0)),"") | G206: IXIC_chained
A207: 1999-10-25 | B207: 2572.57 | C207: =AVERAGE(B158:B207) -> 2542.2746 | D207: =AVERAGE(B8:B207) -> 2350.0178 | F207: =IFERROR(INDEX(02_轉折點45個!B:B,MATCH(A207,02_轉折點45個!A:A,0)),"") | G207: IXIC_chained
A208: 1999-10-26 | B208: 2568.48 | C208: =AVERAGE(B159:B208) -> 2545.311 | D208: =AVERAGE(B9:B208) -> 2351.9677 | F208: =IFERROR(INDEX(02_轉折點45個!B:B,MATCH(A208,02_轉折點45個!A:A,0)),"") | G208: IXIC_chained
A209: 1999-10-27 | B209: 2560.31 | C209: =AVERAGE(B160:B209) -> 2547.71 | D209: =AVERAGE(B10:B209) -> 2354.1684 | F209: =IFERROR(INDEX(02_轉折點45個!B:B,MATCH(A209,02_轉折點45個!A:A,0)),"") | G209: IXIC_chained
A210: 1999-10-28 | B210: 2626.72 | C210: =AVERAGE(B161:B210) -> 2551.6838 | D210: =AVERAGE(B11:B210) -> 2356.7191 | F210: =IFERROR(INDEX(02_轉折點45個!B:B,MATCH(A210,02_轉折點45個!A:A,0)),"") | G210: IXIC_chained
A211: 1999-10-29 | B211: 2710.05 | C211: =AVERAGE(B162:B211) -> 2557.9874 | D211: =AVERAGE(B12:B211) -> 2359.8692 | F211: =IFERROR(INDEX(02_轉折點45個!B:B,MATCH(A211,02_轉折點45個!A:A,0)),"") | G211: IXIC_chained
A212: 1999-11-01 | B212: 2711.16 | C212: =AVERAGE(B163:B212) -> 2563.8218 | D212: =AVERAGE(B13:B212) -> 2362.6988 | F212: =IFERROR(INDEX(02_轉折點45個!B:B,MATCH(A212,02_轉折點45個!A:A,0)),"") | G212: IXIC_chained
A213: 1999-11-02 | B213: 2723.94 | C213: =AVERAGE(B164:B213) -> 2568.6102 | D213: =AVERAGE(B14:B213) -> 2365.3182 | F213: =IFERROR(INDEX(02_轉折點45個!B:B,MATCH(A213,02_轉折點45個!A:A,0)),"") | G213: IXIC_chained
...
