Workbook

Sheet 00_說明
A1: ndx_turning_(TECHNICAL_INDICATOR) — A-Chart 格式 Excel 版 (2026-07-28)
A2: 對應 | B2: HTML版=Macro_dashboard R15.12 A-Chart 頁完整保留(B/C/D已移除)+A3.1訊號raster+A3.2排行榜+TURNS領先排名實裝。本Excel=同一數據的表格版。
A3: 01表 | B3: A0面板同組技術指標(活公式): dashboard內嵌真實NDX OHLC/成交量(2020-01-02..2026-07-27, 1649交易日) + MA5/10/20/50/100/200 + BOLL(20,2σ) + RSI14(Wilder) + MACD(12,26,9) + 三區制度zone(A1.8A Fable) + ZigZag轉折標記 + 當日領先訊號數(COUNTIF活算)。修改F欄(收盤)即全表重算。
A4: 02-05表 | B4: 02=45個主要轉折(1999-2026, ±15%) | 03=34指標領先性排行(45轉折驗證) | 04=逐轉折×逐指標lead矩陣 | 05=全部2037個訊號日。
A5: 驗證 | B5: 01表公式與dashboard預計算陣列交叉核對(sma200/rsi/macd末值一致, 見01表底部核對區); 34指標領先性經5個對抗性驗證agent重算(見前次交付03表)。
A6: 限制 | B6: 01表軸=dashboard價格軸(2020起); 1999-2019轉折見02表, 完整日線見repo data/ndx_daily_spliced.csv。RSI/MACD前若干行為暖機期。

Sheet 01_A0技術指標
A1: A0-Nasdaq 100 · dashboard真實OHLC(2020-01-02..2026-07-27) + A-Chart同組技術指標(活公式) | B-F=OHLC值 G=量 H-M=MA5/10/20/50/100/200 N-P=BOLL Q-T=RSI14(Wilder) U-X=MACD(12,26,9) Y=三區zone Z=轉折 AA/AB=當日頂/底訊號數(式)
A2: 日期 | B2: 開 | C2: 高 | D2: 低 | E2: 收 | F2: 量 | G2: MA5(式) | H2: MA10(式) | I2: MA20(式) | J2: MA50(式) | K2: MA100(式) | L2: MA200(式) | M2: BOLL中(式) | N2: BOLL上(式) | O2: BOLL下(式) | P2: 漲U(式) | Q2: 跌D(式) | R2: AvgU14(式) | S2: AvgD14(式) | T2: RSI14(式) | U2: EMA12(式) | V2: EMA26(式) | W2: MACD(式) | X2: Signal9(式) | Y2: Hist(式) | Z2: 三區zone | AA2: 轉折(式) | AB2: 頂訊(式) | AC2: 底訊(式)
A3: 2020-01-02 | B3: 8802.22 | C3: 8873.63 | D3: 8786.9 | E3: 8872.22 | F3: 2863 | Z3: EASY | AA3: =IFERROR(INDEX(02_轉折點45!B:B,MATCH(A3,02_轉折點45!A:A,0)),"") | AB3: =COUNTIFS(05_訊號明細!A:A,A3,05_訊號明細!C:C,"TOP") -> 1 | AC3: =COUNTIFS(05_訊號明細!A:A,A3,05_訊號明細!C:C,"BOTTOM") -> 0
A4: 2020-01-03 | B4: 8755.17 | C4: 8843.65 | D4: 8755.17 | E4: 8793.9 | F4: 2587 | P4: =MAX(E4-E3,0) -> 0 | Q4: =MAX(E3-E4,0) -> 78.32 | Z4: EASY | AA4: =IFERROR(INDEX(02_轉折點45!B:B,MATCH(A4,02_轉折點45!A:A,0)),"") | AB4: =COUNTIFS(05_訊號明細!A:A,A4,05_訊號明細!C:C,"TOP") -> 0 | AC4: =COUNTIFS(05_訊號明細!A:A,A4,05_訊號明細!C:C,"BOTTOM") -> 0
A5: 2020-01-06 | B5: 8713.89 | C5: 8849.98 | D5: 8713.89 | E5: 8848.52 | F5: 2810 | P5: =MAX(E5-E4,0) -> 54.62 | Q5: =MAX(E4-E5,0) -> 0 | Z5: EASY | AA5: =IFERROR(INDEX(02_轉折點45!B:B,MATCH(A5,02_轉折點45!A:A,0)),"") | AB5: =COUNTIFS(05_訊號明細!A:A,A5,05_訊號明細!C:C,"TOP") -> 0 | AC5: =COUNTIFS(05_訊號明細!A:A,A5,05_訊號明細!C:C,"BOTTOM") -> 0
A6: 2020-01-07 | B6: 8857.14 | C6: 8872.47 | D6: 8821.68 | E6: 8846.45 | F6: 2382 | P6: =MAX(E6-E5,0) -> 0 | Q6: =MAX(E5-E6,0) -> 2.07 | Z6: EASY | AA6: =IFERROR(INDEX(02_轉折點45!B:B,MATCH(A6,02_轉折點45!A:A,0)),"") | AB6: =COUNTIFS(05_訊號明細!A:A,A6,05_訊號明細!C:C,"TOP") -> 0 | AC6: =COUNTIFS(05_訊號明細!A:A,A6,05_訊號明細!C:C,"BOTTOM") -> 0
A7: 2020-01-08 | B7: 8845.45 | C7: 8953.55 | D7: 8834.94 | E7: 8912.37 | F7: 2473 | G7: =AVERAGE(E3:E7) -> 8854.692 | P7: =MAX(E7-E6,0) -> 65.92 | Q7: =MAX(E6-E7,0) -> 0 | Z7: EASY | AA7: =IFERROR(INDEX(02_轉折點45!B:B,MATCH(A7,02_轉折點45!A:A,0)),"") | AB7: =COUNTIFS(05_訊號明細!A:A,A7,05_訊號明細!C:C,"TOP") -> 1 | AC7: =COUNTIFS(05_訊號明細!A:A,A7,05_訊號明細!C:C,"BOTTOM") -> 0
A8: 2020-01-09 | B8: 8990.04 | C8: 9004.55 | D8: 8938.53 | E8: 8989.63 | F8: 2541 | G8: =AVERAGE(E4:E8) -> 8878.174 | P8: =MAX(E8-E7,0) -> 77.26 | Q8: =MAX(E7-E8,0) -> 0 | Z8: EASY | AA8: =IFERROR(INDEX(02_轉折點45!B:B,MATCH(A8,02_轉折點45!A:A,0)),"") | AB8: =COUNTIFS(05_訊號明細!A:A,A8,05_訊號明細!C:C,"TOP") -> 0 | AC8: =COUNTIFS(05_訊號明細!A:A,A8,05_訊號明細!C:C,"BOTTOM") -> 0
A9: 2020-01-10 | B9: 9021.88 | C9: 9024.87 | D9: 8951.83 | E9: 8966.64 | F9: 2383 | G9: =AVERAGE(E5:E9) -> 8912.722 | P9: =MAX(E9-E8,0) -> 0 | Q9: =MAX(E8-E9,0) -> 22.99 | Z9: EASY | AA9: =IFERROR(INDEX(02_轉折點45!B:B,MATCH(A9,02_轉折點45!A:A,0)),"") | AB9: =COUNTIFS(05_訊號明細!A:A,A9,05_訊號明細!C:C,"TOP") -> 0 | AC9: =COUNTIFS(05_訊號明細!A:A,A9,05_訊號明細!C:C,"BOTTOM") -> 0
A10: 2020-01-13 | B10: 9007.94 | C10: 9071.53 | D10: 8991.35 | E10: 9070.65 | F10: 2537 | G10: =AVERAGE(E6:E10) -> 8957.148 | P10: =MAX(E10-E9,0) -> 104.01 | Q10: =MAX(E9-E10,0) -> 0 | Z10: EASY | AA10: =IFERROR(INDEX(02_轉折點45!B:B,MATCH(A10,02_轉折點45!A:A,0)),"") | AB10: =COUNTIFS(05_訊號明細!A:A,A10,05_訊號明細!C:C,"TOP") -> 1 | AC10: =COUNTIFS(05_訊號明細!A:A,A10,05_訊號明細!C:C,"BOTTOM") -> 0
A11: 2020-01-14 | B11: 9068.02 | C11: 9080.16 | D11: 9020.92 | E11: 9033.42 | F11: 2553 | G11: =AVERAGE(E7:E11) -> 8994.542 | P11: =MAX(E11-E10,0) -> 0 | Q11: =MAX(E10-E11,0) -> 37.23 | Z11: EASY | AA11: =IFERROR(INDEX(02_轉折點45!B:B,MATCH(A11,02_轉折點45!A:A,0)),"") | AB11: =COUNTIFS(05_訊號明細!A:A,A11,05_訊號明細!C:C,"TOP") -> 0 | AC11: =COUNTIFS(05_訊號明細!A:A,A11,05_訊號明細!C:C,"BOTTOM") -> 0
A12: 2020-01-15 | B12: 9039.31 | C12: 9078.87 | D12: 9008.95 | E12: 9035.67 | F12: 2443 | G12: =AVERAGE(E8:E12) -> 9019.202 | H12: =AVERAGE(E3:E12) -> 8936.947 | P12: =MAX(E12-E11,0) -> 2.25 | Q12: =MAX(E11-E12,0) -> 0 | Z12: EASY | AA12: =IFERROR(INDEX(02_轉折點45!B:B,MATCH(A12,02_轉折點45!A:A,0)),"") | AB12: =COUNTIFS(05_訊號明細!A:A,A12,05_訊號明細!C:C,"TOP") -> 0 | AC12: =COUNTIFS(05_訊號明細!A:A,A12,05_訊號明細!C:C,"BOTTOM") -> 0
A13: 2020-01-16 | B13: 9088.08 | C13: 9126.07 | D13: 9066.31 | E13: 9125 | F13: 2312 | G13: =AVERAGE(E9:E13) -> 9046.276 | H13: =AVERAGE(E4:E13) -> 8962.225 | P13: =MAX(E13-E12,0) -> 89.33 | Q13: =MAX(E12-E13,0) -> 0 | Z13: EASY | AA13: =IFERROR(INDEX(02_轉折點45!B:B,MATCH(A13,02_轉折點45!A:A,0)),"") | AB13: =COUNTIFS(05_訊號明細!A:A,A13,05_訊號明細!C:C,"TOP") -> 0 | AC13: =COUNTIFS(05_訊號明細!A:A,A13,05_訊號明細!C:C,"BOTTOM") -> 0
A14: 2020-01-17 | B14: 9159.48 | C14: 9176.47 | D14: 9118.98 | E14: 9173.73 | F14: 2543 | G14: =AVERAGE(E10:E14) -> 9087.694 | H14: =AVERAGE(E5:E14) -> 9000.208 | P14: =MAX(E14-E13,0) -> 48.73 | Q14: =MAX(E13-E14,0) -> 0 | U14: =AVERAGE(E3:E14) -> 8972.35 | Z14: EASY | AA14: =IFERROR(INDEX(02_轉折點45!B:B,MATCH(A14,02_轉折點45!A:A,0)),"") | AB14: =COUNTIFS(05_訊號明細!A:A,A14,05_訊號明細!C:C,"TOP") -> 0 | AC14: =COUNTIFS(05_訊號明細!A:A,A14,05_訊號明細!C:C,"BOTTOM") -> 0
A15: 2020-01-21 | B15: 9145.64 | C15: 9187.42 | D15: 9141.78 | E15: 9166.63 | F15: 2687 | G15: =AVERAGE(E11:E15) -> 9106.89 | H15: =AVERAGE(E6:E15) -> 9032.019 | P15: =MAX(E15-E14,0) -> 0 | Q15: =MAX(E14-E15,0) -> 7.1 | U15: =E15*2/13+U14*11/13 -> 9002.2392 | Z15: EASY | AA15: =IFERROR(INDEX(02_轉折點45!B:B,MATCH(A15,02_轉折點45!A:A,0)),"") | AB15: =COUNTIFS(05_訊號明細!A:A,A15,05_訊號明細!C:C,"TOP") -> 0 | AC15: =COUNTIFS(05_訊號明細!A:A,A15,05_訊號明細!C:C,"BOTTOM") -> 0
A16: 2020-01-22 | B16: 9212.35 | C16: 9242.48 | D16: 9179.27 | E16: 9188.58 | F16: 2455 | G16: =AVERAGE(E12:E16) -> 9137.922 | H16: =AVERAGE(E7:E16) -> 9066.232 | P16: =MAX(E16-E15,0) -> 21.95 | Q16: =MAX(E15-E16,0) -> 0 | U16: =E16*2/13+U15*11/13 -> 9030.907 | Z16: EASY | AA16: =IFERROR(INDEX(02_轉折點45!B:B,MATCH(A16,02_轉折點45!A:A,0)),"") | AB16: =COUNTIFS(05_訊號明細!A:A,A16,05_訊號明細!C:C,"TOP") -> 0 | AC16: =COUNTIFS(05_訊號明細!A:A,A16,05_訊號明細!C:C,"BOTTOM") -> 0
A17: 2020-01-23 | B17: 9186.14 | C17: 9221.13 | D17: 9145.23 | E17: 9216.98 | F17: 2466 | G17: =AVERAGE(E13:E17) -> 9174.184 | H17: =AVERAGE(E8:E17) -> 9096.693 | P17: =MAX(E17-E16,0) -> 28.4 | Q17: =MAX(E16-E17,0) -> 0 | R17: =AVERAGE(P4:P17) -> 35.176429 | S17: =AVERAGE(Q4:Q17) -> 10.550714 | T17: =IF(S17=0,100,100-100/(1+R17/S17)) -> 76.926802 | U17: =E17*2/13+U16*11/13 -> 9059.5337 | Z17: EASY | AA17: =IFERROR(INDEX(02_轉折點45!B:B,MATCH(A17,02_轉折點45!A:A,0)),"") | AB17: =COUNTIFS(05_訊號明細!A:A,A17,05_訊號明細!C:C,"TOP") -> 0 | AC17: =COUNTIFS(05_訊號明細!A:A,A17,05_訊號明細!C:C,"BOTTOM") -> 0
A18: 2020-01-24 | B18: 9266.35 | C18: 9272.37 | D18: 9101.44 | E18: 9141.47 | F18: 2623 | G18: =AVERAGE(E14:E18) -> 9177.478 | H18: =AVERAGE(E9:E18) -> 9111.877 | P18: =MAX(E18-E17,0) -> 0 | Q18: =MAX(E17-E18,0) -> 75.51 | R18: =(R17*13+P18)/14 -> 32.663827 | S18: =(S17*13+Q18)/14 -> 15.190663 | T18: =IF(S18=0,100,100-100/(1+R18/S18)) -> 68.256556 | U18: =E18*2/13+U17*11/13 -> 9072.1392 | Z18: EASY | AA18: =IFERROR(INDEX(02_轉折點45!B:B,MATCH(A18,02_轉折點45!A:A,0)),"") | AB18: =COUNTIFS(05_訊號明細!A:A,A18,05_訊號明細!C:C,"TOP") -> 0 | AC18: =COUNTIFS(05_訊號明細!A:A,A18,05_訊號明細!C:C,"BOTTOM") -> 0
A19: 2020-01-27 | B19: 8913.16 | C19: 9001.44 | D19: 8910.97 | E19: 8952.18 | F19: 2594 | G19: =AVERAGE(E15:E19) -> 9133.168 | H19: =AVERAGE(E10:E19) -> 9110.431 | P19: =MAX(E19-E18,0) -> 0 | Q19: =MAX(E18-E19,0) -> 189.29 | R19: =(R18*13+P19)/14 -> 30.330696 | S19: =(S18*13+Q19)/14 -> 27.62633 | T19: =IF(S19=0,100,100-100/(1+R19/S19)) -> 52.333079 | U19: =E19*2/13+U18*11/13 -> 9053.684 | Z19: EASY | AA19: =IFERROR(INDEX(02_轉折點45!B:B,MATCH(A19,02_轉折點45!A:A,0)),"") | AB19: =COUNTIFS(05_訊號明細!A:A,A19,05_訊號明細!C:C,"TOP") -> 2 | AC19: =COUNTIFS(05_訊號明細!A:A,A19,05_訊號明細!C:C,"BOTTOM") -> 0
A20: 2020-01-28 | B20: 9013.23 | C20: 9111.32 | D20: 8994.28 | E20: 9090.93 | F20: 2169 | G20: =AVERAGE(E16:E20) -> 9118.028 | H20: =AVERAGE(E11:E20) -> 9112.459 | P20: =MAX(E20-E19,0) -> 138.75 | Q20: =MAX(E19-E20,0) -> 0 | R20: =(R19*13+P20)/14 -> 38.074932 | S20: =(S19*13+Q20)/14 -> 25.653021 | T20: =IF(S20=0,100,100-100/(1+R20/S20)) -> 59.746046 | U20: =E20*2/13+U19*11/13 -> 9059.4141 | Z20: EASY | AA20: =IFERROR(INDEX(02_轉折點45!B:B,MATCH(A20,02_轉折點45!A:A,0)),"") | AB20: =COUNTIFS(05_訊號明細!A:A,A20,05_訊號明細!C:C,"TOP") -> 0 | AC20: =COUNTIFS(05_訊號明細!A:A,A20,05_訊號明細!C:C,"BOTTOM") -> 0
A21: 2020-01-29 | B21: 9141.52 | C21: 9153.08 | D21: 9067.29 | E21: 9101.61 | F21: 2235 | G21: =AVERAGE(E17:E21) -> 9100.634 | H21: =AVERAGE(E12:E21) -> 9119.278 | P21: =MAX(E21-E20,0) -> 10.68 | Q21: =MAX(E20-E21,0) -> 0 | R21: =(R20*13+P21)/14 -> 36.118151 | S21: =(S20*13+Q21)/14 -> 23.820662 | T21: =IF(S21=0,100,100-100/(1+R21/S21)) -> 60.258369 | U21: =E21*2/13+U20*11/13 -> 9065.9058 | Z21: EASY | AA21: =IFERROR(INDEX(02_轉折點45!B:B,MATCH(A21,02_轉折點45!A:A,0)),"") | AB21: =COUNTIFS(05_訊號明細!A:A,A21,05_訊號明細!C:C,"TOP") -> 2 | AC21: =COUNTIFS(05_訊號明細!A:A,A21,05_訊號明細!C:C,"BOTTOM") -> 0
A22: 2020-01-30 | B22: 9038.92 | C22: 9140.69 | D22: 9019.72 | E22: 9136.09 | F22: 2345 | G22: =AVERAGE(E18:E22) -> 9084.456 | H22: =AVERAGE(E13:E22) -> 9129.32 | I22: =AVERAGE(E3:E22) -> 9033.1335 | M22: =I22 -> 9033.1335 | N22: =I22+2*STDEV(E3:E22) -> 9290.7671 | O22: =I22-2*STDEV(E3:E22) -> 8775.4999 | P22: =MAX(E22-E21,0) -> 34.48 | Q22: =MAX(E21-E22,0) -> 0 | R22: =(R21*13+P22)/14 -> 36.00114 | S22: =(S21*13+Q22)/14 -> 22.119186 | T22: =IF(S22=0,100,100-100/(1+R22/S22)) -> 61.942426 | U22: =E22*2/13+U21*11/13 -> 9076.7034 | Z22: EASY | AA22: =IFERROR(INDEX(02_轉折點45!B:B,MATCH(A22,02_轉折點45!A:A,0)),"") | AB22: =COUNTIFS(05_訊號明細!A:A,A22,05_訊號明細!C:C,"TOP") -> 0 | AC22: =COUNTIFS(05_訊號明細!A:A,A22,05_訊號明細!C:C,"BOTTOM") -> 0
A23: 2020-01-31 | B23: 9169.91 | C23: 9170.22 | D23: 8961.59 | E23: 8991.51 | F23: 2696 | G23: =AVERAGE(E19:E23) -> 9054.464 | H23: =AVERAGE(E14:E23) -> 9115.971 | I23: =AVERAGE(E4:E23) -> 9039.098 | M23: =I23 -> 9039.098 | N23: =I23+2*STDEV(E4:E23) -> 9286.3607 | O23: =I23-2*STDEV(E4:E23) -> 8791.8353 | P23: =MAX(E23-E22,0) -> 0 | Q23: =MAX(E22-E23,0) -> 144.58 | R23: =(R22*13+P23)/14 -> 33.42963 | S23: =(S22*13+Q23)/14 -> 30.866387 | T23: =IF(S23=0,100,100-100/(1+R23/S23)) -> 51.993314 | U23: =E23*2/13+U22*11/13 -> 9063.5967 | Z23: EASY | AA23: =IFERROR(INDEX(02_轉折點45!B:B,MATCH(A23,02_轉折點45!A:A,0)),"") | AB23: =COUNTIFS(05_訊號明細!A:A,A23,05_訊號明細!C:C,"TOP") -> 1 | AC23: =COUNTIFS(05_訊號明細!A:A,A23,05_訊號明細!C:C,"BOTTOM") -> 0
A24: 2020-02-03 | B24: 9033.52 | C24: 9148.5 | D24: 9031.07 | E24: 9126.23 | F24: 2427 | G24: =AVERAGE(E20:E24) -> 9089.274 | H24: =AVERAGE(E15:E24) -> 9111.221 | I24: =AVERAGE(E5:E24) -> 9055.7145 | M24: =I24 -> 9055.7145 | N24: =I24+2*STDEV(E5:E24) -> 9276.887 | O24: =I24-2*STDEV(E5:E24) -> 8834.542 | P24: =MAX(E24-E23,0) -> 134.72 | Q24: =MAX(E23-E24,0) -> 0 | R24: =(R23*13+P24)/14 -> 40.664657 | S24: =(S23*13+Q24)/14 -> 28.661645 | T24: =IF(S24=0,100,100-100/(1+R24/S24)) -> 58.656896 | U24: =E24*2/13+U23*11/13 -> 9073.2326 | Z24: EASY | AA24: =IFERROR(INDEX(02_轉折點45!B:B,MATCH(A24,02_轉折點45!A:A,0)),"") | AB24: =COUNTIFS(05_訊號明細!A:A,A24,05_訊號明細!C:C,"TOP") -> 0 | AC24: =COUNTIFS(05_訊號明細!A:A,A24,05_訊號明細!C:C,"BOTTOM") -> 0
A25: 2020-02-04 | B25: 9256.94 | C25: 9352.96 | D25: 9224.86 | E25: 9334.06 | F25: 2447 | G25: =AVERAGE(E21:E25) -> 9137.9 | H25: =AVERAGE(E16:E25) -> 9127.964 | I25: =AVERAGE(E6:E25) -> 9079.9915 | M25: =I25 -> 9079.9915 | N25: =I25+2*STDEV(E6:E25) -> 9311.7429 | O25: =I25-2*STDEV(E6:E25) -> 8848.2401 | P25: =MAX(E25-E24,0) -> 207.83 | Q25: =MAX(E24-E25,0) -> 0 | R25: =(R24*13+P25)/14 -> 52.605038 | S25: =(S24*13+Q25)/14 -> 26.614385 | T25: =IF(S25=0,100,100-100/(1+R25/S25)) -> 66.404218 | U25: =E25*2/13+U24*11/13 -> 9113.3599 | Z25: EASY | AA25: =IFERROR(INDEX(02_轉折點45!B:B,MATCH(A25,02_轉折點45!A:A,0)),"") | AB25: =COUNTIFS(05_訊號明細!A:A,A25,05_訊號明細!C:C,"TOP") -> 1 | AC25: =COUNTIFS(05_訊號明細!A:A,A25,05_訊號明細!C:C,"BOTTOM") -> 0
A26: 2020-02-05 | B26: 9441.34 | C26: 9442.75 | D26: 9311.88 | E26: 9367.48 | F26: 2470 | G26: =AVERAGE(E22:E26) -> 9191.074 | H26: =AVERAGE(E17:E26) -> 9145.854 | I26: =AVERAGE(E7:E26) -> 9106.043 | M26: =I26 -> 9106.043 | N26: =I26+2*STDEV(E7:E26) -> 9344.3046 | O26: =I26-2*STDEV(E7:E26) -> 8867.7814 | P26: =MAX(E26-E25,0) -> 33.42 | Q26: =MAX(E25-E26,0) -> 0 | R26: =(R25*13+P26)/14 -> 51.234679 | S26: =(S25*13+Q26)/14 -> 24.713358 | T26: =IF(S26=0,100,100-100/(1+R26/S26)) -> 67.460176 | U26: =E26*2/13+U25*11/13 -> 9152.4553 | Z26: EASY | AA26: =IFERROR(INDEX(02_轉折點45!B:B,MATCH(A26,02_轉折點45!A:A,0)),"") | AB26: =COUNTIFS(05_訊號明細!A:A,A26,05_訊號明細!C:C,"TOP") -> 1 | AC26: =COUNTIFS(05_訊號明細!A:A,A26,05_訊號明細!C:C,"BOTTOM") -> 0
A27: 2020-02-06 | B27: 9395.69 | C27: 9448.72 | D27: 9357.86 | E27: 9445.92 | F27: 2314 | G27: =AVERAGE(E23:E27) -> 9253.04 | H27: =AVERAGE(E18:E27) -> 9168.748 | I27: =AVERAGE(E8:E27) -> 9132.7205 | M27: =I27 -> 9132.7205 | N27: =I27+2*STDEV(E8:E27) -> 9397.663 | O27: =I27-2*STDEV(E8:E27) -> 8867.778 | P27: =MAX(E27-E26,0) -> 78.44 | Q27: =MAX(E26-E27,0) -> 0 | R27: =(R26*13+P27)/14 -> 53.177916 | S27: =(S26*13+Q27)/14 -> 22.948118 | T27: =IF(S27=0,100,100-100/(1+R27/S27)) -> 69.855099 | U27: =E27*2/13+U26*11/13 -> 9197.6037 | Z27: EASY | AA27: =IFERROR(INDEX(02_轉折點45!B:B,MATCH(A27,02_轉折點45!A:A,0)),"") | AB27: =COUNTIFS(05_訊號明細!A:A,A27,05_訊號明細!C:C,"TOP") -> 1 | AC27: =COUNTIFS(05_訊號明細!A:A,A27,05_訊號明細!C:C,"BOTTOM") -> 0
A28: 2020-02-07 | B28: 9397.77 | C28: 9453.24 | D28: 9376.91 | E28: 9401.1 | F28: 2244 | G28: =AVERAGE(E24:E28) -> 9334.958 | H28: =AVERAGE(E19:E28) -> 9194.711 | I28: =AVERAGE(E9:E28) -> 9153.294 | M28: =I28 -> 9153.294 | N28: =I28+2*STDEV(E9:E28) -> 9434.8354 | O28: =I28-2*STDEV(E9:E28) -> 8871.7526 | P28: =MAX(E28-E27,0) -> 0 | Q28: =MAX(E27-E28,0) -> 44.82 | R28: =(R27*13+P28)/14 -> 49.379493 | S28: =(S27*13+Q28)/14 -> 24.510395 | T28: =IF(S28=0,100,100-100/(1+R28/S28)) -> 66.828485 | U28: =E28*2/13+U27*11/13 -> 9228.9108 | V28: =AVERAGE(E3:E28) -> 9089.5758 | W28: =U28-V28 -> 139.33506 | Z28: EASY | AA28: =IFERROR(INDEX(02_轉折點45!B:B,MATCH(A28,02_轉折點45!A:A,0)),"") | AB28: =COUNTIFS(05_訊號明細!A:A,A28,05_訊號明細!C:C,"TOP") -> 0 | AC28: =COUNTIFS(05_訊號明細!A:A,A28,05_訊號明細!C:C,"BOTTOM") -> 0
A29: 2020-02-10 | B29: 9373.2 | C29: 9517.74 | D29: 9373.2 | E29: 9516.84 | F29: 2188 | G29: =AVERAGE(E25:E29) -> 9413.08 | H29: =AVERAGE(E20:E29) -> 9251.177 | I29: =AVERAGE(E10:E29) -> 9180.804 | M29: =I29 -> 9180.804 | N29: =I29+2*STDEV(E10:E29) -> 9491.5591 | O29: =I29-2*STDEV(E10:E29) -> 8870.0489 | P29: =MAX(E29-E28,0) -> 115.74 | Q29: =MAX(E28-E29,0) -> 0 | R29: =(R28*13+P29)/14 -> 54.119529 | S29: =(S28*13+Q29)/14 -> 22.759652 | T29: =IF(S29=0,100,100-100/(1+R29/S29)) -> 70.395558 | U29: =E29*2/13+U28*11/13 -> 9273.2076 | V29: =E29*2/27+V28*25/27 -> 9121.225 | W29: =U29-V29 -> 151.98265 | Z29: EASY | AA29: =IFERROR(INDEX(02_轉折點45!B:B,MATCH(A29,02_轉折點45!A:A,0)),"") | AB29: =COUNTIFS(05_訊號明細!A:A,A29,05_訊號明細!C:C,"TOP") -> 1 | AC29: =COUNTIFS(05_訊號明細!A:A,A29,05_訊號明細!C:C,"BOTTOM") -> 0
A30: 2020-02-11 | B30: 9567.81 | C30: 9600.05 | D30: 9493.63 | E30: 9517.86 | F30: 2450 | G30: =AVERAGE(E26:E30) -> 9449.84 | H30: =AVERAGE(E21:E30) -> 9293.87 | I30: =AVERAGE(E11:E30) -> 9203.1645 | M30: =I30 -> 9203.1645 | N30: =I30+2*STDEV(E11:E30) -> 9543.497 | O30: =I30-2*STDEV(E11:E30) -> 8862.832 | P30: =MAX(E30-E29,0) -> 1.02 | Q30: =MAX(E29-E30,0) -> 0 | R30: =(R29*13+P30)/14 -> 50.326706 | S30: =(S29*13+Q30)/14 -> 21.133963 | T30: =IF(S30=0,100,100-100/(1+R30/S30)) -> 70.425741 | U30: =E30*2/13+U29*11/13 -> 9310.8465 | V30: =E30*2/27+V29*25/27 -> 9150.6053 | W30: =U30-V30 -> 160.24111 | Z30: EASY | AA30: =IFERROR(INDEX(02_轉折點45!B:B,MATCH(A30,02_轉折點45!A:A,0)),"") | AB30: =COUNTIFS(05_訊號明細!A:A,A30,05_訊號明細!C:C,"TOP") -> 1 | AC30: =COUNTIFS(05_訊號明細!A:A,A30,05_訊號明細!C:C,"BOTTOM") -> 0
A31: 2020-02-12 | B31: 9569.82 | C31: 9615.91 | D31: 9552.03 | E31: 9613.2 | F31: 2367 | G31: =AVERAGE(E27:E31) -> 9498.984 | H31: =AVERAGE(E22:E31) -> 9345.029 | I31: =AVERAGE(E12:E31) -> 9232.1535 | M31: =I31 -> 9232.1535 | N31: =I31+2*STDEV(E12:E31) -> 9608.4745 | O31: =I31-2*STDEV(E12:E31) -> 8855.8325 | P31: =MAX(E31-E30,0) -> 95.34 | Q31: =MAX(E30-E31,0) -> 0 | R31: =(R30*13+P31)/14 -> 53.541941 | S31: =(S30*13+Q31)/14 -> 19.624394 | T31: =IF(S31=0,100,100-100/(1+R31/S31)) -> 73.178383 | U31: =E31*2/13+U30*11/13 -> 9357.3624 | V31: =E31*2/27+V30*25/27 -> 9184.8716 | W31: =U31-V31 -> 172.49077 | Z31: EASY | AA31: =IFERROR(INDEX(02_轉折點45!B:B,MATCH(A31,02_轉折點45!A:A,0)),"") | AB31: =COUNTIFS(05_訊號明細!A:A,A31,05_訊號明細!C:C,"TOP") -> 1 | AC31: =COUNTIFS(05_訊號明細!A:A,A31,05_訊號明細!C:C,"BOTTOM") -> 0
A32: 2020-02-13 | B32: 9540.67 | C32: 9636.41 | D32: 9532.74 | E32: 9595.7 | F32: 2255 | G32: =AVERAGE(E28:E32) -> 9528.94 | H32: =AVERAGE(E23:E32) -> 9390.99 | I32: =AVERAGE(E13:E32) -> 9260.155 | M32: =I32 -> 9260.155 | N32: =I32+2*STDEV(E13:E32) -> 9657.6635 | O32: =I32-2*STDEV(E13:E32) -> 8862.6465 | P32: =MAX(E32-E31,0) -> 0 | Q32: =MAX(E31-E32,0) -> 17.5 | R32: =(R31*13+P32)/14 -> 49.717517 | S32: =(S31*13+Q32)/14 -> 19.472652 | T32: =IF(S32=0,100,100-100/(1+R32/S32)) -> 71.856331 | U32: =E32*2/13+U31*11/13 -> 9394.0297 | V32: =E32*2/27+V31*25/27 -> 9215.3033 | W32: =U32-V32 -> 178.72636 | Z32: EASY | AA32: =IFERROR(INDEX(02_轉折點45!B:B,MATCH(A32,02_轉折點45!A:A,0)),"") | AB32: =COUNTIFS(05_訊號明細!A:A,A32,05_訊號明細!C:C,"TOP") -> 0 | AC32: =COUNTIFS(05_訊號明細!A:A,A32,05_訊號明細!C:C,"BOTTOM") -> 0
A33: 2020-02-14 | B33: 9613.88 | C33: 9634.75 | D33: 9583.08 | E33: 9623.58 | F33: 2227 | G33: =AVERAGE(E29:E33) -> 9573.436 | H33: =AVERAGE(E24:E33) -> 9454.197 | I33: =AVERAGE(E14:E33) -> 9285.084 | M33: =I33 -> 9285.084 | N33: =I33+2*STDEV(E14:E33) -> 9708.589 | O33: =I33-2*STDEV(E14:E33) -> 8861.579 | P33: =MAX(E33-E32,0) -> 27.88 | Q33: =MAX(E32-E33,0) -> 0 | R33: =(R32*13+P33)/14 -> 48.157694 | S33: =(S32*13+Q33)/14 -> 18.081748 | T33: =IF(S33=0,100,100-100/(1+R33/S33)) -> 72.702445 | U33: =E33*2/13+U32*11/13 -> 9429.3451 | V33: =E33*2/27+V32*25/27 -> 9245.5461 | W33: =U33-V33 -> 183.79907 | Z33: EASY | AA33: =IFERROR(INDEX(02_轉折點45!B:B,MATCH(A33,02_轉折點45!A:A,0)),"") | AB33: =COUNTIFS(05_訊號明細!A:A,A33,05_訊號明細!C:C,"TOP") -> 1 | AC33: =COUNTIFS(05_訊號明細!A:A,A33,05_訊號明細!C:C,"BOTTOM") -> 0
A34: 2020-02-18 | B34: 9567.28 | C34: 9647.72 | D34: 9567.28 | E34: 9629.8 | F34: 2279 | G34: =AVERAGE(E30:E34) -> 9596.028 | H34: =AVERAGE(E25:E34) -> 9504.554 | I34: =AVERAGE(E15:E34) -> 9307.8875 | M34: =I34 -> 9307.8875 | N34: =I34+2*STDEV(E15:E34) -> 9754.6237 | O34: =I34-2*STDEV(E15:E34) -> 8861.1513 | P34: =MAX(E34-E33,0) -> 6.22 | Q34: =MAX(E33-E34,0) -> 0 | R34: =(R33*13+P34)/14 -> 45.162145 | S34: =(S33*13+Q34)/14 -> 16.790195 | T34: =IF(S34=0,100,100-100/(1+R34/S34)) -> 72.898207 | U34: =E34*2/13+U33*11/13 -> 9460.1843 | V34: =E34*2/27+V33*25/27 -> 9274.0093 | W34: =U34-V34 -> 186.17503 | Z34: EASY | AA34: =IFERROR(INDEX(02_轉折點45!B:B,MATCH(A34,02_轉折點45!A:A,0)),"") | AB34: =COUNTIFS(05_訊號明細!A:A,A34,05_訊號明細!C:C,"TOP") -> 1 | AC34: =COUNTIFS(05_訊號明細!A:A,A34,05_訊號明細!C:C,"BOTTOM") -> 0
A35: 2020-02-19 | B35: 9683.94 | C35: 9736.57 | D35: 9676.07 | E35: 9718.73 | F35: 2471 | G35: =AVERAGE(E31:E35) -> 9636.202 | H35: =AVERAGE(E26:E35) -> 9543.021 | I35: =AVERAGE(E16:E35) -> 9335.4925 | M35: =I35 -> 9335.4925 | N35: =I35+2*STDEV(E16:E35) -> 9812.6706 | O35: =I35-2*STDEV(E16:E35) -> 8858.3144 | P35: =MAX(E35-E34,0) -> 88.93 | Q35: =MAX(E34-E35,0) -> 0 | R35: =(R34*13+P35)/14 -> 48.28842 | S35: =(S34*13+Q35)/14 -> 15.590895 | T35: =IF(S35=0,100,100-100/(1+R35/S35)) -> 75.593203 | U35: =E35*2/13+U34*11/13 -> 9499.9606 | V35: =E35*2/27+V34*25/27 -> 9306.9516 | W35: =U35-V35 -> 193.00901 | Z35: EASY | AA35: =IFERROR(INDEX(02_轉折點45!B:B,MATCH(A35,02_轉折點45!A:A,0)),"") -> TOP | AB35: =COUNTIFS(05_訊號明細!A:A,A35,05_訊號明細!C:C,"TOP") -> 0 | AC35: =COUNTIFS(05_訊號明細!A:A,A35,05_訊號明細!C:C,"BOTTOM") -> 0
A36: 2020-02-20 | B36: 9696.66 | C36: 9714.23 | D36: 9513.23 | E36: 9627.83 | F36: 2746 | G36: =AVERAGE(E32:E36) -> 9639.128 | H36: =AVERAGE(E27:E36) -> 9569.056 | I36: =AVERAGE(E17:E36) -> 9357.455 | M36: =I36 -> 9357.455 | N36: =I36+2*STDEV(E17:E36) -> 9846.4499 | O36: =I36-2*STDEV(E17:E36) -> 8868.4601 | P36: =MAX(E36-E35,0) -> 0 | Q36: =MAX(E35-E36,0) -> 90.9 | R36: =(R35*13+P36)/14 -> 44.839247 | S36: =(S35*13+Q36)/14 -> 20.970117 | T36: =IF(S36=0,100,100-100/(1+R36/S36)) -> 68.135056 | U36: =E36*2/13+U35*11/13 -> 9519.6328 | V36: =E36*2/27+V35*25/27 -> 9330.7204 | W36: =U36-V36 -> 188.91246 | X36: =AVERAGE(W28:W36) -> 172.74128 | Y36: =W36-X36 -> 16.171176 | Z36: EASY | AA36: =IFERROR(INDEX(02_轉折點45!B:B,MATCH(A36,02_轉折點45!A:A,0)),"") | AB36: =COUNTIFS(05_訊號明細!A:A,A36,05_訊號明細!C:C,"TOP") -> 0 | AC36: =COUNTIFS(05_訊號明細!A:A,A36,05_訊號明細!C:C,"BOTTOM") -> 0
A37: 2020-02-21 | B37: 9582.54 | C37: 9594 | D37: 9406.38 | E37: 9446.69 | F37: 2750 | G37: =AVERAGE(E33:E37) -> 9609.326 | H37: =AVERAGE(E28:E37) -> 9569.133 | I37: =AVERAGE(E18:E37) -> 9368.9405 | M37: =I37 -> 9368.9405 | N37: =I37+2*STDEV(E18:E37) -> 9854.8238 | O37: =I37-2*STDEV(E18:E37) -> 8883.0572 | P37: =MAX(E37-E36,0) -> 0 | Q37: =MAX(E36-E37,0) -> 181.14 | R37: =(R36*13+P37)/14 -> 41.636444 | S37: =(S36*13+Q37)/14 -> 32.410823 | T37: =IF(S37=0,100,100-100/(1+R37/S37)) -> 56.229549 | U37: =E37*2/13+U36*11/13 -> 9508.4108 | V37: =E37*2/27+V36*25/27 -> 9339.3107 | W37: =U37-V37 -> 169.10014 | X37: =W37*2/10+X36*8/10 -> 172.01305 | Y37: =W37-X37 -> -2.9129114 | Z37: EASY | AA37: =IFERROR(INDEX(02_轉折點45!B:B,MATCH(A37,02_轉折點45!A:A,0)),"") | AB37: =COUNTIFS(05_訊號明細!A:A,A37,05_訊號明細!C:C,"TOP") -> 0 | AC37: =COUNTIFS(05_訊號明細!A:A,A37,05_訊號明細!C:C,"BOTTOM") -> 0
A38: 2020-02-24 | B38: 9055.3 | C38: 9194.91 | D38: 9028.87 | E38: 9079.63 | F38: 3189 | G38: =AVERAGE(E34:E38) -> 9500.536 | H38: =AVERAGE(E29:E38) -> 9536.986 | I38: =AVERAGE(E19:E38) -> 9365.8485 | M38: =I38 -> 9365.8485 | N38: =I38+2*STDEV(E19:E38) -> 9858.5657 | O38: =I38-2*STDEV(E19:E38) -> 8873.1313 | P38: =MAX(E38-E37,0) -> 0 | Q38: =MAX(E37-E38,0) -> 367.06 | R38: =(R37*13+P38)/14 -> 38.662412 | S38: =(S37*13+Q38)/14 -> 56.314335 | T38: =IF(S38=0,100,100-100/(1+R38/S38)) -> 40.707239 | U38: =E38*2/13+U37*11/13 -> 9442.4446 | V38: =E38*2/27+V37*25/27 -> 9320.0751 | W38: =U38-V38 -> 122.36946 | X38: =W38*2/10+X37*8/10 -> 162.08433 | Y38: =W38-X38 -> -39.71487 | Z38: UNCERTAIN | AA38: =IFERROR(INDEX(02_轉折點45!B:B,MATCH(A38,02_轉折點45!A:A,0)),"") | AB38: =COUNTIFS(05_訊號明細!A:A,A38,05_訊號明細!C:C,"TOP") -> 3 | AC38: =COUNTIFS(05_訊號明細!A:A,A38,05_訊號明細!C:C,"BOTTOM") -> 0
A39: 2020-02-25 | B39: 9167.33 | C39: 9183.78 | D39: 8807.11 | E39: 8834.87 | F39: 3596 | G39: =AVERAGE(E35:E39) -> 9341.55 | H39: =AVERAGE(E30:E39) -> 9468.789 | I39: =AVERAGE(E20:E39) -> 9359.983 | M39: =I39 -> 9359.983 | N39: =I39+2*STDEV(E20:E39) -> 9875.6914 | O39: =I39-2*STDEV(E20:E39) -> 8844.2746 | P39: =MAX(E39-E38,0) -> 0 | Q39: =MAX(E38-E39,0) -> 244.76 | R39: =(R38*13+P39)/14 -> 35.900811 | S39: =(S38*13+Q39)/14 -> 69.77474 | T39: =IF(S39=0,100,100-100/(1+R39/S39)) -> 33.972675 | U39: =E39*2/13+U38*11/13 -> 9348.9716 | V39: =E39*2/27+V38*25/27 -> 9284.134 | W39: =U39-V39 -> 64.837573 | X39: =W39*2/10+X38*8/10 -> 142.63498 | Y39: =W39-X39 -> -77.797409 | Z39: UNCERTAIN | AA39: =IFERROR(INDEX(02_轉折點45!B:B,MATCH(A39,02_轉折點45!A:A,0)),"") | AB39: =COUNTIFS(05_訊號明細!A:A,A39,05_訊號明細!C:C,"TOP") -> 0 | AC39: =COUNTIFS(05_訊號明細!A:A,A39,05_訊號明細!C:C,"BOTTOM") -> 0
A40: 2020-02-26 | B40: 8883.01 | C40: 9032.88 | D40: 8813.92 | E40: 8873.76 | F40: 3588 | G40: =AVERAGE(E36:E40) -> 9172.556 | H40: =AVERAGE(E31:E40) -> 9404.379 | I40: =AVERAGE(E21:E40) -> 9349.1245 | M40: =I40 -> 9349.1245 | N40: =I40+2*STDEV(E21:E40) -> 9896.8379 | O40: =I40-2*STDEV(E21:E40) -> 8801.4111 | P40: =MAX(E40-E39,0) -> 38.89 | Q40: =MAX(E39-E40,0) -> 0 | R40: =(R39*13+P40)/14 -> 36.114325 | S40: =(S39*13+Q40)/14 -> 64.79083 | T40: =IF(S40=0,100,100-100/(1+R40/S40)) -> 35.790366 | U40: =E40*2/13+U39*11/13 -> 9275.8621 | V40: =E40*2/27+V39*25/27 -> 9253.7359 | W40: =U40-V40 -> 22.126176 | X40: =W40*2/10+X39*8/10 -> 118.53322 | Y40: =W40-X40 -> -96.407045 | Z40: UNCERTAIN | AA40: =IFERROR(INDEX(02_轉折點45!B:B,MATCH(A40,02_轉折點45!A:A,0)),"") | AB40: =COUNTIFS(05_訊號明細!A:A,A40,05_訊號明細!C:C,"TOP") -> 1 | AC40: =COUNTIFS(05_訊號明細!A:A,A40,05_訊號明細!C:C,"BOTTOM") -> 0
...

Sheet 02_轉折點45
A1: 主要轉折點 (ZigZag ±15%, 1999-2026) | 2020後14個落在01表軸內
A2: 日期 | B2: 類型 | C2: 價位 | D2: 其後走勢% | E2: 走勢迄
A3: 2000-03-10 | B3: TOP | C3: 4612.28 | D3: -0.3421 | E3: 2000-04-14
A4: 2000-04-14 | B4: BOTTOM | C4: 3034.24 | D4: 0.1917 | E4: 2000-05-01
A5: 2000-05-01 | B5: TOP | C5: 3615.99 | D5: -0.2005 | E5: 2000-05-23
A6: 2000-05-23 | B6: BOTTOM | C6: 2891.05 | D6: 0.3508 | E6: 2000-07-17
A7: 2000-07-17 | B7: TOP | C7: 3905.22 | D7: -0.3923 | E7: 2000-11-30
A8: 2000-11-30 | B8: BOTTOM | C8: 2373.4 | D8: 0.1606 | E8: 2000-12-11
A9: 2000-12-11 | B9: TOP | C9: 2754.51 | D9: -0.2399 | E9: 2001-01-02
A10: 2001-01-02 | B10: BOTTOM | C10: 2093.78 | D10: 0.2475 | E10: 2001-01-24
A11: 2001-01-24 | B11: TOP | C11: 2612.04 | D11: -0.4268 | E11: 2001-04-04
A12: 2001-04-04 | B12: BOTTOM | C12: 1497.16 | D12: 0.4119 | E12: 2001-05-22
A13: 2001-05-22 | B13: TOP | C13: 2113.87 | D13: -0.3849 | E13: 2001-09-21
A14: 2001-09-21 | B14: BOTTOM | C14: 1300.19 | D14: 0.447 | E14: 2002-01-04
... A46: 2025-04-08 | B46: BOTTOM | C46: 17090.4 | D46: 0.7451 | E46: 2026-07-10

Sheet 05_訊號明細
A1: 全部訊號日 (2037筆) | 01表當日訊號數以COUNTIFS引用本表
A2: 日期 | B2: 指標 | C2: 警訊 | D2: 族
A3: 1976-05-31 | B3: s_CREDIT | C3: BOTTOM | D3: 月度支柱
A4: 1976-10-31 | B4: score | C4: TOP | D4: 月度支柱
A5: 1977-01-31 | B5: s_POLICY | C5: TOP | D5: 月度支柱
A6: 1977-02-28 | B6: score | C6: TOP | D6: 月度支柱
A7: 1977-11-30 | B7: s_INFL | C7: TOP | D7: 月度支柱
A8: 1978-03-31 | B8: score | C8: BOTTOM | D8: 月度支柱
A9: 1978-06-30 | B9: score | C9: TOP | D9: 月度支柱
A10: 1978-10-31 | B10: score | C10: TOP | D10: 月度支柱
A11: 1978-11-30 | B11: s_CURVE | C11: TOP | D11: 月度支柱
A12: 1979-04-30 | B12: s_CREDIT | C12: TOP | D12: 月度支柱
A13: 1979-11-30 | B13: score | C13: BOTTOM | D13: 月度支柱
... A2039: 2026-07-08 | B2039: sma5_10_cross | C2039: TOP | D2039: 趨勢動能

Sheet 03_領先指標排行
A1: 34指標領先性排行 (45轉折×5族×對抗性驗證) | 中位lead越負越領先 | ⭐=A3.1 raster入選
A2: 排名 | B2: 指標 | C2: 族 | D2: 警訊 | E2: 判定 | F2: 中位lead | G2: 命中 | H2: FP率 | I2: ⭐
A3: 1 | B3: newhigh_low_volume | C3: 量價 | D3: TOP | E3: WEAK | F3: -83d | G3: T7/16 B0/0 | H3: 0.5
A4: 2 | B4: breadth_break_first | C4: 信用廣度 | D4: TOP | E4: LEADING | F4: -82d | G4: T4/6 B0/0 | H4: 0.24 | I4: ⭐
A5: 3 | B5: HV20_rise_from_low_near_high | C5: 波動率 | D5: TOP | E5: LEADING | F5: -80d | G5: T13/22 B0/0 | H5: 0.431 | I5: ⭐
A6: 4 | B6: vix_hyoas_double | C6: 信用廣度 | D6: TOP | E6: WEAK | F6: -80d | G6: T4/6 B0/0 | H6: 0.377
A7: 5 | B7: distribution_cluster | C7: 量價 | D7: TOP | E7: WEAK | F7: -80d | G7: T5/16 B0/0 | H7: 0.383
A8: 6 | B8: HV20_regime_cross25 | C8: 波動率 | D8: TOP | E8: WEAK | F8: -74d | G8: T4/22 B0/0 | H8: 0.467
A9: 7 | B9: sma200_slope_neg | C9: 趨勢動能 | D9: TOP | E9: WEAK | F9: -74d | G9: T4/22 B0/0 | H9: 0.571
A10: 8 | B10: rsi14_top_div | C10: 趨勢動能 | D10: TOP | E10: LEADING | F10: -73d | G10: T14/22 B0/0 | H10: 0.34 | I10: ⭐
A11: 9 | B11: breadth_top_divergence | C11: 信用廣度 | D11: TOP | E11: LEADING | F11: -69d | G11: T6/6 B0/0 | H11: 0.125 | I11: ⭐
A12: 10 | B12: hyoas_widen50 | C12: 信用廣度 | D12: TOP | E12: WEAK | F12: -64d | G12: T2/6 B0/0 | H12: 0.6087
A13: 11 | B13: obv_top_divergence | C13: 量價 | D13: TOP | E13: WEAK | F13: -64d | G13: T6/16 B0/0 | H13: 0.341
A14: 12 | B14: sma5_10_cross | C14: 趨勢動能 | D14: BOTH | E14: LEADING | F14: -60d | G14: T10/22 B16/22 | H14: 0.432
A15: 13 | B15: close_x_sma200 | C15: 趨勢動能 | D15: BOTH | E15: LEADING | F15: -56d | G15: T9/22 B15/22 | H15: 0.425
A16: 14 | B16: macd_wk_hist | C16: 趨勢動能 | D16: BOTH | E16: WEAK | F16: -55d | G16: T8/22 B5/22 | H16: 0.49
A17: 15 | B17: dd52w_cross_6 | C17: 趨勢動能 | D17: TOP | E17: LEADING | F17: -51d | G17: T11/22 B0/0 | H17: 0.525
A18: 16 | B18: VIX_price_rise_divergence | C18: 波動率 | D18: TOP | E18: LEADING | F18: -44d | G18: T6/7 B0/0 | H18: 0.4 | I18: ⭐
A19: 17 | B19: breadth_washout_recovery | C19: 信用廣度 | D19: BOTTOM | E19: LEADING | F19: -44d | G19: T0/0 B4/6 | H19: 0.3333 | I19: ⭐
A20: 18 | B20: score_break70 | C20: 信用廣度 | D20: TOP | E20: WEAK | F20: -44d | G20: T5/6 B0/0 | H20: 0.4355
A21: 19 | B21: hyoas_peak_falloff | C21: 信用廣度 | D21: BOTTOM | E21: LEADING | F21: -43d | G21: T0/0 B5/6 | H21: 0.4769 | I21: ⭐
A22: 20 | B22: volume_climax_reversal_1p5x | C22: 量價 | D22: BOTTOM | E22: WEAK | F22: -36d | G22: T0/0 B2/16 | H22: 0.5
A23: 21 | B23: obv_bottom_divergence | C23: 量價 | D23: BOTTOM | E23: LEADING | F23: -34d | G23: T0/0 B12/16 | H23: 0 | I23: ⭐
A24: 22 | B24: rsi14_bot_div | C24: 趨勢動能 | D24: BOTTOM | E24: LEADING | F24: -32d | G24: T0/0 B18/22 | H24: 0 | I24: ⭐
A25: 23 | B25: score_recover45 | C25: 信用廣度 | D25: BOTTOM | E25: LEADING | F25: -29d | G25: T0/0 B5/6 | H25: 0.4667 | I25: ⭐
A26: 24 | B26: HV20_peak_rolloff | C26: 波動率 | D26: BOTTOM | E26: WEAK | F26: -28d | G26: T0/0 B4/22 | H26: 0.125
A27: 25 | B27: wk10_40_cross | C27: 趨勢動能 | D27: BOTH | E27: WEAK | F27: -25d | G27: T2/22 B1/22 | H27: 0.529
A28: 26 | B28: VIX_squeeze_break | C28: 波動率 | D28: TOP | E28: WEAK | F28: -16d | G28: T1/7 B0/0 | H28: 0.429
A29: 27 | B29: s_CREDIT | C29: 月度支柱 | D29: BOTH | E29: WEAK | F29: -12月 | G29: T3/9 B5/9 | H29: 0.262
A30: 28 | B30: score | C30: 月度支柱 | D30: BOTH | E30: LEADING | F30: -8月 | G30: T8/9 B5/9 | H30: 0.232 | I30: ⭐
A31: 29 | B31: s_POLICY | C31: 月度支柱 | D31: BOTH | E31: LEADING | F31: -7月 | G31: T3/9 B6/9 | H31: 0.333
A32: 30 | B32: s_CURVE | C32: 月度支柱 | D32: TOP | E32: LEADING | F32: -7月 | G32: T5/9 B0/0 | H32: 0
A33: 31 | B33: s_INFL | C33: 月度支柱 | D33: TOP | E33: WEAK | F33: -7月 | G33: T3/9 B0/0 | H33: 0.111
A34: 32 | B34: s_VOL | C34: 月度支柱 | D34: TOP | E34: CONFIRMING | F34: -6月 | G34: T4/9 B0/0 | H34: 0.083
A35: 33 | B35: VIX_spike_reversal | C35: 波動率 | D35: BOTTOM | E35: COINCIDENT | F35: -2d | G35: T0/0 B5/7 | H35: 0.167 | I35: ⭐
A36: 34 | B36: volume_climax_reversal_spec | C36: 量價 | D36: BOTTOM | E36: WEAK | F36: +0d | G36: T0/0 B0/16 | H36: 0

Sheet 04_逐轉折lead矩陣
A1: 主要轉折 × 指標 lead (交易日, 月度族=月, 負=領先, 空=無訊號/不在覆蓋期)
A2: 轉折日期 | B2: 類型 | C2: rsi14_top_div | D2: rsi14_bot_div | E2: macd_wk_hist | F2: sma5_10_cross | G2: close_x_sma200 | H2: sma200_slope_neg | I2: wk10_40_cross | J2: dd52w_cross_6 | K2: HV20_rise_from_low_near_high | L2: HV20_peak_rolloff | M2: VIX_price_rise_divergence | N2: VIX_spike_reversal | O2: VIX_squeeze_break | P2: HV20_regime_cross25 | Q2: hyoas_widen50 | R2: hyoas_peak_falloff | S2: breadth_top_divergence | T2: breadth_washout_recovery | U2: breadth_break_first | V2: score_break70 | W2: score_recover45 | X2: vix_hyoas_double | Y2: obv_top_divergence | Z2: obv_bottom_divergence | AA2: distribution_cluster | AB2: volume_climax_reversal_spec | AC2: volume_climax_reversal_1p5x | AD2: newhigh_low_volume | AE2: s_CREDIT | AF2: s_POLICY | AG2: s_CURVE | AH2: s_INFL | AI2: s_VOL | AJ2: score
A3: 2000-03-10 | B3: TOP | C3: -68 | J3: -45 | K3: -42 | P3: -55 | AD3: -72
A4: 2000-04-14 | B4: BOTTOM | G4: 1
A5: 2000-05-01 | B5: TOP | C5: -71 | G5: -10 | J5: -80 | K5: -77 | P5: -90 | AD5: -85
A6: 2000-05-23 | B6: BOTTOM | D6: 0 | G6: -25 | L6: -6
A7: 2000-07-17 | B7: TOP | G7: -63 | I7: -25 | J7: -86 | K7: -83
A8: 2000-11-30 | B8: BOTTOM | D8: -13 | G8: -69
A9: 2000-12-11 | B9: TOP | G9: -65 | H9: -42
A10: 2001-01-02 | B10: BOTTOM | D10: -34 | F10: -1 | G10: -90
A11: 2001-01-24 | B11: TOP | H11: -71
A12: 2001-04-04 | B12: BOTTOM | D12: -90 | F12: -65 | L12: -49 | Z12: -30
A13: 2001-05-22 | B13: TOP
A14: 2001-09-21 | B14: BOTTOM | Z14: -25
A15: 2002-01-04 | B15: TOP | C15: -21 | G15: -9 | Y15: -21
A16: 2002-08-05 | B16: BOTTOM | D16: -71 | F16: -3 | Z16: -44
A17: 2002-08-22 | B17: TOP
A18: 2002-10-09 | B18: BOTTOM | D18: -90 | E18: -18 | F18: -49 | Z18: -90
A19: 2004-01-26 | B19: TOP | C19: -88 | E19: -42 | F19: -83 | J19: -82 | K19: -81 | P19: -79 | Y19: -88 | AA19: -45 | AD19: -18
A20: 2004-08-12 | B20: BOTTOM | F20: 5 | G20: -70 | Z20: -16
A21: 2007-10-31 | B21: TOP | C21: -2 | E21: -67 | F21: -89 | G21: -54 | J21: -65 | K21: -59 | Y21: -85 | AA21: -80 | AD21: -84 | AE21: -7 | AG21: -15 | AJ21: -15
A22: 2008-03-10 | B22: BOTTOM | D22: -22 | F22: -27 | G22: -72 | Z22: -42
A23: 2008-06-05 | B23: TOP | C23: 0 | G23: -12 | H23: -89 | Y23: -17 | AD23: -17
A24: 2008-10-27 | B24: BOTTOM | D24: -17 | E24: -55 | F24: -70 | G24: -54 | Z24: -20
A25: 2008-11-04 | B25: TOP | G25: -59
A26: 2008-11-20 | B26: BOTTOM | D26: -35 | E26: -73 | F26: -88 | G26: -72 | L26: -6 | Z26: -38
A27: 2009-01-06 | B27: TOP
A28: 2009-03-09 | B28: BOTTOM | D28: -90 | L28: -78 | Z28: -78
A29: 2010-04-23 | B29: TOP | C29: -89 | E29: -63 | F29: -67 | J29: -59 | K29: -67 | Y29: -66 | AA29: -88 | AD29: -83
A30: 2010-07-02 | B30: BOTTOM | D30: -19 | G30: -29 | Z30: -3 | AC30: -37
A31: 2011-04-29 | B31: TOP | C31: -58 | E31: -34 | F31: -67 | J31: -31 | K31: -81 | AA31: -47 | AD31: -88 | AI31: -6 | AJ31: -10
A32: 2011-10-03 | B32: BOTTOM | D32: -30 | F32: 5 | G32: -72 | Z32: -74 | AC32: -34
A33: 2015-07-20 | B33: TOP | C33: -83 | E33: -74 | F33: -78 | K33: -85 | M33: -11 | Y33: -61 | AA33: -80
A34: 2016-02-11 | B34: BOTTOM | D34: -18 | E34: -70 | F34: -34 | G34: -75 | I34: -46 | Z34: -4
A35: 2018-08-29 | B35: TOP | C35: -49 | F35: -70 | K35: -80 | M35: -41 | S35: -61 | U35: -80 | V35: -89
A36: 2018-12-24 | B36: BOTTOM | D36: -41 | F36: -33 | G36: -49 | N36: 1 | W36: -35
A37: 2020-02-19 | B37: TOP | C37: -78 | F37: -50 | J37: 3 | K37: -90 | M37: -47 | O37: -16 | S37: -78 | U37: -90 | V37: 3 | X37: -16
A38: 2020-03-20 | B38: BOTTOM | F38: 5 | G38: -8 | N38: -14 | R38: 4 | W38: -8 | AE38: -9 | AF38: -7 | AJ38: 2
A39: 2021-11-19 | B39: TOP | C39: -85 | E39: -40 | F39: -88 | J39: -36 | K39: -44 | M39: -80 | Q39: -44 | S39: -63 | U39: -44 | V39: -44 | X39: -82
A40: 2022-03-14 | B40: BOTTOM | D40: -14 | F40: 3 | G40: -27 | N40: -2 | R40: -88 | T40: -12 | W40: -29
...
